Workbook

Sheet 00_Home
A1: PATHCARE DIAGNOSTICS · Pathology Laboratory
A2: EMPLOYEE ATTENDANCE & ROSTER MANAGEMENT
A3: Workforce HR system · Single source of truth for staff, shifts, attendance & leave
B5: WORKBOOK NAVIGATION
B6: Sheet | C6: Purpose | D6: Edit here?
B7: 01_Config | C7: Shifts, attendance codes, leave types, departments, public holidays, leave policy. | D7: Yes — setup only
B8: 02_Employee_Master | C8: Master employee register. All other sheets pull names/IDs from here. | D8: Yes — HR master
B9: 03_Roster | C9: Monthly shift roster: M / E / N / WO / PH / LV. Swaps, backup, OT hours. | D9: Yes — Lab Manager
B10: 04_Attendance | C10: Daily attendance marks linked to roster month. Color-coded statuses. | D10: Yes — daily mark
B11: 05_Leave | C11: Leave applications, balances, approval workflow, manager remarks. | D11: Yes — leave desk
B12: 06_Dashboard | C12: Live KPIs, shift headcount, dept stats, trends. Formula-driven — do not type. | D12: No — auto
B14: OPERATING RULES 1. Maintain employees only on Employee Master (Active/Inactive). Never duplicate names on other sheets. 2. Set the working Month / Year on Roster (cells B5 / D5). Attendance uses the same month. 3. Mark roster first (shifts & weekly offs). Then mark daily attendance — or copy roster WO/PH into attendance. 4. Leave sheet updates balances; Approved leave should be reflected as PL/SL/VL on Attendance. 5. Dashboard refreshes automatically. Print Dashboard or Roster in landscape A4 for management reviews. 6. Sample data is for PathCare Diagnostics (illustrative). Replace with your lab’s real staff and holidays.
B20: CURRENT PERIOD | C20: September 2026
B21: Active headcount (sample) | C21: 19

Sheet 01_Config
A1: PATHCARE DIAGNOSTICS · Pathology Laboratory
A2: SYSTEM CONFIGURATION
A3: Controlled lists for drop-downs · Change carefully — used across the workbook
B5: SHIFT CODES | F5: ATTENDANCE CODES
B6: Code | C6: Shift | D6: Timing | F6: Code | G6: Meaning | H6: Fill | I6: Font
B7: M | C7: Morning | D7: 06:00–14:00 | F7: P | G7: Present | H7: D4EDDA | I7: 1B7A4E
B8: E | C8: Evening | D8: 14:00–22:00 | F8: A | G8: Absent | H8: F8D7DA | I8: B71C1C
B9: N | C9: Night | D9: 22:00–06:00 | F9: L | G9: Late Coming | H9: FFF3CD | I9: B78103
B10: WO | C10: Weekly Off | D10: — | F10: HD | G10: Half Day | H10: FFE0B2 | I10: E65100
B11: PH | C11: Public Holiday | D11: — | F11: WFO | G11: Work From Office | H11: D6E4F0 | I11: 0D47A1
B12: LV | C12: Leave | D12: — | F12: PL | G12: Planned Leave | H12: EDE7F6 | I12: 5E35B1
B13: TR | C13: Training | D13: — | F13: UL | G13: Unscheduled Leave | H13: FCE4EC | I13: AD1457
F14: VL | G14: Vacation Leave | H14: E0F7FA | I14: 00838F
F15: SL | G15: Sick Leave | H15: FFEBEE | I15: C62828
B16: DEPARTMENTS | C16: DESIGNATIONS | D16: EMPLOYMENT TYPE | F16: SHIFT ELIGIBILITY | G16: LEAVE TYPES | H16: LEAVE STATUS | I16: EMPLOYEE STATUS
B17: Hematology | C17: Lab Manager | D17: Permanent | F17: All Shifts | G17: Planned Leave | H17: Pending | I17: Active
B18: Biochemistry | C18: Pathologist | D18: Contract | F18: Morning Only | G18: Unplanned Leave | H18: Approved | I18: Inactive
B19: Microbiology | C19: Senior Lab Technologist | D19: Trainee | F19: Morning/Evening | G19: Sick Leave | H19: Rejected
B20: Histopathology | C20: Lab Technologist | D20: Part-time | F20: Night Eligible | G20: Vacation Leave | H20: Cancelled
B21: Phlebotomy | C21: Lab Assistant
B22: Sample Receiving | C22: Phlebotomist
B23: Quality Assurance | C23: QA Officer
B24: Administration | C24: Receptionist
B27: PUBLIC HOLIDAYS (update annually) | F27: LEAVE POLICY (annual entitlement days)
B28: Date | C28: Holiday Name | D28: Applies | F28: Leave Type | G28: Annual Days | H28: Carry Forward | I28: Notes
B29: 46048 | C29: Republic Day | D29: Yes | F29: Planned Leave | G29: 12 | H29: Max 5 | I29: Requires prior approval
B30: 46095 | C30: Holi | D30: Yes | F30: Unplanned Leave | G30: 6 | H30: No | I30: Inform same day
B31: 46249 | C31: Independence Day | D31: Yes | F31: Sick Leave | G31: 10 | H31: No | I31: Medical certificate > 2 days
B32: 46297 | C32: Gandhi Jayanti | D32: Yes | F32: Vacation Leave | G32: 15 | H32: Max 7 | I32: Plan 15 days ahead
B33: 46315 | C33: Diwali | D33: Yes
B34: 46381 | C34: Christmas | D34: Yes

Sheet 02_Employee_Master
A1: PATHCARE DIAGNOSTICS · Pathology Laboratory
A2: EMPLOYEE MASTER REGISTER
A3: Single source of truth · Roster, Attendance, Leave & Dashboard reference this sheet
A5: Employee ID | B5: Employee Name | C5: Designation | D5: Department | E5: Reporting Manager | F5: Date of Joining | G5: Employment Type | H5: Shift Eligibility | I5: Contact Number | J5: Email ID | K5: Emergency Contact | L5: Status
A6: PL-001 | B6: Dr. Ananya Mehta | C6: Pathologist | D6: Histopathology | E6: Lab Director | F6: 43536 | G6: Permanent | H6: Morning Only | I6: 9876543210 | J6: ananya.mehta@pathlab.example | K6: Rajesh Mehta — 9876500001 | L6: Active
A7: PL-002 | B7: Vikram Singh | C7: Lab Manager | D7: Administration | E7: Lab Director | F7: 43252 | G7: Permanent | H7: All Shifts | I7: 9876543211 | J7: vikram.singh@pathlab.example | K7: Priya Singh — 9876500002 | L7: Active
A8: PL-003 | B8: Sneha Patel | C8: Senior Lab Technologist | D8: Hematology | E8: Vikram Singh | F8: 43845 | G8: Permanent | H8: All Shifts | I8: 9876543212 | J8: sneha.patel@pathlab.example | K8: Amit Patel — 9876500003 | L8: Active
A9: PL-004 | B9: Rahul Nair | C9: Lab Technologist | D9: Hematology | E9: Sneha Patel | F9: 44428 | G9: Permanent | H9: All Shifts | I9: 9876543213 | J9: rahul.nair@pathlab.example | K9: Deepa Nair — 9876500004 | L9: Active
A10: PL-005 | B10: Fatima Khan | C10: Lab Technologist | D10: Biochemistry | E10: Vikram Singh | F10: 44140 | G10: Permanent | H10: Morning/Evening | I10: 9876543214 | J10: fatima.khan@pathlab.example | K10: Imran Khan — 9876500005 | L10: Active
A11: PL-006 | B11: Arjun Reddy | C11: Lab Technologist | D11: Biochemistry | E11: Fatima Khan | F11: 44606 | G11: Permanent | H11: All Shifts | I11: 9876543215 | J11: arjun.reddy@pathlab.example | K11: Kavitha Reddy — 9876500006 | L11: Active
A12: PL-007 | B12: Meera Iyer | C12: Senior Lab Technologist | D12: Microbiology | E12: Vikram Singh | F12: 43709 | G12: Permanent | H12: Morning/Evening | I12: 9876543216 | J12: meera.iyer@pathlab.example | K12: Suresh Iyer — 9876500007 | L12: Active
A13: PL-008 | B13: Karan Malhotra | C13: Lab Technologist | D13: Microbiology | E13: Meera Iyer | F13: 45026 | G13: Contract | H13: All Shifts | I13: 9876543217 | J13: karan.malhotra@pathlab.example | K13: Neha Malhotra — 9876500008 | L13: Active
A14: PL-009 | B14: Pooja Sharma | C14: Lab Assistant | D14: Histopathology | E14: Dr. Ananya Mehta | F14: 44334 | G14: Permanent | H14: Morning Only | I14: 9876543218 | J14: pooja.sharma@pathlab.example | K14: Ravi Sharma — 9876500009 | L14: Active
A15: PL-010 | B15: Mohammed Irfan | C15: Phlebotomist | D15: Phlebotomy | E15: Vikram Singh | F15: 44743 | G15: Permanent | H15: Morning/Evening | I15: 9876543219 | J15: m.irfan@pathlab.example | K15: Ayesha Irfan — 9876500010 | L15: Active
A16: PL-011 | B16: Lakshmi Devi | C16: Phlebotomist | D16: Phlebotomy | E16: Vikram Singh | F16: 43912 | G16: Permanent | H16: Morning Only | I16: 9876543220 | J16: lakshmi.devi@pathlab.example | K16: Venkat Devi — 9876500011 | L16: Active
A17: PL-012 | B17: Suresh Kumar | C17: Lab Assistant | D17: Sample Receiving | E17: Vikram Singh | F17: 44536 | G17: Permanent | H17: All Shifts | I17: 9876543221 | J17: suresh.kumar@pathlab.example | K17: Anita Kumar — 9876500012 | L17: Active
... A25: PL-020 | B25: Thomas Mathew | C25: Senior Lab Technologist | D25: Sample Receiving | E25: Vikram Singh | F25: 43423 | G25: Permanent | H25: All Shifts | I25: 9876543229 | J25: thomas.mathew@pathlab.example | K25: Mary Mathew — 9876500020 | L25: Inactive
A47: Total rows | B47: =COUNTA(A6:A45) -> 20 | C47: Active | D47: =COUNTIF(L6:L45,"Active") -> 19 | E47: Inactive | F47: =COUNTIF(L6:L45,"Inactive") -> 1

Sheet 03_Roster
A1: PATHCARE DIAGNOSTICS · Pathology Laboratory
A2: MONTHLY SHIFT ROSTER
A3: Pathology Lab scheduling · M Morning · E Evening · N Night · WO Weekly Off · PH Holiday · LV Leave
A5: Month | B5: 9 | C5: Year | D5: 2026 | E5: Instructions: Set Month (1–12) & Year. Mark each day with M/E/N/WO/PH/LV/TR. Use Backup & Swap columns for coverage.
A6: Emp ID | B6: Employee Name | C6: Department | D6: Designation | E6: 1 | F6: 2 | G6: 3 | H6: 4 | I6: 5 | J6: 6 | K6: 7 | L6: 8 | M6: 9 | N6: 10 | O6: 11 | P6: 12 | Q6: 13 | R6: 14 | S6: 15 | T6: 16 | U6: 17 | V6: 18 | W6: 19 | X6: 20 | Y6: 21 | Z6: 22 | AA6: 23 | AB6: 24 | AC6: 25 | AD6: 26 | AE6: 27 | AF6: 28 | AG6: 29 | AH6: 30 | AI6: WO Days | AJ6: OT Hours | AK6: Backup Resource | AL6: Shift Swap / Notes | AM6: Remarks
E7: T | F7: W | G7: T | H7: F | I7: S | J7: S | K7: M | L7: T | M7: W | N7: T | O7: F | P7: S | Q7: S | R7: M | S7: T | T7: W | U7: T | V7: F | W7: S | X7: S | Y7: M | Z7: T | AA7: W | AB7: T | AC7: F | AD7: S | AE7: S | AF7: M | AG7: T | AH7: W
A8: ='02_Employee_Master'!A6 -> PL-001 | B8: ='02_Employee_Master'!B6 -> Dr. Ananya Mehta | C8: ='02_Employee_Master'!D6 -> Histopathology | D8: ='02_Employee_Master'!C6 -> Pathologist | E8: M | F8: M | G8: M | H8: M | I8: M | J8: M | K8: WO | L8: M | M8: M | N8: M | O8: M | P8: M | Q8: M | R8: WO | S8: M | T8: M | U8: M | V8: M | W8: M | X8: M | Y8: WO | Z8: M | AA8: M | AB8: M | AC8: M | AD8: M | AE8: M | AF8: WO | AG8: M | AH8: M | AI8: =COUNTIF(E8:AH8,"WO") -> 4 | AJ8: 0 | AK8: Vikram Singh
A9: ='02_Employee_Master'!A7 -> PL-002 | B9: ='02_Employee_Master'!B7 -> Vikram Singh | C9: ='02_Employee_Master'!D7 -> Administration | D9: ='02_Employee_Master'!C7 -> Lab Manager | E9: M | F9: WO | G9: M | H9: E | I9: M | J9: M | K9: M | L9: M | M9: WO | N9: M | O9: M | P9: M | Q9: M | R9: E | S9: M | T9: WO | U9: M | V9: M | W9: E | X9: M | Y9: M | Z9: M | AA9: WO | AB9: E | AC9: M | AD9: M | AE9: M | AF9: M | AG9: E | AH9: WO | AI9: =COUNTIF(E9:AH9,"WO") -> 5 | AJ9: 0
A10: ='02_Employee_Master'!A8 -> PL-003 | B10: ='02_Employee_Master'!B8 -> Sneha Patel | C10: ='02_Employee_Master'!D8 -> Hematology | D10: ='02_Employee_Master'!C8 -> Senior Lab Technologist | E10: N | F10: M | G10: E | H10: WO | I10: M | J10: M | K10: M | L10: N | M10: M | N10: M | O10: WO | P10: M | Q10: E | R10: M | S10: N | T10: M | U10: M | V10: WO | W10: M | X10: M | Y10: M | Z10: N | AA10: E | AB10: M | AC10: WO | AD10: M | AE10: M | AF10: E | AG10: N | AH10: M | AI10: =COUNTIF(E10:AH10,"WO") -> 4 | AJ10: 0
A11: ='02_Employee_Master'!A9 -> PL-004 | B11: ='02_Employee_Master'!B9 -> Rahul Nair | C11: ='02_Employee_Master'!D9 -> Hematology | D11: ='02_Employee_Master'!C9 -> Lab Technologist | E11: M | F11: E | G11: M | H11: M | I11: M | J11: WO | K11: N | L11: M | M11: M | N11: M | O11: M | P11: E | Q11: WO | R11: N | S11: M | T11: M | U11: E | V11: M | W11: M | X11: WO | Y11: N | Z11: E | AA11: M | AB11: M | AC11: M | AD11: M | AE11: WO | AF11: N | AG11: M | AH11: M | AI11: =COUNTIF(E11:AH11,"WO") -> 4 | AJ11: 0
A12: ='02_Employee_Master'!A10 -> PL-005 | B12: ='02_Employee_Master'!B10 -> Fatima Khan | C12: ='02_Employee_Master'!D10 -> Biochemistry | D12: ='02_Employee_Master'!C10 -> Lab Technologist | E12: WO | F12: E | G12: M | H12: M | I12: E | J12: M | K12: M | L12: WO | M12: M | N12: M | O12: E | P12: M | Q12: M | R12: E | S12: WO | T12: M | U12: E | V12: M | W12: M | X12: E | Y12: M | Z12: WO | AA12: E | AB12: M | AC12: M | AD12: E | AE12: M | AF12: M | AG12: WO | AH12: M | AI12: =COUNTIF(E12:AH12,"WO") -> 5 | AJ12: 0
A13: ='02_Employee_Master'!A11 -> PL-006 | B13: ='02_Employee_Master'!B11 -> Arjun Reddy | C13: ='02_Employee_Master'!D11 -> Biochemistry | D13: ='02_Employee_Master'!C11 -> Lab Technologist | E13: M | F13: M | G13: WO | H13: M | I13: N | J13: M | K13: M | L13: M | M13: M | N13: WO | O13: M | P13: N | Q13: M | R13: M | S13: E | T13: M | U13: WO | V13: M | W13: N | X13: E | Y13: M | Z13: M | AA13: M | AB13: WO | AC13: E | AD13: N | AE13: M | AF13: M | AG13: M | AH13: E | AI13: =COUNTIF(E13:AH13,"WO") -> 4 | AJ13: 0
A14: ='02_Employee_Master'!A12 -> PL-007 | B14: ='02_Employee_Master'!B12 -> Meera Iyer | C14: ='02_Employee_Master'!D12 -> Microbiology | D14: ='02_Employee_Master'!C12 -> Senior Lab Technologist | E14: M | F14: M | G14: E | H14: M | I14: WO | J14: E | K14: M | L14: M | M14: E | N14: M | O14: M | P14: WO | Q14: M | R14: M | S14: E | T14: M | U14: M | V14: E | W14: WO | X14: M | Y14: E | Z14: M | AA14: M | AB14: E | AC14: M | AD14: WO | AE14: E | AF14: M | AG14: M | AH14: E | AI14: =COUNTIF(E14:AH14,"WO") -> 4 | AJ14: 0 | AK14: Karan Malhotra
A15: ='02_Employee_Master'!A13 -> PL-008 | B15: ='02_Employee_Master'!B13 -> Karan Malhotra | C15: ='02_Employee_Master'!D13 -> Microbiology | D15: ='02_Employee_Master'!C13 -> Lab Technologist | E15: M | F15: M | G15: N | H15: M | I15: M | J15: M | K15: WO | L15: E | M15: M | N15: N | O15: M | P15: M | Q15: E | R15: WO | S15: M | T15: M | U15: N | V15: E | W15: M | X15: M | Y15: WO | Z15: M | AA15: E | AB15: N | AC15: M | AD15: M | AE15: M | AF15: WO | AG15: M | AH15: M | AI15: =COUNTIF(E15:AH15,"WO") -> 4 | AJ15: 0
A16: ='02_Employee_Master'!A14 -> PL-009 | B16: ='02_Employee_Master'!B14 -> Pooja Sharma | C16: ='02_Employee_Master'!D14 -> Histopathology | D16: ='02_Employee_Master'!C14 -> Lab Assistant | E16: M | F16: WO | G16: M | H16: M | I16: M | J16: M | K16: M | L16: M | M16: WO | N16: M | O16: M | P16: M | Q16: M | R16: M | S16: M | T16: WO | U16: M | V16: M | W16: M | X16: M | Y16: M | Z16: M | AA16: WO | AB16: M | AC16: M | AD16: M | AE16: M | AF16: M | AG16: M | AH16: WO | AI16: =COUNTIF(E16:AH16,"WO") -> 5 | AJ16: 0
A17: ='02_Employee_Master'!A15 -> PL-010 | B17: ='02_Employee_Master'!B15 -> Mohammed Irfan | C17: ='02_Employee_Master'!D15 -> Phlebotomy | D17: ='02_Employee_Master'!C15 -> Phlebotomist | E17: M | F17: M | G17: E | H17: WO | I17: M | J17: E | K17: M | L17: M | M17: E | N17: M | O17: WO | P17: E | Q17: M | R17: M | S17: E | T17: M | U17: M | V17: WO | W17: M | X17: M | Y17: E | Z17: M | AA17: M | AB17: E | AC17: WO | AD17: M | AE17: E | AF17: M | AG17: M | AH17: E | AI17: =COUNTIF(E17:AH17,"WO") -> 4 | AJ17: 0
A18: ='02_Employee_Master'!A16 -> PL-011 | B18: ='02_Employee_Master'!B16 -> Lakshmi Devi | C18: ='02_Employee_Master'!D16 -> Phlebotomy | D18: ='02_Employee_Master'!C16 -> Phlebotomist | E18: M | F18: M | G18: M | H18: M | I18: M | J18: WO | K18: M | L18: M | M18: M | N18: M | O18: M | P18: M | Q18: WO | R18: M | S18: M | T18: M | U18: M | V18: M | W18: M | X18: WO | Y18: M | Z18: M | AA18: M | AB18: M | AC18: M | AD18: M | AE18: WO | AF18: M | AG18: M | AH18: M | AI18: =COUNTIF(E18:AH18,"WO") -> 4 | AJ18: 0
A19: ='02_Employee_Master'!A17 -> PL-012 | B19: ='02_Employee_Master'!B17 -> Suresh Kumar | C19: ='02_Employee_Master'!D17 -> Sample Receiving | D19: ='02_Employee_Master'!C17 -> Lab Assistant | E19: WO | F19: M | G19: M | H19: E | I19: M | J19: N | K19: M | L19: WO | M19: E | N19: M | O19: M | P19: M | Q19: N | R19: E | S19: WO | T19: M | U19: M | V19: M | W19: E | X19: N | Y19: M | Z19: WO | AA19: M | AB19: E | AC19: M | AD19: M | AE19: N | AF19: M | AG19: WO | AH19: M | AI19: =COUNTIF(E19:AH19,"WO") -> 5 | AJ19: 0
A20: ='02_Employee_Master'!A18 -> PL-013 | B20: ='02_Employee_Master'!B18 -> Nisha Gupta | C20: ='02_Employee_Master'!D18 -> Quality Assurance | D20: ='02_Employee_Master'!C18 -> QA Officer | E20: M | F20: M | G20: WO | H20: M | I20: M | J20: M | K20: M | L20: M | M20: M | N20: WO | O20: M | P20: M | Q20: M | R20: M | S20: M | T20: M | U20: WO | V20: M | W20: M | X20: M | Y20: M | Z20: M | AA20: M | AB20: WO | AC20: M | AD20: M | AE20: M | AF20: M | AG20: M | AH20: M | AI20: =COUNTIF(E20:AH20,"WO") -> 4 | AJ20: 0 | AK20: Deepak Joshi
A21: ='02_Employee_Master'!A19 -> PL-014 | B21: ='02_Employee_Master'!B19 -> Deepak Joshi | C21: ='02_Employee_Master'!D19 -> Hematology | D21: ='02_Employee_Master'!C19 -> Lab Technologist | E21: M | F21: E | G21: M | H21: M | I21: WO | J21: M | K21: M | L21: E | M21: M | N21: M | O21: E | P21: WO | Q21: M | R21: E | S21: M | T21: M | U21: E | V21: M | W21: WO | X21: E | Y21: M | Z21: M | AA21: E | AB21: M | AC21: M | AD21: WO | AE21: M | AF21: M | AG21: E | AH21: M | AI21: =COUNTIF(E21:AH21,"WO") -> 4 | AJ21: 0
A22: ='02_Employee_Master'!A20 -> PL-015 | B22: ='02_Employee_Master'!B20 -> Anjali Verma | C22: ='02_Employee_Master'!D20 -> Administration | D22: ='02_Employee_Master'!C20 -> Receptionist | E22: M | F22: M | G22: M | H22: M | I22: M | J22: M | K22: WO | L22: M | M22: M | N22: M | O22: M | P22: M | Q22: M | R22: WO | S22: M | T22: M | U22: M | V22: M | W22: M | X22: M | Y22: WO | Z22: M | AA22: M | AB22: M | AC22: M | AD22: M | AE22: M | AF22: WO | AG22: M | AH22: M | AI22: =COUNTIF(E22:AH22,"WO") -> 4 | AJ22: 0
A23: ='02_Employee_Master'!A21 -> PL-016 | B23: ='02_Employee_Master'!B21 -> Ravi Teja | C23: ='02_Employee_Master'!D21 -> Biochemistry | D23: ='02_Employee_Master'!C21 -> Lab Technologist | E23: M | F23: WO | G23: M | H23: M | I23: E | J23: M | K23: M | L23: M | M23: WO | N23: E | O23: M | P23: M | Q23: M | R23: M | S23: E | T23: WO | U23: M | V23: M | W23: M | X23: E | Y23: M | Z23: M | AA23: WO | AB23: M | AC23: E | AD23: M | AE23: M | AF23: M | AG23: M | AH23: WO | AI23: =COUNTIF(E23:AH23,"WO") -> 5 | AJ23: 0
A24: ='02_Employee_Master'!A22 -> PL-017 | B24: ='02_Employee_Master'!B22 -> Geeta Rao | C24: ='02_Employee_Master'!D22 -> Microbiology | D24: ='02_Employee_Master'!C22 -> Lab Assistant | E24: M | F24: E | G24: M | H24: WO | I24: E | J24: M | K24: M | L24: E | M24: M | N24: M | O24: WO | P24: M | Q24: M | R24: E | S24: M | T24: M | U24: E | V24: WO | W24: M | X24: E | Y24: M | Z24: M | AA24: E | AB24: M | AC24: WO | AD24: E | AE24: M | AF24: M | AG24: E | AH24: M | AI24: =COUNTIF(E24:AH24,"WO") -> 4 | AJ24: 0
A25: ='02_Employee_Master'!A23 -> PL-018 | B25: ='02_Employee_Master'!B23 -> Imran Sheikh | C25: ='02_Employee_Master'!D23 -> Phlebotomy | D25: ='02_Employee_Master'!C23 -> Phlebotomist | E25: M | F25: M | G25: M | H25: M | I25: M | J25: WO | K25: M | L25: M | M25: M | N25: M | O25: M | P25: M | Q25: WO | R25: M | S25: M | T25: M | U25: M | V25: M | W25: M | X25: WO | Y25: M | Z25: M | AA25: M | AB25: M | AC25: M | AD25: M | AE25: WO | AF25: M | AG25: M | AH25: M | AI25: =COUNTIF(E25:AH25,"WO") -> 4 | AJ25: 0
A26: ='02_Employee_Master'!A24 -> PL-019 | B26: ='02_Employee_Master'!B24 -> Kavya Menon | C26: ='02_Employee_Master'!D24 -> Histopathology | D26: ='02_Employee_Master'!C24 -> Lab Technologist | E26: WO | F26: M | G26: M | H26: M | I26: M | J26: M | K26: M | L26: WO | M26: M | N26: M | O26: M | P26: M | Q26: M | R26: M | S26: WO | T26: M | U26: M | V26: M | W26: M | X26: M | Y26: M | Z26: WO | AA26: M | AB26: M | AC26: M | AD26: M | AE26: M | AF26: M | AG26: WO | AH26: M | AI26: =COUNTIF(E26:AH26,"WO") -> 5 | AJ26: 0 | AK26: Thomas Mathew
A27: ='02_Employee_Master'!A25 -> PL-020 | B27: ='02_Employee_Master'!B25 -> Thomas Mathew | C27: ='02_Employee_Master'!D25 -> Sample Receiving | D27: ='02_Employee_Master'!C25 -> Senior Lab Technologist | AI27: =COUNTIF(E27:AH27,"WO") -> 0
A28: Morning (M) headcount | E28: =COUNTIF(E8:E27,"M") -> 15 | F28: =COUNTIF(F8:F27,"M") -> 12 | G28: =COUNTIF(G8:G27,"M") -> 13 | H28: =COUNTIF(H8:H27,"M") -> 14 | I28: =COUNTIF(I8:I27,"M") -> 13 | J28: =COUNTIF(J8:J27,"M") -> 13 | K28: =COUNTIF(K8:K27,"M") -> 15 | L28: =COUNTIF(L8:L27,"M") -> 12 | ... AH28: =COUNTIF(AH8:AH27,"M") -> 13
A29: Evening (E) headcount | E29: =COUNTIF(E8:E27,"E") -> 0 | F29: =COUNTIF(F8:F27,"E") -> 4 | G29: =COUNTIF(G8:G27,"E") -> 3 | H29: =COUNTIF(H8:H27,"E") -> 2 | I29: =COUNTIF(I8:I27,"E") -> 3 | J29: =COUNTIF(J8:J27,"E") -> 2 | K29: =COUNTIF(K8:K27,"E") -> 0 | L29: =COUNTIF(L8:L27,"E") -> 3 | ... AH29: =COUNTIF(AH8:AH27,"E") -> 3
A30: Night (N) headcount | E30: =COUNTIF(E8:E27,"N") -> 1 | F30: =COUNTIF(F8:F27,"N") -> 0 | G30: =COUNTIF(G8:G27,"N") -> 1 | H30: =COUNTIF(H8:H27,"N") -> 0 | I30: =COUNTIF(I8:I27,"N") -> 1 | J30: =COUNTIF(J8:J27,"N") -> 1 | K30: =COUNTIF(K8:K27,"N") -> 1 | L30: =COUNTIF(L8:L27,"N") -> 1 | ... AH30: =COUNTIF(AH8:AH27,"N") -> 0

Sheet 04_Attendance
A1: PATHCARE DIAGNOSTICS · Pathology Laboratory
A2: DAILY ATTENDANCE REGISTER
A3: Mark P / A / L / HD / WFO / PL / UL / VL / SL / H / WO / OT · Color-coded · Linked to Employee Master
A5: Period | B5: ='03_Roster'!B5 -> 9 | C5: ='03_Roster'!D5 -> 2026 | D5: 46266 | E5: Legend: P Present · A Absent · L Late · HD Half Day · WFO Work From Office · PL/UL/VL/SL Leave · H Holiday · WO Off · OT Overtime
A6: Emp ID | B6: Employee Name | C6: Department | D6: Designation | E6: 1 | F6: 2 | G6: 3 | H6: 4 | I6: 5 | J6: 6 | K6: 7 | L6: 8 | M6: 9 | N6: 10 | O6: 11 | P6: 12 | Q6: 13 | R6: 14 | S6: 15 | T6: 16 | U6: 17 | V6: 18 | W6: 19 | X6: 20 | Y6: 21 | Z6: 22 | AA6: 23 | AB6: 24 | AC6: 25 | AD6: 26 | AE6: 27 | AF6: 28 | AG6: 29 | AH6: 30 | AI6: Present | AJ6: Absent | AK6: Late | AL6: Half Day | AM6: Leave | AN6: WO/H | AO6: OT Hrs | AP6: Att %
E7: T | F7: W | G7: T | H7: F | I7: S | J7: S | K7: M | L7: T | M7: W | N7: T | O7: F | P7: S | Q7: S | R7: M | S7: T | T7: W | U7: T | V7: F | W7: S | X7: S | Y7: M | Z7: T | AA7: W | AB7: T | AC7: F | AD7: S | AE7: S | AF7: M | AG7: T | AH7: W
A8: ='02_Employee_Master'!A6 -> PL-001 | B8: ='02_Employee_Master'!B6 -> Dr. Ananya Mehta | C8: ='02_Employee_Master'!D6 -> Histopathology | D8: ='02_Employee_Master'!C6 -> Pathologist | E8: P | F8: P | G8: P | H8: P | I8: P | J8: SL | K8: WO | L8: P | M8: P | N8: P | O8: P | P8: P | Q8: P | R8: WO | S8: P | T8: P | U8: P | V8: P | W8: P | X8: P | Y8: WO | Z8: P | AA8: P | AB8: P | AC8: P | AD8: P | AE8: P | AF8: WO | AG8: A | AH8: P | AI8: =COUNTIF(E8:AH8,"P")+COUNTIF(E8:AH8,"L")+COUNTIF(E8:AH8,"WFO")+COUNTIF(E8:AH8,"OT") -> 24 | AJ8: =COUNTIF(E8:AH8,"A") -> 1 | AK8: =COUNTIF(E8:AH8,"L") -> 0 | AL8: =COUNTIF(E8:AH8,"HD") -> 0 | AM8: =COUNTIF(E8:AH8,"PL")+COUNTIF(E8:AH8,"UL")+COUNTIF(E8:AH8,"VL")+COUNTIF(E8:AH8,"SL") -> 1 | AN8: =COUNTIF(E8:AH8,"WO")+COUNTIF(E8:AH8,"H") -> 4 | AO8: ='03_Roster'!AJ8 -> 0 | AP8: =IFERROR((AI8+AL8*0.5)/(COUNTA(E8:AH8)-AN8),"") -> 0.92307692
A9: ='02_Employee_Master'!A7 -> PL-002 | B9: ='02_Employee_Master'!B7 -> Vikram Singh | C9: ='02_Employee_Master'!D7 -> Administration | D9: ='02_Employee_Master'!C7 -> Lab Manager | E9: P | F9: WO | G9: P | H9: HD | I9: P | J9: P | K9: P | L9: P | M9: WO | N9: P | O9: P | P9: P | Q9: P | R9: P | S9: P | T9: WO | U9: P | V9: P | W9: P | X9: P | Y9: P | Z9: P | AA9: WO | AB9: P | AC9: P | AD9: P | AE9: P | AF9: P | AG9: P | AH9: WO | AI9: =COUNTIF(E9:AH9,"P")+COUNTIF(E9:AH9,"L")+COUNTIF(E9:AH9,"WFO")+COUNTIF(E9:AH9,"OT") -> 24 | AJ9: =COUNTIF(E9:AH9,"A") -> 0 | AK9: =COUNTIF(E9:AH9,"L") -> 0 | AL9: =COUNTIF(E9:AH9,"HD") -> 1 | AM9: =COUNTIF(E9:AH9,"PL")+COUNTIF(E9:AH9,"UL")+COUNTIF(E9:AH9,"VL")+COUNTIF(E9:AH9,"SL") -> 0 | AN9: =COUNTIF(E9:AH9,"WO")+COUNTIF(E9:AH9,"H") -> 5 | AO9: ='03_Roster'!AJ9 -> 0 | AP9: =IFERROR((AI9+AL9*0.5)/(COUNTA(E9:AH9)-AN9),"") -> 0.98
A10: ='02_Employee_Master'!A8 -> PL-003 | B10: ='02_Employee_Master'!B8 -> Sneha Patel | C10: ='02_Employee_Master'!D8 -> Hematology | D10: ='02_Employee_Master'!C8 -> Senior Lab Technologist | E10: P | F10: P | G10: P | H10: WO | I10: P | J10: P | K10: P | L10: P | M10: P | N10: P | O10: WO | P10: P | Q10: P | R10: P | S10: P | T10: P | U10: P | V10: WO | W10: P | X10: P | Y10: P | Z10: P | AA10: P | AB10: P | AC10: WO | AD10: P | AE10: P | AF10: P | AG10: P | AH10: P | AI10: =COUNTIF(E10:AH10,"P")+COUNTIF(E10:AH10,"L")+COUNTIF(E10:AH10,"WFO")+COUNTIF(E10:AH10,"OT") -> 26 | AJ10: =COUNTIF(E10:AH10,"A") -> 0 | AK10: =COUNTIF(E10:AH10,"L") -> 0 | AL10: =COUNTIF(E10:AH10,"HD") -> 0 | AM10: =COUNTIF(E10:AH10,"PL")+COUNTIF(E10:AH10,"UL")+COUNTIF(E10:AH10,"VL")+COUNTIF(E10:AH10,"SL") -> 0 | AN10: =COUNTIF(E10:AH10,"WO")+COUNTIF(E10:AH10,"H") -> 4 | AO10: ='03_Roster'!AJ10 -> 0 | AP10: =IFERROR((AI10+AL10*0.5)/(COUNTA(E10:AH10)-AN10),"") -> 1
A11: ='02_Employee_Master'!A9 -> PL-004 | B11: ='02_Employee_Master'!B9 -> Rahul Nair | C11: ='02_Employee_Master'!D9 -> Hematology | D11: ='02_Employee_Master'!C9 -> Lab Technologist | E11: P | F11: P | G11: P | H11: P | I11: P | J11: WO | K11: P | L11: P | M11: P | N11: P | O11: P | P11: P | Q11: WO | R11: P | S11: P | T11: P | U11: P | V11: P | W11: P | X11: WO | Y11: P | Z11: P | AA11: P | AB11: P | AC11: P | AD11: P | AE11: WO | AF11: P | AG11: P | AH11: P | AI11: =COUNTIF(E11:AH11,"P")+COUNTIF(E11:AH11,"L")+COUNTIF(E11:AH11,"WFO")+COUNTIF(E11:AH11,"OT") -> 26 | AJ11: =COUNTIF(E11:AH11,"A") -> 0 | AK11: =COUNTIF(E11:AH11,"L") -> 0 | AL11: =COUNTIF(E11:AH11,"HD") -> 0 | AM11: =COUNTIF(E11:AH11,"PL")+COUNTIF(E11:AH11,"UL")+COUNTIF(E11:AH11,"VL")+COUNTIF(E11:AH11,"SL") -> 0 | AN11: =COUNTIF(E11:AH11,"WO")+COUNTIF(E11:AH11,"H") -> 4 | AO11: ='03_Roster'!AJ11 -> 0 | AP11: =IFERROR((AI11+AL11*0.5)/(COUNTA(E11:AH11)-AN11),"") -> 1
A12: ='02_Employee_Master'!A10 -> PL-005 | B12: ='02_Employee_Master'!B10 -> Fatima Khan | C12: ='02_Employee_Master'!D10 -> Biochemistry | D12: ='02_Employee_Master'!C10 -> Lab Technologist | E12: WO | F12: P | G12: P | H12: P | I12: P | J12: P | K12: P | L12: WO | M12: P | N12: P | O12: P | P12: P | Q12: P | R12: P | S12: WO | T12: P | U12: P | V12: P | W12: P | X12: P | Y12: P | Z12: WO | AA12: P | AB12: P | AC12: P | AD12: P | AE12: L | AF12: P | AG12: WO | AH12: P | AI12: =COUNTIF(E12:AH12,"P")+COUNTIF(E12:AH12,"L")+COUNTIF(E12:AH12,"WFO")+COUNTIF(E12:AH12,"OT") -> 25 | AJ12: =COUNTIF(E12:AH12,"A") -> 0 | AK12: =COUNTIF(E12:AH12,"L") -> 1 | AL12: =COUNTIF(E12:AH12,"HD") -> 0 | AM12: =COUNTIF(E12:AH12,"PL")+COUNTIF(E12:AH12,"UL")+COUNTIF(E12:AH12,"VL")+COUNTIF(E12:AH12,"SL") -> 0 | AN12: =COUNTIF(E12:AH12,"WO")+COUNTIF(E12:AH12,"H") -> 5 | AO12: ='03_Roster'!AJ12 -> 0 | AP12: =IFERROR((AI12+AL12*0.5)/(COUNTA(E12:AH12)-AN12),"") -> 1
A13: ='02_Employee_Master'!A11 -> PL-006 | B13: ='02_Employee_Master'!B11 -> Arjun Reddy | C13: ='02_Employee_Master'!D11 -> Biochemistry | D13: ='02_Employee_Master'!C11 -> Lab Technologist | E13: P | F13: P | G13: WO | H13: P | I13: P | J13: P | K13: P | L13: P | M13: P | N13: WO | O13: P | P13: P | Q13: P | R13: P | S13: P | T13: P | U13: WO | V13: P | W13: P | X13: P | Y13: P | Z13: P | AA13: P | AB13: WO | AC13: P | AD13: P | AE13: P | AF13: P | AG13: P | AH13: P | AI13: =COUNTIF(E13:AH13,"P")+COUNTIF(E13:AH13,"L")+COUNTIF(E13:AH13,"WFO")+COUNTIF(E13:AH13,"OT") -> 26 | AJ13: =COUNTIF(E13:AH13,"A") -> 0 | AK13: =COUNTIF(E13:AH13,"L") -> 0 | AL13: =COUNTIF(E13:AH13,"HD") -> 0 | AM13: =COUNTIF(E13:AH13,"PL")+COUNTIF(E13:AH13,"UL")+COUNTIF(E13:AH13,"VL")+COUNTIF(E13:AH13,"SL") -> 0 | AN13: =COUNTIF(E13:AH13,"WO")+COUNTIF(E13:AH13,"H") -> 4 | AO13: ='03_Roster'!AJ13 -> 0 | AP13: =IFERROR((AI13+AL13*0.5)/(COUNTA(E13:AH13)-AN13),"") -> 1
A14: ='02_Employee_Master'!A12 -> PL-007 | B14: ='02_Employee_Master'!B12 -> Meera Iyer | C14: ='02_Employee_Master'!D12 -> Microbiology | D14: ='02_Employee_Master'!C12 -> Senior Lab Technologist | E14: P | F14: P | G14: P | H14: P | I14: WO | J14: P | K14: P | L14: P | M14: P | N14: P | O14: P | P14: WO | Q14: P | R14: P | S14: P | T14: P | U14: P | V14: P | W14: WO | X14: P | Y14: P | Z14: P | AA14: P | AB14: P | AC14: P | AD14: WO | AE14: P | AF14: P | AG14: P | AH14: P | AI14: =COUNTIF(E14:AH14,"P")+COUNTIF(E14:AH14,"L")+COUNTIF(E14:AH14,"WFO")+COUNTIF(E14:AH14,"OT") -> 26 | AJ14: =COUNTIF(E14:AH14,"A") -> 0 | AK14: =COUNTIF(E14:AH14,"L") -> 0 | AL14: =COUNTIF(E14:AH14,"HD") -> 0 | AM14: =COUNTIF(E14:AH14,"PL")+COUNTIF(E14:AH14,"UL")+COUNTIF(E14:AH14,"VL")+COUNTIF(E14:AH14,"SL") -> 0 | AN14: =COUNTIF(E14:AH14,"WO")+COUNTIF(E14:AH14,"H") -> 4 | AO14: ='03_Roster'!AJ14 -> 0 | AP14: =IFERROR((AI14+AL14*0.5)/(COUNTA(E14:AH14)-AN14),"") -> 1
A15: ='02_Employee_Master'!A13 -> PL-008 | B15: ='02_Employee_Master'!B13 -> Karan Malhotra | C15: ='02_Employee_Master'!D13 -> Microbiology | D15: ='02_Employee_Master'!C13 -> Lab Technologist | E15: P | F15: P | G15: P | H15: P | I15: P | J15: P | K15: WO | L15: P | M15: P | N15: P | O15: P | P15: P | Q15: P | R15: WO | S15: P | T15: P | U15: P | V15: P | W15: P | X15: P | Y15: WO | Z15: P | AA15: P | AB15: P | AC15: P | AD15: P | AE15: P | AF15: WO | AG15: P | AH15: P | AI15: =COUNTIF(E15:AH15,"P")+COUNTIF(E15:AH15,"L")+COUNTIF(E15:AH15,"WFO")+COUNTIF(E15:AH15,"OT") -> 26 | AJ15: =COUNTIF(E15:AH15,"A") -> 0 | AK15: =COUNTIF(E15:AH15,"L") -> 0 | AL15: =COUNTIF(E15:AH15,"HD") -> 0 | AM15: =COUNTIF(E15:AH15,"PL")+COUNTIF(E15:AH15,"UL")+COUNTIF(E15:AH15,"VL")+COUNTIF(E15:AH15,"SL") -> 0 | AN15: =COUNTIF(E15:AH15,"WO")+COUNTIF(E15:AH15,"H") -> 4 | AO15: ='03_Roster'!AJ15 -> 0 | AP15: =IFERROR((AI15+AL15*0.5)/(COUNTA(E15:AH15)-AN15),"") -> 1
A16: ='02_Employee_Master'!A14 -> PL-009 | B16: ='02_Employee_Master'!B14 -> Pooja Sharma | C16: ='02_Employee_Master'!D14 -> Histopathology | D16: ='02_Employee_Master'!C14 -> Lab Assistant | E16: P | F16: WO | G16: P | H16: P | I16: P | J16: P | K16: P | L16: P | M16: WO | N16: P | O16: P | P16: P | Q16: P | R16: L | S16: P | T16: WO | U16: P | V16: P | W16: P | X16: P | Y16: P | Z16: P | AA16: WO | AB16: P | AC16: P | AD16: P | AE16: P | AF16: P | AG16: P | AH16: WO | AI16: =COUNTIF(E16:AH16,"P")+COUNTIF(E16:AH16,"L")+COUNTIF(E16:AH16,"WFO")+COUNTIF(E16:AH16,"OT") -> 25 | AJ16: =COUNTIF(E16:AH16,"A") -> 0 | AK16: =COUNTIF(E16:AH16,"L") -> 1 | AL16: =COUNTIF(E16:AH16,"HD") -> 0 | AM16: =COUNTIF(E16:AH16,"PL")+COUNTIF(E16:AH16,"UL")+COUNTIF(E16:AH16,"VL")+COUNTIF(E16:AH16,"SL") -> 0 | AN16: =COUNTIF(E16:AH16,"WO")+COUNTIF(E16:AH16,"H") -> 5 | AO16: ='03_Roster'!AJ16 -> 0 | AP16: =IFERROR((AI16+AL16*0.5)/(COUNTA(E16:AH16)-AN16),"") -> 1
A17: ='02_Employee_Master'!A15 -> PL-010 | B17: ='02_Employee_Master'!B15 -> Mohammed Irfan | C17: ='02_Employee_Master'!D15 -> Phlebotomy | D17: ='02_Employee_Master'!C15 -> Phlebotomist | E17: P | F17: P | G17: P | H17: WO | I17: P | J17: P | K17: P | L17: P | M17: P | N17: P | O17: WO | P17: P | Q17: P | R17: P | S17: P | T17: P | U17: P | V17: WO | W17: P | X17: P | Y17: P | Z17: P | AA17: P | AB17: P | AC17: WO | AD17: P | AE17: P | AF17: P | AG17: P | AH17: P | AI17: =COUNTIF(E17:AH17,"P")+COUNTIF(E17:AH17,"L")+COUNTIF(E17:AH17,"WFO")+COUNTIF(E17:AH17,"OT") -> 26 | AJ17: =COUNTIF(E17:AH17,"A") -> 0 | AK17: =COUNTIF(E17:AH17,"L") -> 0 | AL17: =COUNTIF(E17:AH17,"HD") -> 0 | AM17: =COUNTIF(E17:AH17,"PL")+COUNTIF(E17:AH17,"UL")+COUNTIF(E17:AH17,"VL")+COUNTIF(E17:AH17,"SL") -> 0 | AN17: =COUNTIF(E17:AH17,"WO")+COUNTIF(E17:AH17,"H") -> 4 | AO17: ='03_Roster'!AJ17 -> 0 | AP17: =IFERROR((AI17+AL17*0.5)/(COUNTA(E17:AH17)-AN17),"") -> 1
A18: ='02_Employee_Master'!A16 -> PL-011 | B18: ='02_Employee_Master'!B16 -> Lakshmi Devi | C18: ='02_Employee_Master'!D16 -> Phlebotomy | D18: ='02_Employee_Master'!C16 -> Phlebotomist | E18: P | F18: P | G18: P | H18: P | I18: P | J18: WO | K18: P | L18: P | M18: P | N18: P | O18: P | P18: P | Q18: WO | R18: P | S18: P | T18: P | U18: P | V18: P | W18: P | X18: WO | Y18: P | Z18: P | AA18: P | AB18: P | AC18: P | AD18: P | AE18: WO | AF18: P | AG18: P | AH18: P | AI18: =COUNTIF(E18:AH18,"P")+COUNTIF(E18:AH18,"L")+COUNTIF(E18:AH18,"WFO")+COUNTIF(E18:AH18,"OT") -> 26 | AJ18: =COUNTIF(E18:AH18,"A") -> 0 | AK18: =COUNTIF(E18:AH18,"L") -> 0 | AL18: =COUNTIF(E18:AH18,"HD") -> 0 | AM18: =COUNTIF(E18:AH18,"PL")+COUNTIF(E18:AH18,"UL")+COUNTIF(E18:AH18,"VL")+COUNTIF(E18:AH18,"SL") -> 0 | AN18: =COUNTIF(E18:AH18,"WO")+COUNTIF(E18:AH18,"H") -> 4 | AO18: ='03_Roster'!AJ18 -> 0 | AP18: =IFERROR((AI18+AL18*0.5)/(COUNTA(E18:AH18)-AN18),"") -> 1
A19: ='02_Employee_Master'!A17 -> PL-012 | B19: ='02_Employee_Master'!B17 -> Suresh Kumar | C19: ='02_Employee_Master'!D17 -> Sample Receiving | D19: ='02_Employee_Master'!C17 -> Lab Assistant | E19: WO | F19: P | G19: P | H19: P | I19: P | J19: P | K19: P | L19: WO | M19: P | N19: P | O19: P | P19: P | Q19: P | R19: P | S19: WO | T19: P | U19: P | V19: P | W19: P | X19: HD | Y19: P | Z19: WO | AA19: P | AB19: P | AC19: P | AD19: P | AE19: P | AF19: P | AG19: WO | AH19: P | AI19: =COUNTIF(E19:AH19,"P")+COUNTIF(E19:AH19,"L")+COUNTIF(E19:AH19,"WFO")+COUNTIF(E19:AH19,"OT") -> 24 | AJ19: =COUNTIF(E19:AH19,"A") -> 0 | AK19: =COUNTIF(E19:AH19,"L") -> 0 | AL19: =COUNTIF(E19:AH19,"HD") -> 1 | AM19: =COUNTIF(E19:AH19,"PL")+COUNTIF(E19:AH19,"UL")+COUNTIF(E19:AH19,"VL")+COUNTIF(E19:AH19,"SL") -> 0 | AN19: =COUNTIF(E19:AH19,"WO")+COUNTIF(E19:AH19,"H") -> 5 | AO19: ='03_Roster'!AJ19 -> 0 | AP19: =IFERROR((AI19+AL19*0.5)/(COUNTA(E19:AH19)-AN19),"") -> 0.98
... A26: ='02_Employee_Master'!A24 -> PL-019 | B26: ='02_Employee_Master'!B24 -> Kavya Menon | C26: ='02_Employee_Master'!D24 -> Histopathology | D26: ='02_Employee_Master'!C24 -> Lab Technologist | E26: WO | F26: P | G26: P | H26: P | I26: P | J26: P | K26: P | L26: WO | M26: P | N26: P | O26: P | P26: P | Q26: P | R26: P | S26: WO | T26: P | U26: P | V26: P | W26: P | X26: P | Y26: P | Z26: WO | AA26: P | AB26: P | AC26: P | AD26: P | AE26: P | AF26: P | AG26: WO | AH26: L | AI26: =COUNTIF(E26:AH26,"P")+COUNTIF(E26:AH26,"L")+COUNTIF(E26:AH26,"WFO")+COUNTIF(E26:AH26,"OT") -> 25 | AJ26: =COUNTIF(E26:AH26,"A") -> 0 | AK26: =COUNTIF(E26:AH26,"L") -> 1 | AL26: =COUNTIF(E26:AH26,"HD") -> 0 | AM26: =COUNTIF(E26:AH26,"PL")+COUNTIF(E26:AH26,"UL")+COUNTIF(E26:AH26,"VL")+COUNTIF(E26:AH26,"SL") -> 0 | AN26: =COUNTIF(E26:AH26,"WO")+COUNTIF(E26:AH26,"H") -> 5 | AO26: ='03_Roster'!AJ26 -> 0 | AP26: =IFERROR((AI26+AL26*0.5)/(COUNTA(E26:AH26)-AN26),"") -> 1
A27: ='02_Employee_Master'!A25 -> PL-020 | B27: ='02_Employee_Master'!B25 -> Thomas Mathew | C27: ='02_Employee_Master'!D25 -> Sample Receiving | D27: ='02_Employee_Master'!C25 -> Senior Lab Technologist | AI27: =COUNTIF(E27:AH27,"P")+COUNTIF(E27:AH27,"L")+COUNTIF(E27:AH27,"WFO")+COUNTIF(E27:AH27,"OT") -> 0 | AJ27: =COUNTIF(E27:AH27,"A") -> 0 | AK27: =COUNTIF(E27:AH27,"L") -> 0 | AL27: =COUNTIF(E27:AH27,"HD") -> 0 | AM27: =COUNTIF(E27:AH27,"PL")+COUNTIF(E27:AH27,"UL")+COUNTIF(E27:AH27,"VL")+COUNTIF(E27:AH27,"SL") -> 0 | AN27: =COUNTIF(E27:AH27,"WO")+COUNTIF(E27:AH27,"H") -> 0 | AO27: ='03_Roster'!AJ27 -> 0 | AP27: =IFERROR((AI27+AL27*0.5)/(COUNTA(E27:AH27)-AN27),"")
A28: Present headcount (P+L+WFO+OT) | E28: =COUNTIF(E8:E27,"P")+COUNTIF(E8:E27,"L")+COUNTIF(E8:E27,"WFO")+COUNTIF(E8:E27,"OT") -> 16 | F28: =COUNTIF(F8:F27,"P")+COUNTIF(F8:F27,"L")+COUNTIF(F8:F27,"WFO")+COUNTIF(F8:F27,"OT") -> 16 | G28: =COUNTIF(G8:G27,"P")+COUNTIF(G8:G27,"L")+COUNTIF(G8:G27,"WFO")+COUNTIF(G8:G27,"OT") -> 17 | H28: =COUNTIF(H8:H27,"P")+COUNTIF(H8:H27,"L")+COUNTIF(H8:H27,"WFO")+COUNTIF(H8:H27,"OT") -> 15 | I28: =COUNTIF(I8:I27,"P")+COUNTIF(I8:I27,"L")+COUNTIF(I8:I27,"WFO")+COUNTIF(I8:I27,"OT") -> 17 | J28: =COUNTIF(J8:J27,"P")+COUNTIF(J8:J27,"L")+COUNTIF(J8:J27,"WFO")+COUNTIF(J8:J27,"OT") -> 15 | K28: =COUNTIF(K8:K27,"P")+COUNTIF(K8:K27,"L")+COUNTIF(K8:K27,"WFO")+COUNTIF(K8:K27,"OT") -> 15 | L28: =COUNTIF(L8:L27,"P")+COUNTIF(L8:L27,"L")+COUNTIF(L8:L27,"WFO")+COUNTIF(L8:L27,"OT") -> 16 | ... AH28: =COUNTIF(AH8:AH27,"P")+COUNTIF(AH8:AH27,"L")+COUNTIF(AH8:AH27,"WFO")+COUNTIF(AH8:AH27,"OT") -> 16

Sheet 05_Leave
A1: PATHCARE DIAGNOSTICS · Pathology Laboratory
A2: LEAVE MANAGEMENT
A3: Applications · Balances · Approvals · Entitlements from Config leave policy
A5: LEAVE BALANCE SUMMARY (auto from policy + applications)
A6: Emp ID | B6: Employee Name | C6: Department | D6: PL Entitled | E6: PL Used | F6: PL Balance | G6: UL Entitled | H6: UL Used | I6: UL Balance | J6: SL Entitled | K6: SL Used | L6: SL Balance | M6: VL Entitled | N6: VL Used | O6: VL Balance
A7: ='02_Employee_Master'!A6 -> PL-001 | B7: ='02_Employee_Master'!B6 -> Dr. Ananya Mehta | C7: ='02_Employee_Master'!D6 -> Histopathology | D7: ='01_Config'!G29 -> 12 | E7: =SUMIFS($E$30:$E$79,$A$30:$A$79,A7,$D$30:$D$79,"Planned Leave",$H$30:$H$79,"Approved") -> 0 | F7: =D7-E7 -> 12 | G7: ='01_Config'!G30 -> 6 | H7: =SUMIFS($E$30:$E$79,$A$30:$A$79,A7,$D$30:$D$79,"Unplanned Leave",$H$30:$H$79,"Approved") -> 0 | I7: =G7-H7 -> 6 | J7: ='01_Config'!G31 -> 10 | K7: =SUMIFS($E$30:$E$79,$A$30:$A$79,A7,$D$30:$D$79,"Sick Leave",$H$30:$H$79,"Approved") -> 0 | L7: =J7-K7 -> 10 | M7: ='01_Config'!G32 -> 15 | N7: =SUMIFS($E$30:$E$79,$A$30:$A$79,A7,$D$30:$D$79,"Vacation Leave",$H$30:$H$79,"Approved") -> 0 | O7: =M7-N7 -> 15
A8: ='02_Employee_Master'!A7 -> PL-002 | B8: ='02_Employee_Master'!B7 -> Vikram Singh | C8: ='02_Employee_Master'!D7 -> Administration | D8: ='01_Config'!G29 -> 12 | E8: =SUMIFS($E$30:$E$79,$A$30:$A$79,A8,$D$30:$D$79,"Planned Leave",$H$30:$H$79,"Approved") -> 0 | F8: =D8-E8 -> 12 | G8: ='01_Config'!G30 -> 6 | H8: =SUMIFS($E$30:$E$79,$A$30:$A$79,A8,$D$30:$D$79,"Unplanned Leave",$H$30:$H$79,"Approved") -> 0 | I8: =G8-H8 -> 6 | J8: ='01_Config'!G31 -> 10 | K8: =SUMIFS($E$30:$E$79,$A$30:$A$79,A8,$D$30:$D$79,"Sick Leave",$H$30:$H$79,"Approved") -> 0 | L8: =J8-K8 -> 10 | M8: ='01_Config'!G32 -> 15 | N8: =SUMIFS($E$30:$E$79,$A$30:$A$79,A8,$D$30:$D$79,"Vacation Leave",$H$30:$H$79,"Approved") -> 0 | O8: =M8-N8 -> 15
A9: ='02_Employee_Master'!A8 -> PL-003 | B9: ='02_Employee_Master'!B8 -> Sneha Patel | C9: ='02_Employee_Master'!D8 -> Hematology | D9: ='01_Config'!G29 -> 12 | E9: =SUMIFS($E$30:$E$79,$A$30:$A$79,A9,$D$30:$D$79,"Planned Leave",$H$30:$H$79,"Approved") -> 0 | F9: =D9-E9 -> 12 | G9: ='01_Config'!G30 -> 6 | H9: =SUMIFS($E$30:$E$79,$A$30:$A$79,A9,$D$30:$D$79,"Unplanned Leave",$H$30:$H$79,"Approved") -> 0 | I9: =G9-H9 -> 6 | J9: ='01_Config'!G31 -> 10 | K9: =SUMIFS($E$30:$E$79,$A$30:$A$79,A9,$D$30:$D$79,"Sick Leave",$H$30:$H$79,"Approved") -> 0 | L9: =J9-K9 -> 10 | M9: ='01_Config'!G32 -> 15 | N9: =SUMIFS($E$30:$E$79,$A$30:$A$79,A9,$D$30:$D$79,"Vacation Leave",$H$30:$H$79,"Approved") -> 0 | O9: =M9-N9 -> 15
A10: ='02_Employee_Master'!A9 -> PL-004 | B10: ='02_Employee_Master'!B9 -> Rahul Nair | C10: ='02_Employee_Master'!D9 -> Hematology | D10: ='01_Config'!G29 -> 12 | E10: =SUMIFS($E$30:$E$79,$A$30:$A$79,A10,$D$30:$D$79,"Planned Leave",$H$30:$H$79,"Approved") -> 2 | F10: =D10-E10 -> 10 | G10: ='01_Config'!G30 -> 6 | H10: =SUMIFS($E$30:$E$79,$A$30:$A$79,A10,$D$30:$D$79,"Unplanned Leave",$H$30:$H$79,"Approved") -> 0 | I10: =G10-H10 -> 6 | J10: ='01_Config'!G31 -> 10 | K10: =SUMIFS($E$30:$E$79,$A$30:$A$79,A10,$D$30:$D$79,"Sick Leave",$H$30:$H$79,"Approved") -> 0 | L10: =J10-K10 -> 10 | M10: ='01_Config'!G32 -> 15 | N10: =SUMIFS($E$30:$E$79,$A$30:$A$79,A10,$D$30:$D$79,"Vacation Leave",$H$30:$H$79,"Approved") -> 0 | O10: =M10-N10 -> 15
A11: ='02_Employee_Master'!A10 -> PL-005 | B11: ='02_Employee_Master'!B10 -> Fatima Khan | C11: ='02_Employee_Master'!D10 -> Biochemistry | D11: ='01_Config'!G29 -> 12 | E11: =SUMIFS($E$30:$E$79,$A$30:$A$79,A11,$D$30:$D$79,"Planned Leave",$H$30:$H$79,"Approved") -> 0 | F11: =D11-E11 -> 12 | G11: ='01_Config'!G30 -> 6 | H11: =SUMIFS($E$30:$E$79,$A$30:$A$79,A11,$D$30:$D$79,"Unplanned Leave",$H$30:$H$79,"Approved") -> 0 | I11: =G11-H11 -> 6 | J11: ='01_Config'!G31 -> 10 | K11: =SUMIFS($E$30:$E$79,$A$30:$A$79,A11,$D$30:$D$79,"Sick Leave",$H$30:$H$79,"Approved") -> 0 | L11: =J11-K11 -> 10 | M11: ='01_Config'!G32 -> 15 | N11: =SUMIFS($E$30:$E$79,$A$30:$A$79,A11,$D$30:$D$79,"Vacation Leave",$H$30:$H$79,"Approved") -> 0 | O11: =M11-N11 -> 15
A12: ='02_Employee_Master'!A11 -> PL-006 | B12: ='02_Employee_Master'!B11 -> Arjun Reddy | C12: ='02_Employee_Master'!D11 -> Biochemistry | D12: ='01_Config'!G29 -> 12 | E12: =SUMIFS($E$30:$E$79,$A$30:$A$79,A12,$D$30:$D$79,"Planned Leave",$H$30:$H$79,"Approved") -> 0 | F12: =D12-E12 -> 12 | G12: ='01_Config'!G30 -> 6 | H12: =SUMIFS($E$30:$E$79,$A$30:$A$79,A12,$D$30:$D$79,"Unplanned Leave",$H$30:$H$79,"Approved") -> 0 | I12: =G12-H12 -> 6 | J12: ='01_Config'!G31 -> 10 | K12: =SUMIFS($E$30:$E$79,$A$30:$A$79,A12,$D$30:$D$79,"Sick Leave",$H$30:$H$79,"Approved") -> 0 | L12: =J12-K12 -> 10 | M12: ='01_Config'!G32 -> 15 | N12: =SUMIFS($E$30:$E$79,$A$30:$A$79,A12,$D$30:$D$79,"Vacation Leave",$H$30:$H$79,"Approved") -> 0 | O12: =M12-N12 -> 15
A13: ='02_Employee_Master'!A12 -> PL-007 | B13: ='02_Employee_Master'!B12 -> Meera Iyer | C13: ='02_Employee_Master'!D12 -> Microbiology | D13: ='01_Config'!G29 -> 12 | E13: =SUMIFS($E$30:$E$79,$A$30:$A$79,A13,$D$30:$D$79,"Planned Leave",$H$30:$H$79,"Approved") -> 0 | F13: =D13-E13 -> 12 | G13: ='01_Config'!G30 -> 6 | H13: =SUMIFS($E$30:$E$79,$A$30:$A$79,A13,$D$30:$D$79,"Unplanned Leave",$H$30:$H$79,"Approved") -> 0 | I13: =G13-H13 -> 6 | J13: ='01_Config'!G31 -> 10 | K13: =SUMIFS($E$30:$E$79,$A$30:$A$79,A13,$D$30:$D$79,"Sick Leave",$H$30:$H$79,"Approved") -> 1 | L13: =J13-K13 -> 9 | M13: ='01_Config'!G32 -> 15 | N13: =SUMIFS($E$30:$E$79,$A$30:$A$79,A13,$D$30:$D$79,"Vacation Leave",$H$30:$H$79,"Approved") -> 0 | O13: =M13-N13 -> 15
A14: ='02_Employee_Master'!A13 -> PL-008 | B14: ='02_Employee_Master'!B13 -> Karan Malhotra | C14: ='02_Employee_Master'!D13 -> Microbiology | D14: ='01_Config'!G29 -> 12 | E14: =SUMIFS($E$30:$E$79,$A$30:$A$79,A14,$D$30:$D$79,"Planned Leave",$H$30:$H$79,"Approved") -> 0 | F14: =D14-E14 -> 12 | G14: ='01_Config'!G30 -> 6 | H14: =SUMIFS($E$30:$E$79,$A$30:$A$79,A14,$D$30:$D$79,"Unplanned Leave",$H$30:$H$79,"Approved") -> 0 | I14: =G14-H14 -> 6 | J14: ='01_Config'!G31 -> 10 | K14: =SUMIFS($E$30:$E$79,$A$30:$A$79,A14,$D$30:$D$79,"Sick Leave",$H$30:$H$79,"Approved") -> 0 | L14: =J14-K14 -> 10 | M14: ='01_Config'!G32 -> 15 | N14: =SUMIFS($E$30:$E$79,$A$30:$A$79,A14,$D$30:$D$79,"Vacation Leave",$H$30:$H$79,"Approved") -> 0 | O14: =M14-N14 -> 15
A15: ='02_Employee_Master'!A14 -> PL-009 | B15: ='02_Employee_Master'!B14 -> Pooja Sharma | C15: ='02_Employee_Master'!D14 -> Histopathology | D15: ='01_Config'!G29 -> 12 | E15: =SUMIFS($E$30:$E$79,$A$30:$A$79,A15,$D$30:$D$79,"Planned Leave",$H$30:$H$79,"Approved") -> 0 | F15: =D15-E15 -> 12 | G15: ='01_Config'!G30 -> 6 | H15: =SUMIFS($E$30:$E$79,$A$30:$A$79,A15,$D$30:$D$79,"Unplanned Leave",$H$30:$H$79,"Approved") -> 0 | I15: =G15-H15 -> 6 | J15: ='01_Config'!G31 -> 10 | K15: =SUMIFS($E$30:$E$79,$A$30:$A$79,A15,$D$30:$D$79,"Sick Leave",$H$30:$H$79,"Approved") -> 0 | L15: =J15-K15 -> 10 | M15: ='01_Config'!G32 -> 15 | N15: =SUMIFS($E$30:$E$79,$A$30:$A$79,A15,$D$30:$D$79,"Vacation Leave",$H$30:$H$79,"Approved") -> 0 | O15: =M15-N15 -> 15
A16: ='02_Employee_Master'!A15 -> PL-010 | B16: ='02_Employee_Master'!B15 -> Mohammed Irfan | C16: ='02_Employee_Master'!D15 -> Phlebotomy | D16: ='01_Config'!G29 -> 12 | E16: =SUMIFS($E$30:$E$79,$A$30:$A$79,A16,$D$30:$D$79,"Planned Leave",$H$30:$H$79,"Approved") -> 0 | F16: =D16-E16 -> 12 | G16: ='01_Config'!G30 -> 6 | H16: =SUMIFS($E$30:$E$79,$A$30:$A$79,A16,$D$30:$D$79,"Unplanned Leave",$H$30:$H$79,"Approved") -> 1 | I16: =G16-H16 -> 5 | J16: ='01_Config'!G31 -> 10 | K16: =SUMIFS($E$30:$E$79,$A$30:$A$79,A16,$D$30:$D$79,"Sick Leave",$H$30:$H$79,"Approved") -> 0 | L16: =J16-K16 -> 10 | M16: ='01_Config'!G32 -> 15 | N16: =SUMIFS($E$30:$E$79,$A$30:$A$79,A16,$D$30:$D$79,"Vacation Leave",$H$30:$H$79,"Approved") -> 0 | O16: =M16-N16 -> 15
A17: ='02_Employee_Master'!A16 -> PL-011 | B17: ='02_Employee_Master'!B16 -> Lakshmi Devi | C17: ='02_Employee_Master'!D16 -> Phlebotomy | D17: ='01_Config'!G29 -> 12 | E17: =SUMIFS($E$30:$E$79,$A$30:$A$79,A17,$D$30:$D$79,"Planned Leave",$H$30:$H$79,"Approved") -> 1 | F17: =D17-E17 -> 11 | G17: ='01_Config'!G30 -> 6 | H17: =SUMIFS($E$30:$E$79,$A$30:$A$79,A17,$D$30:$D$79,"Unplanned Leave",$H$30:$H$79,"Approved") -> 0 | I17: =G17-H17 -> 6 | J17: ='01_Config'!G31 -> 10 | K17: =SUMIFS($E$30:$E$79,$A$30:$A$79,A17,$D$30:$D$79,"Sick Leave",$H$30:$H$79,"Approved") -> 0 | L17: =J17-K17 -> 10 | M17: ='01_Config'!G32 -> 15 | N17: =SUMIFS($E$30:$E$79,$A$30:$A$79,A17,$D$30:$D$79,"Vacation Leave",$H$30:$H$79,"Approved") -> 0 | O17: =M17-N17 -> 15
A18: ='02_Employee_Master'!A17 -> PL-012 | B18: ='02_Employee_Master'!B17 -> Suresh Kumar | C18: ='02_Employee_Master'!D17 -> Sample Receiving | D18: ='01_Config'!G29 -> 12 | E18: =SUMIFS($E$30:$E$79,$A$30:$A$79,A18,$D$30:$D$79,"Planned Leave",$H$30:$H$79,"Approved") -> 0 | F18: =D18-E18 -> 12 | G18: ='01_Config'!G30 -> 6 | H18: =SUMIFS($E$30:$E$79,$A$30:$A$79,A18,$D$30:$D$79,"Unplanned Leave",$H$30:$H$79,"Approved") -> 0 | I18: =G18-H18 -> 6 | J18: ='01_Config'!G31 -> 10 | K18: =SUMIFS($E$30:$E$79,$A$30:$A$79,A18,$D$30:$D$79,"Sick Leave",$H$30:$H$79,"Approved") -> 0 | L18: =J18-K18 -> 10 | M18: ='01_Config'!G32 -> 15 | N18: =SUMIFS($E$30:$E$79,$A$30:$A$79,A18,$D$30:$D$79,"Vacation Leave",$H$30:$H$79,"Approved") -> 0 | O18: =M18-N18 -> 15
A19: ='02_Employee_Master'!A18 -> PL-013 | B19: ='02_Employee_Master'!B18 -> Nisha Gupta | C19: ='02_Employee_Master'!D18 -> Quality Assurance | D19: ='01_Config'!G29 -> 12 | E19: =SUMIFS($E$30:$E$79,$A$30:$A$79,A19,$D$30:$D$79,"Planned Leave",$H$30:$H$79,"Approved") -> 0 | F19: =D19-E19 -> 12 | G19: ='01_Config'!G30 -> 6 | H19: =SUMIFS($E$30:$E$79,$A$30:$A$79,A19,$D$30:$D$79,"Unplanned Leave",$H$30:$H$79,"Approved") -> 0 | I19: =G19-H19 -> 6 | J19: ='01_Config'!G31 -> 10 | K19: =SUMIFS($E$30:$E$79,$A$30:$A$79,A19,$D$30:$D$79,"Sick Leave",$H$30:$H$79,"Approved") -> 0 | L19: =J19-K19 -> 10 | M19: ='01_Config'!G32 -> 15 | N19: =SUMIFS($E$30:$E$79,$A$30:$A$79,A19,$D$30:$D$79,"Vacation Leave",$H$30:$H$79,"Approved") -> 0 | O19: =M19-N19 -> 15
A20: ='02_Employee_Master'!A19 -> PL-014 | B20: ='02_Employee_Master'!B19 -> Deepak Joshi | C20: ='02_Employee_Master'!D19 -> Hematology | D20: ='01_Config'!G29 -> 12 | E20: =SUMIFS($E$30:$E$79,$A$30:$A$79,A20,$D$30:$D$79,"Planned Leave",$H$30:$H$79,"Approved") -> 0 | F20: =D20-E20 -> 12 | G20: ='01_Config'!G30 -> 6 | H20: =SUMIFS($E$30:$E$79,$A$30:$A$79,A20,$D$30:$D$79,"Unplanned Leave",$H$30:$H$79,"Approved") -> 0 | I20: =G20-H20 -> 6 | J20: ='01_Config'!G31 -> 10 | K20: =SUMIFS($E$30:$E$79,$A$30:$A$79,A20,$D$30:$D$79,"Sick Leave",$H$30:$H$79,"Approved") -> 0 | L20: =J20-K20 -> 10 | M20: ='01_Config'!G32 -> 15 | N20: =SUMIFS($E$30:$E$79,$A$30:$A$79,A20,$D$30:$D$79,"Vacation Leave",$H$30:$H$79,"Approved") -> 0 | O20: =M20-N20 -> 15
A21: ='02_Employee_Master'!A20 -> PL-015 | B21: ='02_Employee_Master'!B20 -> Anjali Verma | C21: ='02_Employee_Master'!D20 -> Administration | D21: ='01_Config'!G29 -> 12 | E21: =SUMIFS($E$30:$E$79,$A$30:$A$79,A21,$D$30:$D$79,"Planned Leave",$H$30:$H$79,"Approved") -> 0 | F21: =D21-E21 -> 12 | G21: ='01_Config'!G30 -> 6 | H21: =SUMIFS($E$30:$E$79,$A$30:$A$79,A21,$D$30:$D$79,"Unplanned Leave",$H$30:$H$79,"Approved") -> 0 | I21: =G21-H21 -> 6 | J21: ='01_Config'!G31 -> 10 | K21: =SUMIFS($E$30:$E$79,$A$30:$A$79,A21,$D$30:$D$79,"Sick Leave",$H$30:$H$79,"Approved") -> 0 | L21: =J21-K21 -> 10 | M21: ='01_Config'!G32 -> 15 | N21: =SUMIFS($E$30:$E$79,$A$30:$A$79,A21,$D$30:$D$79,"Vacation Leave",$H$30:$H$79,"Approved") -> 0 | O21: =M21-N21 -> 15
A22: ='02_Employee_Master'!A21 -> PL-016 | B22: ='02_Employee_Master'!B21 -> Ravi Teja | C22: ='02_Employee_Master'!D21 -> Biochemistry | D22: ='01_Config'!G29 -> 12 | E22: =SUMIFS($E$30:$E$79,$A$30:$A$79,A22,$D$30:$D$79,"Planned Leave",$H$30:$H$79,"Approved") -> 0 | F22: =D22-E22 -> 12 | G22: ='01_Config'!G30 -> 6 | H22: =SUMIFS($E$30:$E$79,$A$30:$A$79,A22,$D$30:$D$79,"Unplanned Leave",$H$30:$H$79,"Approved") -> 0 | I22: =G22-H22 -> 6 | J22: ='01_Config'!G31 -> 10 | K22: =SUMIFS($E$30:$E$79,$A$30:$A$79,A22,$D$30:$D$79,"Sick Leave",$H$30:$H$79,"Approved") -> 2 | L22: =J22-K22 -> 8 | M22: ='01_Config'!G32 -> 15 | N22: =SUMIFS($E$30:$E$79,$A$30:$A$79,A22,$D$30:$D$79,"Vacation Leave",$H$30:$H$79,"Approved") -> 0 | O22: =M22-N22 -> 15
A23: ='02_Employee_Master'!A22 -> PL-017 | B23: ='02_Employee_Master'!B22 -> Geeta Rao | C23: ='02_Employee_Master'!D22 -> Microbiology | D23: ='01_Config'!G29 -> 12 | E23: =SUMIFS($E$30:$E$79,$A$30:$A$79,A23,$D$30:$D$79,"Planned Leave",$H$30:$H$79,"Approved") -> 0 | F23: =D23-E23 -> 12 | G23: ='01_Config'!G30 -> 6 | H23: =SUMIFS($E$30:$E$79,$A$30:$A$79,A23,$D$30:$D$79,"Unplanned Leave",$H$30:$H$79,"Approved") -> 0 | I23: =G23-H23 -> 6 | J23: ='01_Config'!G31 -> 10 | K23: =SUMIFS($E$30:$E$79,$A$30:$A$79,A23,$D$30:$D$79,"Sick Leave",$H$30:$H$79,"Approved") -> 0 | L23: =J23-K23 -> 10 | M23: ='01_Config'!G32 -> 15 | N23: =SUMIFS($E$30:$E$79,$A$30:$A$79,A23,$D$30:$D$79,"Vacation Leave",$H$30:$H$79,"Approved") -> 0 | O23: =M23-N23 -> 15
A24: ='02_Employee_Master'!A23 -> PL-018 | B24: ='02_Employee_Master'!B23 -> Imran Sheikh | C24: ='02_Employee_Master'!D23 -> Phlebotomy | D24: ='01_Config'!G29 -> 12 | E24: =SUMIFS($E$30:$E$79,$A$30:$A$79,A24,$D$30:$D$79,"Planned Leave",$H$30:$H$79,"Approved") -> 0 | F24: =D24-E24 -> 12 | G24: ='01_Config'!G30 -> 6 | H24: =SUMIFS($E$30:$E$79,$A$30:$A$79,A24,$D$30:$D$79,"Unplanned Leave",$H$30:$H$79,"Approved") -> 0 | I24: =G24-H24 -> 6 | J24: ='01_Config'!G31 -> 10 | K24: =SUMIFS($E$30:$E$79,$A$30:$A$79,A24,$D$30:$D$79,"Sick Leave",$H$30:$H$79,"Approved") -> 0 | L24: =J24-K24 -> 10 | M24: ='01_Config'!G32 -> 15 | N24: =SUMIFS($E$30:$E$79,$A$30:$A$79,A24,$D$30:$D$79,"Vacation Leave",$H$30:$H$79,"Approved") -> 0 | O24: =M24-N24 -> 15
A25: ='02_Employee_Master'!A24 -> PL-019 | B25: ='02_Employee_Master'!B24 -> Kavya Menon | C25: ='02_Employee_Master'!D24 -> Histopathology | D25: ='01_Config'!G29 -> 12 | E25: =SUMIFS($E$30:$E$79,$A$30:$A$79,A25,$D$30:$D$79,"Planned Leave",$H$30:$H$79,"Approved") -> 0 | F25: =D25-E25 -> 12 | G25: ='01_Config'!G30 -> 6 | H25: =SUMIFS($E$30:$E$79,$A$30:$A$79,A25,$D$30:$D$79,"Unplanned Leave",$H$30:$H$79,"Approved") -> 0 | I25: =G25-H25 -> 6 | J25: ='01_Config'!G31 -> 10 | K25: =SUMIFS($E$30:$E$79,$A$30:$A$79,A25,$D$30:$D$79,"Sick Leave",$H$30:$H$79,"Approved") -> 0 | L25: =J25-K25 -> 10 | M25: ='01_Config'!G32 -> 15 | N25: =SUMIFS($E$30:$E$79,$A$30:$A$79,A25,$D$30:$D$79,"Vacation Leave",$H$30:$H$79,"Approved") -> 0 | O25: =M25-N25 -> 15
A26: ='02_Employee_Master'!A25 -> PL-020 | B26: ='02_Employee_Master'!B25 -> Thomas Mathew | C26: ='02_Employee_Master'!D25 -> Sample Receiving | D26: ='01_Config'!G29 -> 12 | E26: =SUMIFS($E$30:$E$79,$A$30:$A$79,A26,$D$30:$D$79,"Planned Leave",$H$30:$H$79,"Approved") -> 0 | F26: =D26-E26 -> 12 | G26: ='01_Config'!G30 -> 6 | H26: =SUMIFS($E$30:$E$79,$A$30:$A$79,A26,$D$30:$D$79,"Unplanned Leave",$H$30:$H$79,"Approved") -> 0 | I26: =G26-H26 -> 6 | J26: ='01_Config'!G31 -> 10 | K26: =SUMIFS($E$30:$E$79,$A$30:$A$79,A26,$D$30:$D$79,"Sick Leave",$H$30:$H$79,"Approved") -> 0 | L26: =J26-K26 -> 10 | M26: ='01_Config'!G32 -> 15 | N26: =SUMIFS($E$30:$E$79,$A$30:$A$79,A26,$D$30:$D$79,"Vacation Leave",$H$30:$H$79,"Approved") -> 0 | O26: =M26-N26 -> 15
A28: LEAVE APPLICATIONS & APPROVAL WORKFLOW
A29: Emp ID | B29: Employee Name | C29: Department | D29: Leave Type | E29: Days | F29: From Date | G29: To Date | H29: Approval Status | I29: Approver | J29: Manager Remarks
A30: PL-004 | B30: =IFERROR(VLOOKUP(A30,'02_Employee_Master'!$A$6:$B$25,2,FALSE),"") -> Rahul Nair | C30: =IFERROR(VLOOKUP(A30,'02_Employee_Master'!$A$6:$D$25,4,FALSE),"") -> Hematology | D30: Planned Leave | E30: 2 | F30: 46273 | G30: 46274 | H30: Approved | I30: Sneha Patel | J30: Family function — approved
A31: PL-007 | B31: =IFERROR(VLOOKUP(A31,'02_Employee_Master'!$A$6:$B$25,2,FALSE),"") -> Meera Iyer | C31: =IFERROR(VLOOKUP(A31,'02_Employee_Master'!$A$6:$D$25,4,FALSE),"") -> Microbiology | D31: Sick Leave | E31: 1 | F31: 46268 | G31: 46268 | H31: Approved | I31: Vikram Singh | J31: Fever — certificate received
A32: PL-010 | B32: =IFERROR(VLOOKUP(A32,'02_Employee_Master'!$A$6:$B$25,2,FALSE),"") -> Mohammed Irfan | C32: =IFERROR(VLOOKUP(A32,'02_Employee_Master'!$A$6:$D$25,4,FALSE),"") -> Phlebotomy | D32: Unplanned Leave | E32: 1 | F32: 46276 | G32: 46276 | H32: Approved | I32: Vikram Singh | J32: Emergency at home
A33: PL-005 | B33: =IFERROR(VLOOKUP(A33,'02_Employee_Master'!$A$6:$B$25,2,FALSE),"") -> Fatima Khan | C33: =IFERROR(VLOOKUP(A33,'02_Employee_Master'!$A$6:$D$25,4,FALSE),"") -> Biochemistry | D33: Vacation Leave | E33: 3 | F33: 46287 | G33: 46289 | H33: Pending | I33: Vikram Singh
A34: PL-014 | B34: =IFERROR(VLOOKUP(A34,'02_Employee_Master'!$A$6:$B$25,2,FALSE),"") -> Deepak Joshi | C34: =IFERROR(VLOOKUP(A34,'02_Employee_Master'!$A$6:$D$25,4,FALSE),"") -> Hematology | D34: Planned Leave | E34: 1 | F34: 46280 | G34: 46280 | H34: Rejected | I34: Sneha Patel | J34: Short staffing on that day
A35: PL-016 | B35: =IFERROR(VLOOKUP(A35,'02_Employee_Master'!$A$6:$B$25,2,FALSE),"") -> Ravi Teja | C35: =IFERROR(VLOOKUP(A35,'02_Employee_Master'!$A$6:$D$25,4,FALSE),"") -> Biochemistry | D35: Sick Leave | E35: 2 | F35: 46269 | G35: 46270 | H35: Approved | I35: Fatima Khan | J35: Medical advice
A36: PL-011 | B36: =IFERROR(VLOOKUP(A36,'02_Employee_Master'!$A$6:$B$25,2,FALSE),"") -> Lakshmi Devi | C36: =IFERROR(VLOOKUP(A36,'02_Employee_Master'!$A$6:$D$25,4,FALSE),"") -> Phlebotomy | D36: Planned Leave | E36: 1 | F36: 46283 | G36: 46283 | H36: Approved | I36: Vikram Singh | J36: OK
A37: PL-008 | B37: =IFERROR(VLOOKUP(A37,'02_Employee_Master'!$A$6:$B$25,2,FALSE),"") -> Karan Malhotra | C37: =IFERROR(VLOOKUP(A37,'02_Employee_Master'!$A$6:$D$25,4,FALSE),"") -> Microbiology | D37: Unplanned Leave | E37: 1 | F37: 46267 | G37: 46267 | H37: Pending | I37: Meera Iyer | J37: Awaiting confirmation
B38: =IF(A38="","",IFERROR(VLOOKUP(A38,'02_Employee_Master'!$A$6:$B$25,2,FALSE),"")) | C38: =IF(A38="","",IFERROR(VLOOKUP(A38,'02_Employee_Master'!$A$6:$D$25,4,FALSE),""))
B39: =IF(A39="","",IFERROR(VLOOKUP(A39,'02_Employee_Master'!$A$6:$B$25,2,FALSE),"")) | C39: =IF(A39="","",IFERROR(VLOOKUP(A39,'02_Employee_Master'!$A$6:$D$25,4,FALSE),""))
B40: =IF(A40="","",IFERROR(VLOOKUP(A40,'02_Employee_Master'!$A$6:$B$25,2,FALSE),"")) | C40: =IF(A40="","",IFERROR(VLOOKUP(A40,'02_Employee_Master'!$A$6:$D$25,4,FALSE),""))
B41: =IF(A41="","",IFERROR(VLOOKUP(A41,'02_Employee_Master'!$A$6:$B$25,2,FALSE),"")) | C41: =IF(A41="","",IFERROR(VLOOKUP(A41,'02_Employee_Master'!$A$6:$D$25,4,FALSE),""))
B42: =IF(A42="","",IFERROR(VLOOKUP(A42,'02_Employee_Master'!$A$6:$B$25,2,FALSE),"")) | C42: =IF(A42="","",IFERROR(VLOOKUP(A42,'02_Employee_Master'!$A$6:$D$25,4,FALSE),""))
...

Sheet 06_Dashboard
A1: PATHCARE DIAGNOSTICS · Pathology Laboratory
A2: WORKFORCE DASHBOARD
A3: Live management view · September 2026 · Formula-driven from Master / Roster / Attendance / Leave
B5: KEY PERFORMANCE INDICATORS
B6: TOTAL EMPLOYEES | C6: ACTIVE STAFF | D6: INACTIVE | E6: ON LEAVE (apps) | F6: PENDING LEAVE
B7: =COUNTA('02_Employee_Master'!A6:A45) -> 20 | C7: =COUNTIF('02_Employee_Master'!L6:L45,"Active") -> 19 | D7: =COUNTIF('02_Employee_Master'!L6:L45,"Inactive") -> 1 | E7: =COUNTIF('05_Leave'!H30:H79,"Approved") -> 5 | F7: =COUNTIF('05_Leave'!H30:H79,"Pending") -> 2
B9: ATTENDANCE SNAPSHOT — Day 15 of month (change formula day refs as needed)
B10: Present | C10: Absent | D10: Late | E10: On Leave | F10: Att % (month avg)
B11: =COUNTIF('04_Attendance'!S8:S27,"P")+COUNTIF('04_Attendance'!S8:S27,"L")+COUNTIF('04_Attendance'!S8:S27,"WFO")+COUNTIF('04_Attendance'!S8:S27,"OT") -> 16 | C11: =COUNTIF('04_Attendance'!S8:S27,"A") -> 0 | D11: =COUNTIF('04_Attendance'!S8:S27,"L") -> 0 | E11: =COUNTIF('04_Attendance'!S8:S27,"PL")+COUNTIF('04_Attendance'!S8:S27,"UL")+COUNTIF('04_Attendance'!S8:S27,"VL")+COUNTIF('04_Attendance'!S8:S27,"SL") -> 0 | F11: =IFERROR(AVERAGE('04_Attendance'!AP8:AP27),0) -> 0.98975709
B13: SHIFT-WISE HEADCOUNT — Roster Day 15 | H13: DEPARTMENT-WISE ACTIVE HEADCOUNT
B14: Morning | C14: Evening | D14: Night | H14: Department | I14: Active | J14: Avg Att % | K14: On Leave (bal SL used)
B15: =COUNTIF('03_Roster'!S8:S27,"M") -> 11 | C15: =COUNTIF('03_Roster'!S8:S27,"E") -> 4 | D15: =COUNTIF('03_Roster'!S8:S27,"N") -> 1 | H15: Hematology | I15: =COUNTIFS('02_Employee_Master'!$D$6:$D$45,H15,'02_Employee_Master'!$L$6:$L$45,"Active") -> 3 | J15: =IFERROR(AVERAGEIF('04_Attendance'!$C$8:$C$27,H15,'04_Attendance'!$AP$8:$AP$27),"") -> 1 | K15: =SUMIF('05_Leave'!$C$7:$C$26,H15,'05_Leave'!$K$7:$K$26) -> 0
H16: Biochemistry | I16: =COUNTIFS('02_Employee_Master'!$D$6:$D$45,H16,'02_Employee_Master'!$L$6:$L$45,"Active") -> 3 | J16: =IFERROR(AVERAGEIF('04_Attendance'!$C$8:$C$27,H16,'04_Attendance'!$AP$8:$AP$27),"") -> 0.99333333 | K16: =SUMIF('05_Leave'!$C$7:$C$26,H16,'05_Leave'!$K$7:$K$26) -> 2
B17: LEAVE SUMMARY (this period) | H17: Microbiology | I17: =COUNTIFS('02_Employee_Master'!$D$6:$D$45,H17,'02_Employee_Master'!$L$6:$L$45,"Active") -> 3 | J17: =IFERROR(AVERAGEIF('04_Attendance'!$C$8:$C$27,H17,'04_Attendance'!$AP$8:$AP$27),"") -> 0.99358974 | K17: =SUMIF('05_Leave'!$C$7:$C$26,H17,'05_Leave'!$K$7:$K$26) -> 1
B18: Approved applications | D18: =COUNTIF('05_Leave'!H30:H79,"Approved") -> 5 | H18: Histopathology | I18: =COUNTIFS('02_Employee_Master'!$D$6:$D$45,H18,'02_Employee_Master'!$L$6:$L$45,"Active") -> 3 | J18: =IFERROR(AVERAGEIF('04_Attendance'!$C$8:$C$27,H18,'04_Attendance'!$AP$8:$AP$27),"") -> 0.97435897 | K18: =SUMIF('05_Leave'!$C$7:$C$26,H18,'05_Leave'!$K$7:$K$26) -> 0
B19: Pending approvals | D19: =COUNTIF('05_Leave'!H30:H79,"Pending") -> 2 | H19: Phlebotomy | I19: =COUNTIFS('02_Employee_Master'!$D$6:$D$45,H19,'02_Employee_Master'!$L$6:$L$45,"Active") -> 3 | J19: =IFERROR(AVERAGEIF('04_Attendance'!$C$8:$C$27,H19,'04_Attendance'!$AP$8:$AP$27),"") -> 1 | K19: =SUMIF('05_Leave'!$C$7:$C$26,H19,'05_Leave'!$K$7:$K$26) -> 0
B20: Rejected | D20: =COUNTIF('05_Leave'!H30:H79,"Rejected") -> 1 | H20: Sample Receiving | I20: =COUNTIFS('02_Employee_Master'!$D$6:$D$45,H20,'02_Employee_Master'!$L$6:$L$45,"Active") -> 1 | J20: =IFERROR(AVERAGEIF('04_Attendance'!$C$8:$C$27,H20,'04_Attendance'!$AP$8:$AP$27),"") -> 0.98 | K20: =SUMIF('05_Leave'!$C$7:$C$26,H20,'05_Leave'!$K$7:$K$26) -> 0
B21: Total leave days approved | D21: =SUMIF('05_Leave'!H30:H79,"Approved",'05_Leave'!E30:E79) -> 7 | H21: Quality Assurance | I21: =COUNTIFS('02_Employee_Master'!$D$6:$D$45,H21,'02_Employee_Master'!$L$6:$L$45,"Active") -> 1 | J21: =IFERROR(AVERAGEIF('04_Attendance'!$C$8:$C$27,H21,'04_Attendance'!$AP$8:$AP$27),"") -> 1 | K21: =SUMIF('05_Leave'!$C$7:$C$26,H21,'05_Leave'!$K$7:$K$26) -> 0
H22: Administration | I22: =COUNTIFS('02_Employee_Master'!$D$6:$D$45,H22,'02_Employee_Master'!$L$6:$L$45,"Active") -> 2 | J22: =IFERROR(AVERAGEIF('04_Attendance'!$C$8:$C$27,H22,'04_Attendance'!$AP$8:$AP$27),"") -> 0.97076923 | K22: =SUMIF('05_Leave'!$C$7:$C$26,H22,'05_Leave'!$K$7:$K$26) -> 0
B24: MONTHLY ATTENDANCE TREND (Present headcount by day)
B25: Day | C25: Present
B26: 1 | C26: ='04_Attendance'!E28 -> 16
B27: 2 | C27: ='04_Attendance'!F28 -> 16
B28: 3 | C28: ='04_Attendance'!G28 -> 17
B29: 4 | C29: ='04_Attendance'!H28 -> 15
B30: 5 | C30: ='04_Attendance'!I28 -> 17
B31: 6 | C31: ='04_Attendance'!J28 -> 15
B32: 7 | C32: ='04_Attendance'!K28 -> 15
B33: 8 | C33: ='04_Attendance'!L28 -> 16
B34: 9 | C34: ='04_Attendance'!M28 -> 15
B35: 10 | C35: ='04_Attendance'!N28 -> 17
B36: 11 | C36: ='04_Attendance'!O28 -> 16
B37: 12 | C37: ='04_Attendance'!P28 -> 17
B38: 13 | C38: ='04_Attendance'!Q28 -> 16
B39: 14 | C39: ='04_Attendance'!R28 -> 16
B40: 15 | C40: ='04_Attendance'!S28 -> 16
B41: 16 | C41: ='04_Attendance'!T28 -> 16
B42: 17 | C42: ='04_Attendance'!U28 -> 17
B43: 18 | C43: ='04_Attendance'!V28 -> 16
B44: 19 | C44: ='04_Attendance'!W28 -> 17
...
