Workbook

Sheet 00_Home
A1: PATHCARE DIAGNOSTICS · Pathology Laboratory
A2: EMPLOYEE ATTENDANCE & ROSTER MANAGEMENT
A3: Workforce HR system · Single source of truth for staff, shifts, attendance & leave
B5: WORKBOOK NAVIGATION
B6: Sheet | C6: Purpose | D6: Edit here?
B7: 01_Config | C7: Shifts, attendance codes, leave types, departments, public holidays, leave policy. | D7: Yes — setup only
B8: 02_Employee_Master | C8: Master employee register. All other sheets pull names/IDs from here. | D8: Yes — HR master
B9: 03_Roster | C9: Full-month view (auto from Week sheets). Set Month/Year here. Use week buttons to edit. | D9: View + period
B10: W1–W5_Roster | C10: Week-wise roster (Days 1–7, 8–14, 15–21, 22–28, 29–31). Edit shifts here. | D10: Yes — weekly edit
B11: 04_Attendance | C11: Daily attendance marks linked to roster month. Color-coded statuses. | D11: Yes — daily mark
B12: 05_Leave | C12: Leave applications, balances, approval workflow, manager remarks. | D12: Yes — leave desk
B13: 06_Dashboard | C13: Live KPIs, shift headcount, dept stats, trends. Formula-driven — do not type. | D13: No — auto
B15: WEEK ROSTER SHORTCUTS (click to open)
B16: ▶ Week 1 (Days 1–7) | C16: ▶ Week 2 (Days 8–14) | D16: ▶ Week 3 (Days 15–21)
B17: ▶ Week 4 (Days 22–28) | C17: ▶ Week 5 (Days 29–31) | D17: 📅 Full Month
B19: OPERATING RULES 1. Maintain employees only on Employee Master (Active/Inactive). 2. Set Month / Year on 03_Roster (B5 / D5). Enter shifts on Week 1–5 sheets (buttons above). 3. Full Month roster mirrors weeks automatically. Then mark Attendance daily. 4. Leave sheet updates balances; Dashboard recalculates from live data.
B23: WHEN THE MONTH CHANGES — DO THIS
B24: Step 1 | C24: Optional archive: File → Save As → Pathology_Roster_YYYY-MM.xlsx
B25: Step 2 | C25: 03_Roster → set B5 = new month, D5 = year.
B26: Step 3 | C26: Open each Week 1–5 sheet → clear old marks → enter new week roster.
B27: Step 4 | C27: Full Month updates from weeks. Clear & mark 04_Attendance for the new month.
B28: Step 5 | C28: Update holidays / leave as needed. Check Dashboard.
B30: CURRENT PERIOD | C30: ='03_Roster'!B5 | D30: ='03_Roster'!D5

Sheet 01_Config
A1: PATHCARE DIAGNOSTICS · Pathology Laboratory
A2: SYSTEM CONFIGURATION
A3: Controlled lists for drop-downs · Change carefully — used across the workbook
B5: SHIFT CODES | F5: ATTENDANCE CODES
B6: Code | C6: Shift | D6: Timing | F6: Code | G6: Meaning | H6: Fill | I6: Font
B7: M | C7: Morning | D7: 06:00–14:00 | F7: P | G7: Present | H7: D4EDDA | I7: 1B7A4E
B8: E | C8: Evening | D8: 14:00–22:00 | F8: A | G8: Absent | H8: F8D7DA | I8: B71C1C
B9: N | C9: Night | D9: 22:00–06:00 | F9: L | G9: Late Coming | H9: FFF3CD | I9: B78103
B10: WO | C10: Weekly Off | D10: — | F10: HD | G10: Half Day | H10: FFE0B2 | I10: E65100
B11: PH | C11: Public Holiday | D11: — | F11: WFO | G11: Work From Office | H11: D6E4F0 | I11: 0D47A1
B12: LV | C12: Leave | D12: — | F12: PL | G12: Planned Leave | H12: EDE7F6 | I12: 5E35B1
B13: TR | C13: Training | D13: — | F13: UL | G13: Unscheduled Leave | H13: FCE4EC | I13: AD1457
F14: VL | G14: Vacation Leave | H14: E0F7FA | I14: 00838F
F15: SL | G15: Sick Leave | H15: FFEBEE | I15: C62828
B16: DEPARTMENTS | C16: DESIGNATIONS | D16: EMPLOYMENT TYPE | F16: SHIFT ELIGIBILITY | G16: LEAVE TYPES | H16: LEAVE STATUS | I16: EMPLOYEE STATUS
B17: Hematology | C17: Lab Manager | D17: Permanent | F17: All Shifts | G17: Planned Leave | H17: Pending | I17: Active
B18: Biochemistry | C18: Pathologist | D18: Contract | F18: Morning Only | G18: Unplanned Leave | H18: Approved | I18: Inactive
B19: Microbiology | C19: Senior Lab Technologist | D19: Trainee | F19: Morning/Evening | G19: Sick Leave | H19: Rejected
B20: Histopathology | C20: Lab Technologist | D20: Part-time | F20: Night Eligible | G20: Vacation Leave | H20: Cancelled
B21: Phlebotomy | C21: Lab Assistant
B22: Sample Receiving | C22: Phlebotomist
B23: Quality Assurance | C23: QA Officer
B24: Administration | C24: Receptionist
B27: PUBLIC HOLIDAYS (update annually) | F27: LEAVE POLICY (annual entitlement days)
B28: Date | C28: Holiday Name | D28: Applies | F28: Leave Type | G28: Annual Days | H28: Carry Forward | I28: Notes
B29: 46048 | C29: Republic Day | D29: Yes | F29: Planned Leave | G29: 12 | H29: Max 5 | I29: Requires prior approval
B30: 46095 | C30: Holi | D30: Yes | F30: Unplanned Leave | G30: 6 | H30: No | I30: Inform same day
B31: 46249 | C31: Independence Day | D31: Yes | F31: Sick Leave | G31: 10 | H31: No | I31: Medical certificate > 2 days
B32: 46297 | C32: Gandhi Jayanti | D32: Yes | F32: Vacation Leave | G32: 15 | H32: Max 7 | I32: Plan 15 days ahead
B33: 46315 | C33: Diwali | D33: Yes
B34: 46381 | C34: Christmas | D34: Yes

Sheet 02_Employee_Master
A1: PATHCARE DIAGNOSTICS · Pathology Laboratory
A2: EMPLOYEE MASTER REGISTER
A3: Single source of truth · Roster, Attendance, Leave & Dashboard reference this sheet
A5: Employee ID | B5: Employee Name | C5: Designation | D5: Department | E5: Reporting Manager | F5: Date of Joining | G5: Employment Type | H5: Shift Eligibility | I5: Contact Number | J5: Email ID | K5: Emergency Contact | L5: Status
A6: PL-001 | B6: Dr. Ananya Mehta | C6: Pathologist | D6: Histopathology | E6: Lab Director | F6: 43536 | G6: Permanent | H6: Morning Only | I6: 9876543210 | J6: ananya.mehta@pathlab.example | K6: Rajesh Mehta — 9876500001 | L6: Active
A7: PL-002 | B7: Vikram Singh | C7: Lab Manager | D7: Administration | E7: Lab Director | F7: 43252 | G7: Permanent | H7: All Shifts | I7: 9876543211 | J7: vikram.singh@pathlab.example | K7: Priya Singh — 9876500002 | L7: Active
A8: PL-003 | B8: Sneha Patel | C8: Senior Lab Technologist | D8: Hematology | E8: Vikram Singh | F8: 43845 | G8: Permanent | H8: All Shifts | I8: 9876543212 | J8: sneha.patel@pathlab.example | K8: Amit Patel — 9876500003 | L8: Active
A9: PL-004 | B9: Rahul Nair | C9: Lab Technologist | D9: Hematology | E9: Sneha Patel | F9: 44428 | G9: Permanent | H9: All Shifts | I9: 9876543213 | J9: rahul.nair@pathlab.example | K9: Deepa Nair — 9876500004 | L9: Active
A10: PL-005 | B10: Fatima Khan | C10: Lab Technologist | D10: Biochemistry | E10: Vikram Singh | F10: 44140 | G10: Permanent | H10: Morning/Evening | I10: 9876543214 | J10: fatima.khan@pathlab.example | K10: Imran Khan — 9876500005 | L10: Active
A11: PL-006 | B11: Arjun Reddy | C11: Lab Technologist | D11: Biochemistry | E11: Fatima Khan | F11: 44606 | G11: Permanent | H11: All Shifts | I11: 9876543215 | J11: arjun.reddy@pathlab.example | K11: Kavitha Reddy — 9876500006 | L11: Active
A12: PL-007 | B12: Meera Iyer | C12: Senior Lab Technologist | D12: Microbiology | E12: Vikram Singh | F12: 43709 | G12: Permanent | H12: Morning/Evening | I12: 9876543216 | J12: meera.iyer@pathlab.example | K12: Suresh Iyer — 9876500007 | L12: Active
A13: PL-008 | B13: Karan Malhotra | C13: Lab Technologist | D13: Microbiology | E13: Meera Iyer | F13: 45026 | G13: Contract | H13: All Shifts | I13: 9876543217 | J13: karan.malhotra@pathlab.example | K13: Neha Malhotra — 9876500008 | L13: Active
A14: PL-009 | B14: Pooja Sharma | C14: Lab Assistant | D14: Histopathology | E14: Dr. Ananya Mehta | F14: 44334 | G14: Permanent | H14: Morning Only | I14: 9876543218 | J14: pooja.sharma@pathlab.example | K14: Ravi Sharma — 9876500009 | L14: Active
A15: PL-010 | B15: Mohammed Irfan | C15: Phlebotomist | D15: Phlebotomy | E15: Vikram Singh | F15: 44743 | G15: Permanent | H15: Morning/Evening | I15: 9876543219 | J15: m.irfan@pathlab.example | K15: Ayesha Irfan — 9876500010 | L15: Active
A16: PL-011 | B16: Lakshmi Devi | C16: Phlebotomist | D16: Phlebotomy | E16: Vikram Singh | F16: 43912 | G16: Permanent | H16: Morning Only | I16: 9876543220 | J16: lakshmi.devi@pathlab.example | K16: Venkat Devi — 9876500011 | L16: Active
A17: PL-012 | B17: Suresh Kumar | C17: Lab Assistant | D17: Sample Receiving | E17: Vikram Singh | F17: 44536 | G17: Permanent | H17: All Shifts | I17: 9876543221 | J17: suresh.kumar@pathlab.example | K17: Anita Kumar — 9876500012 | L17: Active
... A25: PL-020 | B25: Thomas Mathew | C25: Senior Lab Technologist | D25: Sample Receiving | E25: Vikram Singh | F25: 43423 | G25: Permanent | H25: All Shifts | I25: 9876543229 | J25: thomas.mathew@pathlab.example | K25: Mary Mathew — 9876500020 | L25: Inactive
A47: Total rows | B47: =COUNTA(A6:A45) | C47: Active | D47: =COUNTIF(L6:L45,"Active") | E47: Inactive | F47: =COUNTIF(L6:L45,"Inactive")

Sheet 03_Roster
A1: PATHCARE DIAGNOSTICS · Pathology Laboratory
A2: MONTHLY SHIFT ROSTER
A3: Pathology Lab scheduling · Change Month (B5) & Year (D5) for a new period · M/E/N/WO/PH/LV/TR
A4: GO → | B4: Full Month | C4: ▶ Week 1 | D4: ▶ Week 2 | E4: ▶ Week 3 | F4: ▶ Week 4 | G4: ▶ Week 5 | H4: Click a week button to open that week’s roster (edit there — Full Month syncs automatically)
A5: Month | B5: 9 | C5: Year | D5: 2026 | E5: NEW MONTH: change B5 & D5 → use Week 1–5 buttons below to enter roster week-by-week → Full Month auto-updates. Grey columns = day does not exist in that month.
A6: Emp ID | B6: Employee Name | C6: Department | D6: Designation | E6: 1 | F6: 2 | G6: 3 | H6: 4 | I6: 5 | J6: 6 | K6: 7 | L6: 8 | M6: 9 | N6: 10 | O6: 11 | P6: 12 | Q6: 13 | R6: 14 | S6: 15 | T6: 16 | U6: 17 | V6: 18 | W6: 19 | X6: 20 | Y6: 21 | Z6: 22 | AA6: 23 | AB6: 24 | AC6: 25 | AD6: 26 | AE6: 27 | AF6: 28 | AG6: 29 | AH6: 30 | AI6: 31 | AJ6: WO Days | AK6: OT Hours | AL6: Backup Resource | AM6: Shift Swap / Notes | AN6: Remarks
E7: =IF(E$6>DAY(DATE($D$5,$B$5+1,0)),"",TEXT(DATE($D$5,$B$5,E$6),"DDD")) | F7: =IF(F$6>DAY(DATE($D$5,$B$5+1,0)),"",TEXT(DATE($D$5,$B$5,F$6),"DDD")) | G7: =IF(G$6>DAY(DATE($D$5,$B$5+1,0)),"",TEXT(DATE($D$5,$B$5,G$6),"DDD")) | H7: =IF(H$6>DAY(DATE($D$5,$B$5+1,0)),"",TEXT(DATE($D$5,$B$5,H$6),"DDD")) | I7: =IF(I$6>DAY(DATE($D$5,$B$5+1,0)),"",TEXT(DATE($D$5,$B$5,I$6),"DDD")) | J7: =IF(J$6>DAY(DATE($D$5,$B$5+1,0)),"",TEXT(DATE($D$5,$B$5,J$6),"DDD")) | K7: =IF(K$6>DAY(DATE($D$5,$B$5+1,0)),"",TEXT(DATE($D$5,$B$5,K$6),"DDD")) | L7: =IF(L$6>DAY(DATE($D$5,$B$5+1,0)),"",TEXT(DATE($D$5,$B$5,L$6),"DDD")) | ... AI7: =IF(AI$6>DAY(DATE($D$5,$B$5+1,0)),"",TEXT(DATE($D$5,$B$5,AI$6),"DDD"))
A8: ='02_Employee_Master'!A6 | B8: ='02_Employee_Master'!B6 | C8: ='02_Employee_Master'!D6 | D8: ='02_Employee_Master'!C6 | E8: ='W1_Roster'!E8 | F8: ='W1_Roster'!F8 | G8: ='W1_Roster'!G8 | H8: ='W1_Roster'!H8 | I8: ='W1_Roster'!I8 | J8: ='W1_Roster'!J8 | K8: ='W1_Roster'!K8 | L8: ='W2_Roster'!E8 | M8: ='W2_Roster'!F8 | N8: ='W2_Roster'!G8 | O8: ='W2_Roster'!H8 | P8: ='W2_Roster'!I8 | Q8: ='W2_Roster'!J8 | R8: ='W2_Roster'!K8 | S8: ='W3_Roster'!E8 | T8: ='W3_Roster'!F8 | U8: ='W3_Roster'!G8 | V8: ='W3_Roster'!H8 | W8: ='W3_Roster'!I8 | X8: ='W3_Roster'!J8 | Y8: ='W3_Roster'!K8 | Z8: ='W4_Roster'!E8 | AA8: ='W4_Roster'!F8 | AB8: ='W4_Roster'!G8 | AC8: ='W4_Roster'!H8 | AD8: ='W4_Roster'!I8 | AE8: ='W4_Roster'!J8 | AF8: ='W4_Roster'!K8 | AG8: ='W5_Roster'!E8 | AH8: ='W5_Roster'!F8 | AI8: ='W5_Roster'!G8 | AJ8: =COUNTIF(E8:AI8,"WO") | AK8: 0 | AL8: Vikram Singh
A9: ='02_Employee_Master'!A7 | B9: ='02_Employee_Master'!B7 | C9: ='02_Employee_Master'!D7 | D9: ='02_Employee_Master'!C7 | E9: ='W1_Roster'!E9 | F9: ='W1_Roster'!F9 | G9: ='W1_Roster'!G9 | H9: ='W1_Roster'!H9 | I9: ='W1_Roster'!I9 | J9: ='W1_Roster'!J9 | K9: ='W1_Roster'!K9 | L9: ='W2_Roster'!E9 | M9: ='W2_Roster'!F9 | N9: ='W2_Roster'!G9 | O9: ='W2_Roster'!H9 | P9: ='W2_Roster'!I9 | Q9: ='W2_Roster'!J9 | R9: ='W2_Roster'!K9 | S9: ='W3_Roster'!E9 | T9: ='W3_Roster'!F9 | U9: ='W3_Roster'!G9 | V9: ='W3_Roster'!H9 | W9: ='W3_Roster'!I9 | X9: ='W3_Roster'!J9 | Y9: ='W3_Roster'!K9 | Z9: ='W4_Roster'!E9 | AA9: ='W4_Roster'!F9 | AB9: ='W4_Roster'!G9 | AC9: ='W4_Roster'!H9 | AD9: ='W4_Roster'!I9 | AE9: ='W4_Roster'!J9 | AF9: ='W4_Roster'!K9 | AG9: ='W5_Roster'!E9 | AH9: ='W5_Roster'!F9 | AI9: ='W5_Roster'!G9 | AJ9: =COUNTIF(E9:AI9,"WO") | AK9: 0
A10: ='02_Employee_Master'!A8 | B10: ='02_Employee_Master'!B8 | C10: ='02_Employee_Master'!D8 | D10: ='02_Employee_Master'!C8 | E10: ='W1_Roster'!E10 | F10: ='W1_Roster'!F10 | G10: ='W1_Roster'!G10 | H10: ='W1_Roster'!H10 | I10: ='W1_Roster'!I10 | J10: ='W1_Roster'!J10 | K10: ='W1_Roster'!K10 | L10: ='W2_Roster'!E10 | M10: ='W2_Roster'!F10 | N10: ='W2_Roster'!G10 | O10: ='W2_Roster'!H10 | P10: ='W2_Roster'!I10 | Q10: ='W2_Roster'!J10 | R10: ='W2_Roster'!K10 | S10: ='W3_Roster'!E10 | T10: ='W3_Roster'!F10 | U10: ='W3_Roster'!G10 | V10: ='W3_Roster'!H10 | W10: ='W3_Roster'!I10 | X10: ='W3_Roster'!J10 | Y10: ='W3_Roster'!K10 | Z10: ='W4_Roster'!E10 | AA10: ='W4_Roster'!F10 | AB10: ='W4_Roster'!G10 | AC10: ='W4_Roster'!H10 | AD10: ='W4_Roster'!I10 | AE10: ='W4_Roster'!J10 | AF10: ='W4_Roster'!K10 | AG10: ='W5_Roster'!E10 | AH10: ='W5_Roster'!F10 | AI10: ='W5_Roster'!G10 | AJ10: =COUNTIF(E10:AI10,"WO") | AK10: 0
A11: ='02_Employee_Master'!A9 | B11: ='02_Employee_Master'!B9 | C11: ='02_Employee_Master'!D9 | D11: ='02_Employee_Master'!C9 | E11: ='W1_Roster'!E11 | F11: ='W1_Roster'!F11 | G11: ='W1_Roster'!G11 | H11: ='W1_Roster'!H11 | I11: ='W1_Roster'!I11 | J11: ='W1_Roster'!J11 | K11: ='W1_Roster'!K11 | L11: ='W2_Roster'!E11 | M11: ='W2_Roster'!F11 | N11: ='W2_Roster'!G11 | O11: ='W2_Roster'!H11 | P11: ='W2_Roster'!I11 | Q11: ='W2_Roster'!J11 | R11: ='W2_Roster'!K11 | S11: ='W3_Roster'!E11 | T11: ='W3_Roster'!F11 | U11: ='W3_Roster'!G11 | V11: ='W3_Roster'!H11 | W11: ='W3_Roster'!I11 | X11: ='W3_Roster'!J11 | Y11: ='W3_Roster'!K11 | Z11: ='W4_Roster'!E11 | AA11: ='W4_Roster'!F11 | AB11: ='W4_Roster'!G11 | AC11: ='W4_Roster'!H11 | AD11: ='W4_Roster'!I11 | AE11: ='W4_Roster'!J11 | AF11: ='W4_Roster'!K11 | AG11: ='W5_Roster'!E11 | AH11: ='W5_Roster'!F11 | AI11: ='W5_Roster'!G11 | AJ11: =COUNTIF(E11:AI11,"WO") | AK11: 0
A12: ='02_Employee_Master'!A10 | B12: ='02_Employee_Master'!B10 | C12: ='02_Employee_Master'!D10 | D12: ='02_Employee_Master'!C10 | E12: ='W1_Roster'!E12 | F12: ='W1_Roster'!F12 | G12: ='W1_Roster'!G12 | H12: ='W1_Roster'!H12 | I12: ='W1_Roster'!I12 | J12: ='W1_Roster'!J12 | K12: ='W1_Roster'!K12 | L12: ='W2_Roster'!E12 | M12: ='W2_Roster'!F12 | N12: ='W2_Roster'!G12 | O12: ='W2_Roster'!H12 | P12: ='W2_Roster'!I12 | Q12: ='W2_Roster'!J12 | R12: ='W2_Roster'!K12 | S12: ='W3_Roster'!E12 | T12: ='W3_Roster'!F12 | U12: ='W3_Roster'!G12 | V12: ='W3_Roster'!H12 | W12: ='W3_Roster'!I12 | X12: ='W3_Roster'!J12 | Y12: ='W3_Roster'!K12 | Z12: ='W4_Roster'!E12 | AA12: ='W4_Roster'!F12 | AB12: ='W4_Roster'!G12 | AC12: ='W4_Roster'!H12 | AD12: ='W4_Roster'!I12 | AE12: ='W4_Roster'!J12 | AF12: ='W4_Roster'!K12 | AG12: ='W5_Roster'!E12 | AH12: ='W5_Roster'!F12 | AI12: ='W5_Roster'!G12 | AJ12: =COUNTIF(E12:AI12,"WO") | AK12: 0
A13: ='02_Employee_Master'!A11 | B13: ='02_Employee_Master'!B11 | C13: ='02_Employee_Master'!D11 | D13: ='02_Employee_Master'!C11 | E13: ='W1_Roster'!E13 | F13: ='W1_Roster'!F13 | G13: ='W1_Roster'!G13 | H13: ='W1_Roster'!H13 | I13: ='W1_Roster'!I13 | J13: ='W1_Roster'!J13 | K13: ='W1_Roster'!K13 | L13: ='W2_Roster'!E13 | M13: ='W2_Roster'!F13 | N13: ='W2_Roster'!G13 | O13: ='W2_Roster'!H13 | P13: ='W2_Roster'!I13 | Q13: ='W2_Roster'!J13 | R13: ='W2_Roster'!K13 | S13: ='W3_Roster'!E13 | T13: ='W3_Roster'!F13 | U13: ='W3_Roster'!G13 | V13: ='W3_Roster'!H13 | W13: ='W3_Roster'!I13 | X13: ='W3_Roster'!J13 | Y13: ='W3_Roster'!K13 | Z13: ='W4_Roster'!E13 | AA13: ='W4_Roster'!F13 | AB13: ='W4_Roster'!G13 | AC13: ='W4_Roster'!H13 | AD13: ='W4_Roster'!I13 | AE13: ='W4_Roster'!J13 | AF13: ='W4_Roster'!K13 | AG13: ='W5_Roster'!E13 | AH13: ='W5_Roster'!F13 | AI13: ='W5_Roster'!G13 | AJ13: =COUNTIF(E13:AI13,"WO") | AK13: 0
A14: ='02_Employee_Master'!A12 | B14: ='02_Employee_Master'!B12 | C14: ='02_Employee_Master'!D12 | D14: ='02_Employee_Master'!C12 | E14: ='W1_Roster'!E14 | F14: ='W1_Roster'!F14 | G14: ='W1_Roster'!G14 | H14: ='W1_Roster'!H14 | I14: ='W1_Roster'!I14 | J14: ='W1_Roster'!J14 | K14: ='W1_Roster'!K14 | L14: ='W2_Roster'!E14 | M14: ='W2_Roster'!F14 | N14: ='W2_Roster'!G14 | O14: ='W2_Roster'!H14 | P14: ='W2_Roster'!I14 | Q14: ='W2_Roster'!J14 | R14: ='W2_Roster'!K14 | S14: ='W3_Roster'!E14 | T14: ='W3_Roster'!F14 | U14: ='W3_Roster'!G14 | V14: ='W3_Roster'!H14 | W14: ='W3_Roster'!I14 | X14: ='W3_Roster'!J14 | Y14: ='W3_Roster'!K14 | Z14: ='W4_Roster'!E14 | AA14: ='W4_Roster'!F14 | AB14: ='W4_Roster'!G14 | AC14: ='W4_Roster'!H14 | AD14: ='W4_Roster'!I14 | AE14: ='W4_Roster'!J14 | AF14: ='W4_Roster'!K14 | AG14: ='W5_Roster'!E14 | AH14: ='W5_Roster'!F14 | AI14: ='W5_Roster'!G14 | AJ14: =COUNTIF(E14:AI14,"WO") | AK14: 0 | AL14: Karan Malhotra
A15: ='02_Employee_Master'!A13 | B15: ='02_Employee_Master'!B13 | C15: ='02_Employee_Master'!D13 | D15: ='02_Employee_Master'!C13 | E15: ='W1_Roster'!E15 | F15: ='W1_Roster'!F15 | G15: ='W1_Roster'!G15 | H15: ='W1_Roster'!H15 | I15: ='W1_Roster'!I15 | J15: ='W1_Roster'!J15 | K15: ='W1_Roster'!K15 | L15: ='W2_Roster'!E15 | M15: ='W2_Roster'!F15 | N15: ='W2_Roster'!G15 | O15: ='W2_Roster'!H15 | P15: ='W2_Roster'!I15 | Q15: ='W2_Roster'!J15 | R15: ='W2_Roster'!K15 | S15: ='W3_Roster'!E15 | T15: ='W3_Roster'!F15 | U15: ='W3_Roster'!G15 | V15: ='W3_Roster'!H15 | W15: ='W3_Roster'!I15 | X15: ='W3_Roster'!J15 | Y15: ='W3_Roster'!K15 | Z15: ='W4_Roster'!E15 | AA15: ='W4_Roster'!F15 | AB15: ='W4_Roster'!G15 | AC15: ='W4_Roster'!H15 | AD15: ='W4_Roster'!I15 | AE15: ='W4_Roster'!J15 | AF15: ='W4_Roster'!K15 | AG15: ='W5_Roster'!E15 | AH15: ='W5_Roster'!F15 | AI15: ='W5_Roster'!G15 | AJ15: =COUNTIF(E15:AI15,"WO") | AK15: 0
A16: ='02_Employee_Master'!A14 | B16: ='02_Employee_Master'!B14 | C16: ='02_Employee_Master'!D14 | D16: ='02_Employee_Master'!C14 | E16: ='W1_Roster'!E16 | F16: ='W1_Roster'!F16 | G16: ='W1_Roster'!G16 | H16: ='W1_Roster'!H16 | I16: ='W1_Roster'!I16 | J16: ='W1_Roster'!J16 | K16: ='W1_Roster'!K16 | L16: ='W2_Roster'!E16 | M16: ='W2_Roster'!F16 | N16: ='W2_Roster'!G16 | O16: ='W2_Roster'!H16 | P16: ='W2_Roster'!I16 | Q16: ='W2_Roster'!J16 | R16: ='W2_Roster'!K16 | S16: ='W3_Roster'!E16 | T16: ='W3_Roster'!F16 | U16: ='W3_Roster'!G16 | V16: ='W3_Roster'!H16 | W16: ='W3_Roster'!I16 | X16: ='W3_Roster'!J16 | Y16: ='W3_Roster'!K16 | Z16: ='W4_Roster'!E16 | AA16: ='W4_Roster'!F16 | AB16: ='W4_Roster'!G16 | AC16: ='W4_Roster'!H16 | AD16: ='W4_Roster'!I16 | AE16: ='W4_Roster'!J16 | AF16: ='W4_Roster'!K16 | AG16: ='W5_Roster'!E16 | AH16: ='W5_Roster'!F16 | AI16: ='W5_Roster'!G16 | AJ16: =COUNTIF(E16:AI16,"WO") | AK16: 0
A17: ='02_Employee_Master'!A15 | B17: ='02_Employee_Master'!B15 | C17: ='02_Employee_Master'!D15 | D17: ='02_Employee_Master'!C15 | E17: ='W1_Roster'!E17 | F17: ='W1_Roster'!F17 | G17: ='W1_Roster'!G17 | H17: ='W1_Roster'!H17 | I17: ='W1_Roster'!I17 | J17: ='W1_Roster'!J17 | K17: ='W1_Roster'!K17 | L17: ='W2_Roster'!E17 | M17: ='W2_Roster'!F17 | N17: ='W2_Roster'!G17 | O17: ='W2_Roster'!H17 | P17: ='W2_Roster'!I17 | Q17: ='W2_Roster'!J17 | R17: ='W2_Roster'!K17 | S17: ='W3_Roster'!E17 | T17: ='W3_Roster'!F17 | U17: ='W3_Roster'!G17 | V17: ='W3_Roster'!H17 | W17: ='W3_Roster'!I17 | X17: ='W3_Roster'!J17 | Y17: ='W3_Roster'!K17 | Z17: ='W4_Roster'!E17 | AA17: ='W4_Roster'!F17 | AB17: ='W4_Roster'!G17 | AC17: ='W4_Roster'!H17 | AD17: ='W4_Roster'!I17 | AE17: ='W4_Roster'!J17 | AF17: ='W4_Roster'!K17 | AG17: ='W5_Roster'!E17 | AH17: ='W5_Roster'!F17 | AI17: ='W5_Roster'!G17 | AJ17: =COUNTIF(E17:AI17,"WO") | AK17: 0
A18: ='02_Employee_Master'!A16 | B18: ='02_Employee_Master'!B16 | C18: ='02_Employee_Master'!D16 | D18: ='02_Employee_Master'!C16 | E18: ='W1_Roster'!E18 | F18: ='W1_Roster'!F18 | G18: ='W1_Roster'!G18 | H18: ='W1_Roster'!H18 | I18: ='W1_Roster'!I18 | J18: ='W1_Roster'!J18 | K18: ='W1_Roster'!K18 | L18: ='W2_Roster'!E18 | M18: ='W2_Roster'!F18 | N18: ='W2_Roster'!G18 | O18: ='W2_Roster'!H18 | P18: ='W2_Roster'!I18 | Q18: ='W2_Roster'!J18 | R18: ='W2_Roster'!K18 | S18: ='W3_Roster'!E18 | T18: ='W3_Roster'!F18 | U18: ='W3_Roster'!G18 | V18: ='W3_Roster'!H18 | W18: ='W3_Roster'!I18 | X18: ='W3_Roster'!J18 | Y18: ='W3_Roster'!K18 | Z18: ='W4_Roster'!E18 | AA18: ='W4_Roster'!F18 | AB18: ='W4_Roster'!G18 | AC18: ='W4_Roster'!H18 | AD18: ='W4_Roster'!I18 | AE18: ='W4_Roster'!J18 | AF18: ='W4_Roster'!K18 | AG18: ='W5_Roster'!E18 | AH18: ='W5_Roster'!F18 | AI18: ='W5_Roster'!G18 | AJ18: =COUNTIF(E18:AI18,"WO") | AK18: 0
A19: ='02_Employee_Master'!A17 | B19: ='02_Employee_Master'!B17 | C19: ='02_Employee_Master'!D17 | D19: ='02_Employee_Master'!C17 | E19: ='W1_Roster'!E19 | F19: ='W1_Roster'!F19 | G19: ='W1_Roster'!G19 | H19: ='W1_Roster'!H19 | I19: ='W1_Roster'!I19 | J19: ='W1_Roster'!J19 | K19: ='W1_Roster'!K19 | L19: ='W2_Roster'!E19 | M19: ='W2_Roster'!F19 | N19: ='W2_Roster'!G19 | O19: ='W2_Roster'!H19 | P19: ='W2_Roster'!I19 | Q19: ='W2_Roster'!J19 | R19: ='W2_Roster'!K19 | S19: ='W3_Roster'!E19 | T19: ='W3_Roster'!F19 | U19: ='W3_Roster'!G19 | V19: ='W3_Roster'!H19 | W19: ='W3_Roster'!I19 | X19: ='W3_Roster'!J19 | Y19: ='W3_Roster'!K19 | Z19: ='W4_Roster'!E19 | AA19: ='W4_Roster'!F19 | AB19: ='W4_Roster'!G19 | AC19: ='W4_Roster'!H19 | AD19: ='W4_Roster'!I19 | AE19: ='W4_Roster'!J19 | AF19: ='W4_Roster'!K19 | AG19: ='W5_Roster'!E19 | AH19: ='W5_Roster'!F19 | AI19: ='W5_Roster'!G19 | AJ19: =COUNTIF(E19:AI19,"WO") | AK19: 0
A20: ='02_Employee_Master'!A18 | B20: ='02_Employee_Master'!B18 | C20: ='02_Employee_Master'!D18 | D20: ='02_Employee_Master'!C18 | E20: ='W1_Roster'!E20 | F20: ='W1_Roster'!F20 | G20: ='W1_Roster'!G20 | H20: ='W1_Roster'!H20 | I20: ='W1_Roster'!I20 | J20: ='W1_Roster'!J20 | K20: ='W1_Roster'!K20 | L20: ='W2_Roster'!E20 | M20: ='W2_Roster'!F20 | N20: ='W2_Roster'!G20 | O20: ='W2_Roster'!H20 | P20: ='W2_Roster'!I20 | Q20: ='W2_Roster'!J20 | R20: ='W2_Roster'!K20 | S20: ='W3_Roster'!E20 | T20: ='W3_Roster'!F20 | U20: ='W3_Roster'!G20 | V20: ='W3_Roster'!H20 | W20: ='W3_Roster'!I20 | X20: ='W3_Roster'!J20 | Y20: ='W3_Roster'!K20 | Z20: ='W4_Roster'!E20 | AA20: ='W4_Roster'!F20 | AB20: ='W4_Roster'!G20 | AC20: ='W4_Roster'!H20 | AD20: ='W4_Roster'!I20 | AE20: ='W4_Roster'!J20 | AF20: ='W4_Roster'!K20 | AG20: ='W5_Roster'!E20 | AH20: ='W5_Roster'!F20 | AI20: ='W5_Roster'!G20 | AJ20: =COUNTIF(E20:AI20,"WO") | AK20: 0 | AL20: Deepak Joshi
A21: ='02_Employee_Master'!A19 | B21: ='02_Employee_Master'!B19 | C21: ='02_Employee_Master'!D19 | D21: ='02_Employee_Master'!C19 | E21: ='W1_Roster'!E21 | F21: ='W1_Roster'!F21 | G21: ='W1_Roster'!G21 | H21: ='W1_Roster'!H21 | I21: ='W1_Roster'!I21 | J21: ='W1_Roster'!J21 | K21: ='W1_Roster'!K21 | L21: ='W2_Roster'!E21 | M21: ='W2_Roster'!F21 | N21: ='W2_Roster'!G21 | O21: ='W2_Roster'!H21 | P21: ='W2_Roster'!I21 | Q21: ='W2_Roster'!J21 | R21: ='W2_Roster'!K21 | S21: ='W3_Roster'!E21 | T21: ='W3_Roster'!F21 | U21: ='W3_Roster'!G21 | V21: ='W3_Roster'!H21 | W21: ='W3_Roster'!I21 | X21: ='W3_Roster'!J21 | Y21: ='W3_Roster'!K21 | Z21: ='W4_Roster'!E21 | AA21: ='W4_Roster'!F21 | AB21: ='W4_Roster'!G21 | AC21: ='W4_Roster'!H21 | AD21: ='W4_Roster'!I21 | AE21: ='W4_Roster'!J21 | AF21: ='W4_Roster'!K21 | AG21: ='W5_Roster'!E21 | AH21: ='W5_Roster'!F21 | AI21: ='W5_Roster'!G21 | AJ21: =COUNTIF(E21:AI21,"WO") | AK21: 0
A22: ='02_Employee_Master'!A20 | B22: ='02_Employee_Master'!B20 | C22: ='02_Employee_Master'!D20 | D22: ='02_Employee_Master'!C20 | E22: ='W1_Roster'!E22 | F22: ='W1_Roster'!F22 | G22: ='W1_Roster'!G22 | H22: ='W1_Roster'!H22 | I22: ='W1_Roster'!I22 | J22: ='W1_Roster'!J22 | K22: ='W1_Roster'!K22 | L22: ='W2_Roster'!E22 | M22: ='W2_Roster'!F22 | N22: ='W2_Roster'!G22 | O22: ='W2_Roster'!H22 | P22: ='W2_Roster'!I22 | Q22: ='W2_Roster'!J22 | R22: ='W2_Roster'!K22 | S22: ='W3_Roster'!E22 | T22: ='W3_Roster'!F22 | U22: ='W3_Roster'!G22 | V22: ='W3_Roster'!H22 | W22: ='W3_Roster'!I22 | X22: ='W3_Roster'!J22 | Y22: ='W3_Roster'!K22 | Z22: ='W4_Roster'!E22 | AA22: ='W4_Roster'!F22 | AB22: ='W4_Roster'!G22 | AC22: ='W4_Roster'!H22 | AD22: ='W4_Roster'!I22 | AE22: ='W4_Roster'!J22 | AF22: ='W4_Roster'!K22 | AG22: ='W5_Roster'!E22 | AH22: ='W5_Roster'!F22 | AI22: ='W5_Roster'!G22 | AJ22: =COUNTIF(E22:AI22,"WO") | AK22: 0
A23: ='02_Employee_Master'!A21 | B23: ='02_Employee_Master'!B21 | C23: ='02_Employee_Master'!D21 | D23: ='02_Employee_Master'!C21 | E23: ='W1_Roster'!E23 | F23: ='W1_Roster'!F23 | G23: ='W1_Roster'!G23 | H23: ='W1_Roster'!H23 | I23: ='W1_Roster'!I23 | J23: ='W1_Roster'!J23 | K23: ='W1_Roster'!K23 | L23: ='W2_Roster'!E23 | M23: ='W2_Roster'!F23 | N23: ='W2_Roster'!G23 | O23: ='W2_Roster'!H23 | P23: ='W2_Roster'!I23 | Q23: ='W2_Roster'!J23 | R23: ='W2_Roster'!K23 | S23: ='W3_Roster'!E23 | T23: ='W3_Roster'!F23 | U23: ='W3_Roster'!G23 | V23: ='W3_Roster'!H23 | W23: ='W3_Roster'!I23 | X23: ='W3_Roster'!J23 | Y23: ='W3_Roster'!K23 | Z23: ='W4_Roster'!E23 | AA23: ='W4_Roster'!F23 | AB23: ='W4_Roster'!G23 | AC23: ='W4_Roster'!H23 | AD23: ='W4_Roster'!I23 | AE23: ='W4_Roster'!J23 | AF23: ='W4_Roster'!K23 | AG23: ='W5_Roster'!E23 | AH23: ='W5_Roster'!F23 | AI23: ='W5_Roster'!G23 | AJ23: =COUNTIF(E23:AI23,"WO") | AK23: 0
A24: ='02_Employee_Master'!A22 | B24: ='02_Employee_Master'!B22 | C24: ='02_Employee_Master'!D22 | D24: ='02_Employee_Master'!C22 | E24: ='W1_Roster'!E24 | F24: ='W1_Roster'!F24 | G24: ='W1_Roster'!G24 | H24: ='W1_Roster'!H24 | I24: ='W1_Roster'!I24 | J24: ='W1_Roster'!J24 | K24: ='W1_Roster'!K24 | L24: ='W2_Roster'!E24 | M24: ='W2_Roster'!F24 | N24: ='W2_Roster'!G24 | O24: ='W2_Roster'!H24 | P24: ='W2_Roster'!I24 | Q24: ='W2_Roster'!J24 | R24: ='W2_Roster'!K24 | S24: ='W3_Roster'!E24 | T24: ='W3_Roster'!F24 | U24: ='W3_Roster'!G24 | V24: ='W3_Roster'!H24 | W24: ='W3_Roster'!I24 | X24: ='W3_Roster'!J24 | Y24: ='W3_Roster'!K24 | Z24: ='W4_Roster'!E24 | AA24: ='W4_Roster'!F24 | AB24: ='W4_Roster'!G24 | AC24: ='W4_Roster'!H24 | AD24: ='W4_Roster'!I24 | AE24: ='W4_Roster'!J24 | AF24: ='W4_Roster'!K24 | AG24: ='W5_Roster'!E24 | AH24: ='W5_Roster'!F24 | AI24: ='W5_Roster'!G24 | AJ24: =COUNTIF(E24:AI24,"WO") | AK24: 0
A25: ='02_Employee_Master'!A23 | B25: ='02_Employee_Master'!B23 | C25: ='02_Employee_Master'!D23 | D25: ='02_Employee_Master'!C23 | E25: ='W1_Roster'!E25 | F25: ='W1_Roster'!F25 | G25: ='W1_Roster'!G25 | H25: ='W1_Roster'!H25 | I25: ='W1_Roster'!I25 | J25: ='W1_Roster'!J25 | K25: ='W1_Roster'!K25 | L25: ='W2_Roster'!E25 | M25: ='W2_Roster'!F25 | N25: ='W2_Roster'!G25 | O25: ='W2_Roster'!H25 | P25: ='W2_Roster'!I25 | Q25: ='W2_Roster'!J25 | R25: ='W2_Roster'!K25 | S25: ='W3_Roster'!E25 | T25: ='W3_Roster'!F25 | U25: ='W3_Roster'!G25 | V25: ='W3_Roster'!H25 | W25: ='W3_Roster'!I25 | X25: ='W3_Roster'!J25 | Y25: ='W3_Roster'!K25 | Z25: ='W4_Roster'!E25 | AA25: ='W4_Roster'!F25 | AB25: ='W4_Roster'!G25 | AC25: ='W4_Roster'!H25 | AD25: ='W4_Roster'!I25 | AE25: ='W4_Roster'!J25 | AF25: ='W4_Roster'!K25 | AG25: ='W5_Roster'!E25 | AH25: ='W5_Roster'!F25 | AI25: ='W5_Roster'!G25 | AJ25: =COUNTIF(E25:AI25,"WO") | AK25: 0
A26: ='02_Employee_Master'!A24 | B26: ='02_Employee_Master'!B24 | C26: ='02_Employee_Master'!D24 | D26: ='02_Employee_Master'!C24 | E26: ='W1_Roster'!E26 | F26: ='W1_Roster'!F26 | G26: ='W1_Roster'!G26 | H26: ='W1_Roster'!H26 | I26: ='W1_Roster'!I26 | J26: ='W1_Roster'!J26 | K26: ='W1_Roster'!K26 | L26: ='W2_Roster'!E26 | M26: ='W2_Roster'!F26 | N26: ='W2_Roster'!G26 | O26: ='W2_Roster'!H26 | P26: ='W2_Roster'!I26 | Q26: ='W2_Roster'!J26 | R26: ='W2_Roster'!K26 | S26: ='W3_Roster'!E26 | T26: ='W3_Roster'!F26 | U26: ='W3_Roster'!G26 | V26: ='W3_Roster'!H26 | W26: ='W3_Roster'!I26 | X26: ='W3_Roster'!J26 | Y26: ='W3_Roster'!K26 | Z26: ='W4_Roster'!E26 | AA26: ='W4_Roster'!F26 | AB26: ='W4_Roster'!G26 | AC26: ='W4_Roster'!H26 | AD26: ='W4_Roster'!I26 | AE26: ='W4_Roster'!J26 | AF26: ='W4_Roster'!K26 | AG26: ='W5_Roster'!E26 | AH26: ='W5_Roster'!F26 | AI26: ='W5_Roster'!G26 | AJ26: =COUNTIF(E26:AI26,"WO") | AK26: 0 | AL26: Thomas Mathew
A27: ='02_Employee_Master'!A25 | B27: ='02_Employee_Master'!B25 | C27: ='02_Employee_Master'!D25 | D27: ='02_Employee_Master'!C25 | E27: ='W1_Roster'!E27 | F27: ='W1_Roster'!F27 | G27: ='W1_Roster'!G27 | H27: ='W1_Roster'!H27 | I27: ='W1_Roster'!I27 | J27: ='W1_Roster'!J27 | K27: ='W1_Roster'!K27 | L27: ='W2_Roster'!E27 | M27: ='W2_Roster'!F27 | N27: ='W2_Roster'!G27 | O27: ='W2_Roster'!H27 | P27: ='W2_Roster'!I27 | Q27: ='W2_Roster'!J27 | R27: ='W2_Roster'!K27 | S27: ='W3_Roster'!E27 | T27: ='W3_Roster'!F27 | U27: ='W3_Roster'!G27 | V27: ='W3_Roster'!H27 | W27: ='W3_Roster'!I27 | X27: ='W3_Roster'!J27 | Y27: ='W3_Roster'!K27 | Z27: ='W4_Roster'!E27 | AA27: ='W4_Roster'!F27 | AB27: ='W4_Roster'!G27 | AC27: ='W4_Roster'!H27 | AD27: ='W4_Roster'!I27 | AE27: ='W4_Roster'!J27 | AF27: ='W4_Roster'!K27 | AG27: ='W5_Roster'!E27 | AH27: ='W5_Roster'!F27 | AI27: ='W5_Roster'!G27 | AJ27: =COUNTIF(E27:AI27,"WO")
A28: Morning (M) headcount | E28: =IF(E$6>DAY(DATE($D$5,$B$5+1,0)),"",COUNTIF(E8:E27,"M")) | F28: =IF(F$6>DAY(DATE($D$5,$B$5+1,0)),"",COUNTIF(F8:F27,"M")) | G28: =IF(G$6>DAY(DATE($D$5,$B$5+1,0)),"",COUNTIF(G8:G27,"M")) | H28: =IF(H$6>DAY(DATE($D$5,$B$5+1,0)),"",COUNTIF(H8:H27,"M")) | I28: =IF(I$6>DAY(DATE($D$5,$B$5+1,0)),"",COUNTIF(I8:I27,"M")) | J28: =IF(J$6>DAY(DATE($D$5,$B$5+1,0)),"",COUNTIF(J8:J27,"M")) | K28: =IF(K$6>DAY(DATE($D$5,$B$5+1,0)),"",COUNTIF(K8:K27,"M")) | L28: =IF(L$6>DAY(DATE($D$5,$B$5+1,0)),"",COUNTIF(L8:L27,"M")) | ... AI28: =IF(AI$6>DAY(DATE($D$5,$B$5+1,0)),"",COUNTIF(AI8:AI27,"M"))
A29: Evening (E) headcount | E29: =IF(E$6>DAY(DATE($D$5,$B$5+1,0)),"",COUNTIF(E8:E27,"E")) | F29: =IF(F$6>DAY(DATE($D$5,$B$5+1,0)),"",COUNTIF(F8:F27,"E")) | G29: =IF(G$6>DAY(DATE($D$5,$B$5+1,0)),"",COUNTIF(G8:G27,"E")) | H29: =IF(H$6>DAY(DATE($D$5,$B$5+1,0)),"",COUNTIF(H8:H27,"E")) | I29: =IF(I$6>DAY(DATE($D$5,$B$5+1,0)),"",COUNTIF(I8:I27,"E")) | J29: =IF(J$6>DAY(DATE($D$5,$B$5+1,0)),"",COUNTIF(J8:J27,"E")) | K29: =IF(K$6>DAY(DATE($D$5,$B$5+1,0)),"",COUNTIF(K8:K27,"E")) | L29: =IF(L$6>DAY(DATE($D$5,$B$5+1,0)),"",COUNTIF(L8:L27,"E")) | ... AI29: =IF(AI$6>DAY(DATE($D$5,$B$5+1,0)),"",COUNTIF(AI8:AI27,"E"))
A30: Night (N) headcount | E30: =IF(E$6>DAY(DATE($D$5,$B$5+1,0)),"",COUNTIF(E8:E27,"N")) | F30: =IF(F$6>DAY(DATE($D$5,$B$5+1,0)),"",COUNTIF(F8:F27,"N")) | G30: =IF(G$6>DAY(DATE($D$5,$B$5+1,0)),"",COUNTIF(G8:G27,"N")) | H30: =IF(H$6>DAY(DATE($D$5,$B$5+1,0)),"",COUNTIF(H8:H27,"N")) | I30: =IF(I$6>DAY(DATE($D$5,$B$5+1,0)),"",COUNTIF(I8:I27,"N")) | J30: =IF(J$6>DAY(DATE($D$5,$B$5+1,0)),"",COUNTIF(J8:J27,"N")) | K30: =IF(K$6>DAY(DATE($D$5,$B$5+1,0)),"",COUNTIF(K8:K27,"N")) | L30: =IF(L$6>DAY(DATE($D$5,$B$5+1,0)),"",COUNTIF(L8:L27,"N")) | ... AI30: =IF(AI$6>DAY(DATE($D$5,$B$5+1,0)),"",COUNTIF(AI8:AI27,"N"))
A32: Note: Day cells on Full Month are linked from Week 1–5 sheets. Enter / change shifts on W1_Roster … W5_Roster (use the buttons above).

Sheet W1_Roster
A1: PATHCARE DIAGNOSTICS · Pathology Laboratory
A2: WEEK 1 ROSTER · Days 1–7
A3: Edit shifts here · Syncs to Full Month automatically · Period = Roster Month/Year
A4: GO → | B4: Full Month | C4: ● W1 | D4: ▶ W2 | E4: ▶ W3 | F4: ▶ W4 | G4: ▶ W5 | H4: You are on Week 1 | Drop-down: M E N WO PH LV TR
A5: Month | B5: ='03_Roster'!B5 | C5: Year | D5: ='03_Roster'!D5
A6: Emp ID | B6: Employee Name | C6: Department | D6: Designation | E6: 1 | F6: 2 | G6: 3 | H6: 4 | I6: 5 | J6: 6 | K6: 7 | L6: Backup | M6: Week notes
E7: =IF(E$6>DAY(DATE('03_Roster'!$D$5,'03_Roster'!$B$5+1,0)),"",TEXT(DATE('03_Roster'!$D$5,'03_Roster'!$B$5,E$6),"DDD")) | F7: =IF(F$6>DAY(DATE('03_Roster'!$D$5,'03_Roster'!$B$5+1,0)),"",TEXT(DATE('03_Roster'!$D$5,'03_Roster'!$B$5,F$6),"DDD")) | G7: =IF(G$6>DAY(DATE('03_Roster'!$D$5,'03_Roster'!$B$5+1,0)),"",TEXT(DATE('03_Roster'!$D$5,'03_Roster'!$B$5,G$6),"DDD")) | H7: =IF(H$6>DAY(DATE('03_Roster'!$D$5,'03_Roster'!$B$5+1,0)),"",TEXT(DATE('03_Roster'!$D$5,'03_Roster'!$B$5,H$6),"DDD")) | I7: =IF(I$6>DAY(DATE('03_Roster'!$D$5,'03_Roster'!$B$5+1,0)),"",TEXT(DATE('03_Roster'!$D$5,'03_Roster'!$B$5,I$6),"DDD")) | J7: =IF(J$6>DAY(DATE('03_Roster'!$D$5,'03_Roster'!$B$5+1,0)),"",TEXT(DATE('03_Roster'!$D$5,'03_Roster'!$B$5,J$6),"DDD")) | K7: =IF(K$6>DAY(DATE('03_Roster'!$D$5,'03_Roster'!$B$5+1,0)),"",TEXT(DATE('03_Roster'!$D$5,'03_Roster'!$B$5,K$6),"DDD"))
A8: ='02_Employee_Master'!A6 | B8: ='02_Employee_Master'!B6 | C8: ='02_Employee_Master'!D6 | D8: ='02_Employee_Master'!C6 | E8: M | F8: M | G8: M | H8: M | I8: M | J8: M | K8: WO | L8: Vikram Singh
A9: ='02_Employee_Master'!A7 | B9: ='02_Employee_Master'!B7 | C9: ='02_Employee_Master'!D7 | D9: ='02_Employee_Master'!C7 | E9: M | F9: WO | G9: M | H9: E | I9: M | J9: M | K9: M
A10: ='02_Employee_Master'!A8 | B10: ='02_Employee_Master'!B8 | C10: ='02_Employee_Master'!D8 | D10: ='02_Employee_Master'!C8 | E10: N | F10: M | G10: E | H10: WO | I10: M | J10: M | K10: M
A11: ='02_Employee_Master'!A9 | B11: ='02_Employee_Master'!B9 | C11: ='02_Employee_Master'!D9 | D11: ='02_Employee_Master'!C9 | E11: M | F11: E | G11: M | H11: M | I11: M | J11: WO | K11: N
A12: ='02_Employee_Master'!A10 | B12: ='02_Employee_Master'!B10 | C12: ='02_Employee_Master'!D10 | D12: ='02_Employee_Master'!C10 | E12: WO | F12: E | G12: M | H12: M | I12: E | J12: M | K12: M
A13: ='02_Employee_Master'!A11 | B13: ='02_Employee_Master'!B11 | C13: ='02_Employee_Master'!D11 | D13: ='02_Employee_Master'!C11 | E13: M | F13: M | G13: WO | H13: M | I13: N | J13: M | K13: M
A14: ='02_Employee_Master'!A12 | B14: ='02_Employee_Master'!B12 | C14: ='02_Employee_Master'!D12 | D14: ='02_Employee_Master'!C12 | E14: M | F14: M | G14: E | H14: M | I14: WO | J14: E | K14: M | L14: Karan Malhotra
A15: ='02_Employee_Master'!A13 | B15: ='02_Employee_Master'!B13 | C15: ='02_Employee_Master'!D13 | D15: ='02_Employee_Master'!C13 | E15: M | F15: M | G15: N | H15: M | I15: M | J15: M | K15: WO
A16: ='02_Employee_Master'!A14 | B16: ='02_Employee_Master'!B14 | C16: ='02_Employee_Master'!D14 | D16: ='02_Employee_Master'!C14 | E16: M | F16: WO | G16: M | H16: M | I16: M | J16: M | K16: M
A17: ='02_Employee_Master'!A15 | B17: ='02_Employee_Master'!B15 | C17: ='02_Employee_Master'!D15 | D17: ='02_Employee_Master'!C15 | E17: M | F17: M | G17: E | H17: WO | I17: M | J17: E | K17: M
A18: ='02_Employee_Master'!A16 | B18: ='02_Employee_Master'!B16 | C18: ='02_Employee_Master'!D16 | D18: ='02_Employee_Master'!C16 | E18: M | F18: M | G18: M | H18: M | I18: M | J18: WO | K18: M
A19: ='02_Employee_Master'!A17 | B19: ='02_Employee_Master'!B17 | C19: ='02_Employee_Master'!D17 | D19: ='02_Employee_Master'!C17 | E19: WO | F19: M | G19: M | H19: E | I19: M | J19: N | K19: M
A20: ='02_Employee_Master'!A18 | B20: ='02_Employee_Master'!B18 | C20: ='02_Employee_Master'!D18 | D20: ='02_Employee_Master'!C18 | E20: M | F20: M | G20: WO | H20: M | I20: M | J20: M | K20: M | L20: Deepak Joshi
A21: ='02_Employee_Master'!A19 | B21: ='02_Employee_Master'!B19 | C21: ='02_Employee_Master'!D19 | D21: ='02_Employee_Master'!C19 | E21: M | F21: E | G21: M | H21: M | I21: WO | J21: M | K21: M
A22: ='02_Employee_Master'!A20 | B22: ='02_Employee_Master'!B20 | C22: ='02_Employee_Master'!D20 | D22: ='02_Employee_Master'!C20 | E22: M | F22: M | G22: M | H22: M | I22: M | J22: M | K22: WO
A23: ='02_Employee_Master'!A21 | B23: ='02_Employee_Master'!B21 | C23: ='02_Employee_Master'!D21 | D23: ='02_Employee_Master'!C21 | E23: M | F23: WO | G23: M | H23: M | I23: E | J23: M | K23: M
A24: ='02_Employee_Master'!A22 | B24: ='02_Employee_Master'!B22 | C24: ='02_Employee_Master'!D22 | D24: ='02_Employee_Master'!C22 | E24: M | F24: E | G24: M | H24: WO | I24: E | J24: M | K24: M
A25: ='02_Employee_Master'!A23 | B25: ='02_Employee_Master'!B23 | C25: ='02_Employee_Master'!D23 | D25: ='02_Employee_Master'!C23 | E25: M | F25: M | G25: M | H25: M | I25: M | J25: WO | K25: M
A26: ='02_Employee_Master'!A24 | B26: ='02_Employee_Master'!B24 | C26: ='02_Employee_Master'!D24 | D26: ='02_Employee_Master'!C24 | E26: WO | F26: M | G26: M | H26: M | I26: M | J26: M | K26: M | L26: Thomas Mathew
A27: ='02_Employee_Master'!A25 | B27: ='02_Employee_Master'!B25 | C27: ='02_Employee_Master'!D25 | D27: ='02_Employee_Master'!C25
A28: On duty (M+E+N) | E28: =COUNTIF(E8:E27,"M")+COUNTIF(E8:E27,"E")+COUNTIF(E8:E27,"N") | F28: =COUNTIF(F8:F27,"M")+COUNTIF(F8:F27,"E")+COUNTIF(F8:F27,"N") | G28: =COUNTIF(G8:G27,"M")+COUNTIF(G8:G27,"E")+COUNTIF(G8:G27,"N") | H28: =COUNTIF(H8:H27,"M")+COUNTIF(H8:H27,"E")+COUNTIF(H8:H27,"N") | I28: =COUNTIF(I8:I27,"M")+COUNTIF(I8:I27,"E")+COUNTIF(I8:I27,"N") | J28: =COUNTIF(J8:J27,"M")+COUNTIF(J8:J27,"E")+COUNTIF(J8:J27,"N") | K28: =COUNTIF(K8:K27,"M")+COUNTIF(K8:K27,"E")+COUNTIF(K8:K27,"N")

Sheet W2_Roster
A1: PATHCARE DIAGNOSTICS · Pathology Laboratory
A2: WEEK 2 ROSTER · Days 8–14
A3: Edit shifts here · Syncs to Full Month automatically · Period = Roster Month/Year
A4: GO → | B4: Full Month | C4: ▶ W1 | D4: ● W2 | E4: ▶ W3 | F4: ▶ W4 | G4: ▶ W5 | H4: You are on Week 2 | Drop-down: M E N WO PH LV TR
A5: Month | B5: ='03_Roster'!B5 | C5: Year | D5: ='03_Roster'!D5
A6: Emp ID | B6: Employee Name | C6: Department | D6: Designation | E6: 8 | F6: 9 | G6: 10 | H6: 11 | I6: 12 | J6: 13 | K6: 14 | L6: Backup | M6: Week notes
E7: =IF(E$6>DAY(DATE('03_Roster'!$D$5,'03_Roster'!$B$5+1,0)),"",TEXT(DATE('03_Roster'!$D$5,'03_Roster'!$B$5,E$6),"DDD")) | F7: =IF(F$6>DAY(DATE('03_Roster'!$D$5,'03_Roster'!$B$5+1,0)),"",TEXT(DATE('03_Roster'!$D$5,'03_Roster'!$B$5,F$6),"DDD")) | G7: =IF(G$6>DAY(DATE('03_Roster'!$D$5,'03_Roster'!$B$5+1,0)),"",TEXT(DATE('03_Roster'!$D$5,'03_Roster'!$B$5,G$6),"DDD")) | H7: =IF(H$6>DAY(DATE('03_Roster'!$D$5,'03_Roster'!$B$5+1,0)),"",TEXT(DATE('03_Roster'!$D$5,'03_Roster'!$B$5,H$6),"DDD")) | I7: =IF(I$6>DAY(DATE('03_Roster'!$D$5,'03_Roster'!$B$5+1,0)),"",TEXT(DATE('03_Roster'!$D$5,'03_Roster'!$B$5,I$6),"DDD")) | J7: =IF(J$6>DAY(DATE('03_Roster'!$D$5,'03_Roster'!$B$5+1,0)),"",TEXT(DATE('03_Roster'!$D$5,'03_Roster'!$B$5,J$6),"DDD")) | K7: =IF(K$6>DAY(DATE('03_Roster'!$D$5,'03_Roster'!$B$5+1,0)),"",TEXT(DATE('03_Roster'!$D$5,'03_Roster'!$B$5,K$6),"DDD"))
A8: ='02_Employee_Master'!A6 | B8: ='02_Employee_Master'!B6 | C8: ='02_Employee_Master'!D6 | D8: ='02_Employee_Master'!C6 | E8: M | F8: M | G8: M | H8: M | I8: M | J8: M | K8: WO | L8: Vikram Singh
A9: ='02_Employee_Master'!A7 | B9: ='02_Employee_Master'!B7 | C9: ='02_Employee_Master'!D7 | D9: ='02_Employee_Master'!C7 | E9: M | F9: WO | G9: M | H9: M | I9: M | J9: M | K9: E
A10: ='02_Employee_Master'!A8 | B10: ='02_Employee_Master'!B8 | C10: ='02_Employee_Master'!D8 | D10: ='02_Employee_Master'!C8 | E10: N | F10: M | G10: M | H10: WO | I10: M | J10: E | K10: M
A11: ='02_Employee_Master'!A9 | B11: ='02_Employee_Master'!B9 | C11: ='02_Employee_Master'!D9 | D11: ='02_Employee_Master'!C9 | E11: M | F11: M | G11: M | H11: M | I11: E | J11: WO | K11: N
A12: ='02_Employee_Master'!A10 | B12: ='02_Employee_Master'!B10 | C12: ='02_Employee_Master'!D10 | D12: ='02_Employee_Master'!C10 | E12: WO | F12: M | G12: M | H12: E | I12: M | J12: M | K12: E
A13: ='02_Employee_Master'!A11 | B13: ='02_Employee_Master'!B11 | C13: ='02_Employee_Master'!D11 | D13: ='02_Employee_Master'!C11 | E13: M | F13: M | G13: WO | H13: M | I13: N | J13: M | K13: M
A14: ='02_Employee_Master'!A12 | B14: ='02_Employee_Master'!B12 | C14: ='02_Employee_Master'!D12 | D14: ='02_Employee_Master'!C12 | E14: M | F14: E | G14: M | H14: M | I14: WO | J14: M | K14: M | L14: Karan Malhotra
A15: ='02_Employee_Master'!A13 | B15: ='02_Employee_Master'!B13 | C15: ='02_Employee_Master'!D13 | D15: ='02_Employee_Master'!C13 | E15: E | F15: M | G15: N | H15: M | I15: M | J15: E | K15: WO
A16: ='02_Employee_Master'!A14 | B16: ='02_Employee_Master'!B14 | C16: ='02_Employee_Master'!D14 | D16: ='02_Employee_Master'!C14 | E16: M | F16: WO | G16: M | H16: M | I16: M | J16: M | K16: M
A17: ='02_Employee_Master'!A15 | B17: ='02_Employee_Master'!B15 | C17: ='02_Employee_Master'!D15 | D17: ='02_Employee_Master'!C15 | E17: M | F17: E | G17: M | H17: WO | I17: E | J17: M | K17: M
A18: ='02_Employee_Master'!A16 | B18: ='02_Employee_Master'!B16 | C18: ='02_Employee_Master'!D16 | D18: ='02_Employee_Master'!C16 | E18: M | F18: M | G18: M | H18: M | I18: M | J18: WO | K18: M
A19: ='02_Employee_Master'!A17 | B19: ='02_Employee_Master'!B17 | C19: ='02_Employee_Master'!D17 | D19: ='02_Employee_Master'!C17 | E19: WO | F19: E | G19: M | H19: M | I19: M | J19: N | K19: E
A20: ='02_Employee_Master'!A18 | B20: ='02_Employee_Master'!B18 | C20: ='02_Employee_Master'!D18 | D20: ='02_Employee_Master'!C18 | E20: M | F20: M | G20: WO | H20: M | I20: M | J20: M | K20: M | L20: Deepak Joshi
A21: ='02_Employee_Master'!A19 | B21: ='02_Employee_Master'!B19 | C21: ='02_Employee_Master'!D19 | D21: ='02_Employee_Master'!C19 | E21: E | F21: M | G21: M | H21: E | I21: WO | J21: M | K21: E
A22: ='02_Employee_Master'!A20 | B22: ='02_Employee_Master'!B20 | C22: ='02_Employee_Master'!D20 | D22: ='02_Employee_Master'!C20 | E22: M | F22: M | G22: M | H22: M | I22: M | J22: M | K22: WO
A23: ='02_Employee_Master'!A21 | B23: ='02_Employee_Master'!B21 | C23: ='02_Employee_Master'!D21 | D23: ='02_Employee_Master'!C21 | E23: M | F23: WO | G23: E | H23: M | I23: M | J23: M | K23: M
A24: ='02_Employee_Master'!A22 | B24: ='02_Employee_Master'!B22 | C24: ='02_Employee_Master'!D22 | D24: ='02_Employee_Master'!C22 | E24: E | F24: M | G24: M | H24: WO | I24: M | J24: M | K24: E
A25: ='02_Employee_Master'!A23 | B25: ='02_Employee_Master'!B23 | C25: ='02_Employee_Master'!D23 | D25: ='02_Employee_Master'!C23 | E25: M | F25: M | G25: M | H25: M | I25: M | J25: WO | K25: M
A26: ='02_Employee_Master'!A24 | B26: ='02_Employee_Master'!B24 | C26: ='02_Employee_Master'!D24 | D26: ='02_Employee_Master'!C24 | E26: WO | F26: M | G26: M | H26: M | I26: M | J26: M | K26: M | L26: Thomas Mathew
A27: ='02_Employee_Master'!A25 | B27: ='02_Employee_Master'!B25 | C27: ='02_Employee_Master'!D25 | D27: ='02_Employee_Master'!C25
A28: On duty (M+E+N) | E28: =COUNTIF(E8:E27,"M")+COUNTIF(E8:E27,"E")+COUNTIF(E8:E27,"N") | F28: =COUNTIF(F8:F27,"M")+COUNTIF(F8:F27,"E")+COUNTIF(F8:F27,"N") | G28: =COUNTIF(G8:G27,"M")+COUNTIF(G8:G27,"E")+COUNTIF(G8:G27,"N") | H28: =COUNTIF(H8:H27,"M")+COUNTIF(H8:H27,"E")+COUNTIF(H8:H27,"N") | I28: =COUNTIF(I8:I27,"M")+COUNTIF(I8:I27,"E")+COUNTIF(I8:I27,"N") | J28: =COUNTIF(J8:J27,"M")+COUNTIF(J8:J27,"E")+COUNTIF(J8:J27,"N") | K28: =COUNTIF(K8:K27,"M")+COUNTIF(K8:K27,"E")+COUNTIF(K8:K27,"N")

Sheet W3_Roster
A1: PATHCARE DIAGNOSTICS · Pathology Laboratory
A2: WEEK 3 ROSTER · Days 15–21
A3: Edit shifts here · Syncs to Full Month automatically · Period = Roster Month/Year
A4: GO → | B4: Full Month | C4: ▶ W1 | D4: ▶ W2 | E4: ● W3 | F4: ▶ W4 | G4: ▶ W5 | H4: You are on Week 3 | Drop-down: M E N WO PH LV TR
A5: Month | B5: ='03_Roster'!B5 | C5: Year | D5: ='03_Roster'!D5
A6: Emp ID | B6: Employee Name | C6: Department | D6: Designation | E6: 15 | F6: 16 | G6: 17 | H6: 18 | I6: 19 | J6: 20 | K6: 21 | L6: Backup | M6: Week notes
E7: =IF(E$6>DAY(DATE('03_Roster'!$D$5,'03_Roster'!$B$5+1,0)),"",TEXT(DATE('03_Roster'!$D$5,'03_Roster'!$B$5,E$6),"DDD")) | F7: =IF(F$6>DAY(DATE('03_Roster'!$D$5,'03_Roster'!$B$5+1,0)),"",TEXT(DATE('03_Roster'!$D$5,'03_Roster'!$B$5,F$6),"DDD")) | G7: =IF(G$6>DAY(DATE('03_Roster'!$D$5,'03_Roster'!$B$5+1,0)),"",TEXT(DATE('03_Roster'!$D$5,'03_Roster'!$B$5,G$6),"DDD")) | H7: =IF(H$6>DAY(DATE('03_Roster'!$D$5,'03_Roster'!$B$5+1,0)),"",TEXT(DATE('03_Roster'!$D$5,'03_Roster'!$B$5,H$6),"DDD")) | I7: =IF(I$6>DAY(DATE('03_Roster'!$D$5,'03_Roster'!$B$5+1,0)),"",TEXT(DATE('03_Roster'!$D$5,'03_Roster'!$B$5,I$6),"DDD")) | J7: =IF(J$6>DAY(DATE('03_Roster'!$D$5,'03_Roster'!$B$5+1,0)),"",TEXT(DATE('03_Roster'!$D$5,'03_Roster'!$B$5,J$6),"DDD")) | K7: =IF(K$6>DAY(DATE('03_Roster'!$D$5,'03_Roster'!$B$5+1,0)),"",TEXT(DATE('03_Roster'!$D$5,'03_Roster'!$B$5,K$6),"DDD"))
A8: ='02_Employee_Master'!A6 | B8: ='02_Employee_Master'!B6 | C8: ='02_Employee_Master'!D6 | D8: ='02_Employee_Master'!C6 | E8: M | F8: M | G8: M | H8: M | I8: M | J8: M | K8: WO | L8: Vikram Singh
A9: ='02_Employee_Master'!A7 | B9: ='02_Employee_Master'!B7 | C9: ='02_Employee_Master'!D7 | D9: ='02_Employee_Master'!C7 | E9: M | F9: WO | G9: M | H9: M | I9: E | J9: M | K9: M
A10: ='02_Employee_Master'!A8 | B10: ='02_Employee_Master'!B8 | C10: ='02_Employee_Master'!D8 | D10: ='02_Employee_Master'!C8 | E10: N | F10: M | G10: M | H10: WO | I10: M | J10: M | K10: M
A11: ='02_Employee_Master'!A9 | B11: ='02_Employee_Master'!B9 | C11: ='02_Employee_Master'!D9 | D11: ='02_Employee_Master'!C9 | E11: M | F11: M | G11: E | H11: M | I11: M | J11: WO | K11: N
A12: ='02_Employee_Master'!A10 | B12: ='02_Employee_Master'!B10 | C12: ='02_Employee_Master'!D10 | D12: ='02_Employee_Master'!C10 | E12: WO | F12: M | G12: E | H12: M | I12: M | J12: E | K12: M
A13: ='02_Employee_Master'!A11 | B13: ='02_Employee_Master'!B11 | C13: ='02_Employee_Master'!D11 | D13: ='02_Employee_Master'!C11 | E13: E | F13: M | G13: WO | H13: M | I13: N | J13: E | K13: M
A14: ='02_Employee_Master'!A12 | B14: ='02_Employee_Master'!B12 | C14: ='02_Employee_Master'!D12 | D14: ='02_Employee_Master'!C12 | E14: E | F14: M | G14: M | H14: E | I14: WO | J14: M | K14: E | L14: Karan Malhotra
A15: ='02_Employee_Master'!A13 | B15: ='02_Employee_Master'!B13 | C15: ='02_Employee_Master'!D13 | D15: ='02_Employee_Master'!C13 | E15: M | F15: M | G15: N | H15: E | I15: M | J15: M | K15: WO
A16: ='02_Employee_Master'!A14 | B16: ='02_Employee_Master'!B14 | C16: ='02_Employee_Master'!D14 | D16: ='02_Employee_Master'!C14 | E16: M | F16: WO | G16: M | H16: M | I16: M | J16: M | K16: M
A17: ='02_Employee_Master'!A15 | B17: ='02_Employee_Master'!B15 | C17: ='02_Employee_Master'!D15 | D17: ='02_Employee_Master'!C15 | E17: E | F17: M | G17: M | H17: WO | I17: M | J17: M | K17: E
A18: ='02_Employee_Master'!A16 | B18: ='02_Employee_Master'!B16 | C18: ='02_Employee_Master'!D16 | D18: ='02_Employee_Master'!C16 | E18: M | F18: M | G18: M | H18: M | I18: M | J18: WO | K18: M
A19: ='02_Employee_Master'!A17 | B19: ='02_Employee_Master'!B17 | C19: ='02_Employee_Master'!D17 | D19: ='02_Employee_Master'!C17 | E19: WO | F19: M | G19: M | H19: M | I19: E | J19: N | K19: M
A20: ='02_Employee_Master'!A18 | B20: ='02_Employee_Master'!B18 | C20: ='02_Employee_Master'!D18 | D20: ='02_Employee_Master'!C18 | E20: M | F20: M | G20: WO | H20: M | I20: M | J20: M | K20: M | L20: Deepak Joshi
A21: ='02_Employee_Master'!A19 | B21: ='02_Employee_Master'!B19 | C21: ='02_Employee_Master'!D19 | D21: ='02_Employee_Master'!C19 | E21: M | F21: M | G21: E | H21: M | I21: WO | J21: E | K21: M
A22: ='02_Employee_Master'!A20 | B22: ='02_Employee_Master'!B20 | C22: ='02_Employee_Master'!D20 | D22: ='02_Employee_Master'!C20 | E22: M | F22: M | G22: M | H22: M | I22: M | J22: M | K22: WO
A23: ='02_Employee_Master'!A21 | B23: ='02_Employee_Master'!B21 | C23: ='02_Employee_Master'!D21 | D23: ='02_Employee_Master'!C21 | E23: E | F23: WO | G23: M | H23: M | I23: M | J23: E | K23: M
A24: ='02_Employee_Master'!A22 | B24: ='02_Employee_Master'!B22 | C24: ='02_Employee_Master'!D22 | D24: ='02_Employee_Master'!C22 | E24: M | F24: M | G24: E | H24: WO | I24: M | J24: E | K24: M
A25: ='02_Employee_Master'!A23 | B25: ='02_Employee_Master'!B23 | C25: ='02_Employee_Master'!D23 | D25: ='02_Employee_Master'!C23 | E25: M | F25: M | G25: M | H25: M | I25: M | J25: WO | K25: M
A26: ='02_Employee_Master'!A24 | B26: ='02_Employee_Master'!B24 | C26: ='02_Employee_Master'!D24 | D26: ='02_Employee_Master'!C24 | E26: WO | F26: M | G26: M | H26: M | I26: M | J26: M | K26: M | L26: Thomas Mathew
A27: ='02_Employee_Master'!A25 | B27: ='02_Employee_Master'!B25 | C27: ='02_Employee_Master'!D25 | D27: ='02_Employee_Master'!C25
A28: On duty (M+E+N) | E28: =COUNTIF(E8:E27,"M")+COUNTIF(E8:E27,"E")+COUNTIF(E8:E27,"N") | F28: =COUNTIF(F8:F27,"M")+COUNTIF(F8:F27,"E")+COUNTIF(F8:F27,"N") | G28: =COUNTIF(G8:G27,"M")+COUNTIF(G8:G27,"E")+COUNTIF(G8:G27,"N") | H28: =COUNTIF(H8:H27,"M")+COUNTIF(H8:H27,"E")+COUNTIF(H8:H27,"N") | I28: =COUNTIF(I8:I27,"M")+COUNTIF(I8:I27,"E")+COUNTIF(I8:I27,"N") | J28: =COUNTIF(J8:J27,"M")+COUNTIF(J8:J27,"E")+COUNTIF(J8:J27,"N") | K28: =COUNTIF(K8:K27,"M")+COUNTIF(K8:K27,"E")+COUNTIF(K8:K27,"N")

Sheet W4_Roster
A1: PATHCARE DIAGNOSTICS · Pathology Laboratory
A2: WEEK 4 ROSTER · Days 22–28
A3: Edit shifts here · Syncs to Full Month automatically · Period = Roster Month/Year
A4: GO → | B4: Full Month | C4: ▶ W1 | D4: ▶ W2 | E4: ▶ W3 | F4: ● W4 | G4: ▶ W5 | H4: You are on Week 4 | Drop-down: M E N WO PH LV TR
A5: Month | B5: ='03_Roster'!B5 | C5: Year | D5: ='03_Roster'!D5
A6: Emp ID | B6: Employee Name | C6: Department | D6: Designation | E6: 22 | F6: 23 | G6: 24 | H6: 25 | I6: 26 | J6: 27 | K6: 28 | L6: Backup | M6: Week notes
E7: =IF(E$6>DAY(DATE('03_Roster'!$D$5,'03_Roster'!$B$5+1,0)),"",TEXT(DATE('03_Roster'!$D$5,'03_Roster'!$B$5,E$6),"DDD")) | F7: =IF(F$6>DAY(DATE('03_Roster'!$D$5,'03_Roster'!$B$5+1,0)),"",TEXT(DATE('03_Roster'!$D$5,'03_Roster'!$B$5,F$6),"DDD")) | G7: =IF(G$6>DAY(DATE('03_Roster'!$D$5,'03_Roster'!$B$5+1,0)),"",TEXT(DATE('03_Roster'!$D$5,'03_Roster'!$B$5,G$6),"DDD")) | H7: =IF(H$6>DAY(DATE('03_Roster'!$D$5,'03_Roster'!$B$5+1,0)),"",TEXT(DATE('03_Roster'!$D$5,'03_Roster'!$B$5,H$6),"DDD")) | I7: =IF(I$6>DAY(DATE('03_Roster'!$D$5,'03_Roster'!$B$5+1,0)),"",TEXT(DATE('03_Roster'!$D$5,'03_Roster'!$B$5,I$6),"DDD")) | J7: =IF(J$6>DAY(DATE('03_Roster'!$D$5,'03_Roster'!$B$5+1,0)),"",TEXT(DATE('03_Roster'!$D$5,'03_Roster'!$B$5,J$6),"DDD")) | K7: =IF(K$6>DAY(DATE('03_Roster'!$D$5,'03_Roster'!$B$5+1,0)),"",TEXT(DATE('03_Roster'!$D$5,'03_Roster'!$B$5,K$6),"DDD"))
A8: ='02_Employee_Master'!A6 | B8: ='02_Employee_Master'!B6 | C8: ='02_Employee_Master'!D6 | D8: ='02_Employee_Master'!C6 | E8: M | F8: M | G8: M | H8: M | I8: M | J8: M | K8: WO | L8: Vikram Singh
A9: ='02_Employee_Master'!A7 | B9: ='02_Employee_Master'!B7 | C9: ='02_Employee_Master'!D7 | D9: ='02_Employee_Master'!C7 | E9: M | F9: WO | G9: E | H9: M | I9: M | J9: M | K9: M
A10: ='02_Employee_Master'!A8 | B10: ='02_Employee_Master'!B8 | C10: ='02_Employee_Master'!D8 | D10: ='02_Employee_Master'!C8 | E10: N | F10: E | G10: M | H10: WO | I10: M | J10: M | K10: E
A11: ='02_Employee_Master'!A9 | B11: ='02_Employee_Master'!B9 | C11: ='02_Employee_Master'!D9 | D11: ='02_Employee_Master'!C9 | E11: E | F11: M | G11: M | H11: M | I11: M | J11: WO | K11: N
A12: ='02_Employee_Master'!A10 | B12: ='02_Employee_Master'!B10 | C12: ='02_Employee_Master'!D10 | D12: ='02_Employee_Master'!C10 | E12: WO | F12: E | G12: M | H12: M | I12: E | J12: M | K12: M
A13: ='02_Employee_Master'!A11 | B13: ='02_Employee_Master'!B11 | C13: ='02_Employee_Master'!D11 | D13: ='02_Employee_Master'!C11 | E13: M | F13: M | G13: WO | H13: E | I13: N | J13: M | K13: M
A14: ='02_Employee_Master'!A12 | B14: ='02_Employee_Master'!B12 | C14: ='02_Employee_Master'!D12 | D14: ='02_Employee_Master'!C12 | E14: M | F14: M | G14: E | H14: M | I14: WO | J14: E | K14: M | L14: Karan Malhotra
A15: ='02_Employee_Master'!A13 | B15: ='02_Employee_Master'!B13 | C15: ='02_Employee_Master'!D13 | D15: ='02_Employee_Master'!C13 | E15: M | F15: E | G15: N | H15: M | I15: M | J15: M | K15: WO
A16: ='02_Employee_Master'!A14 | B16: ='02_Employee_Master'!B14 | C16: ='02_Employee_Master'!D14 | D16: ='02_Employee_Master'!C14 | E16: M | F16: WO | G16: M | H16: M | I16: M | J16: M | K16: M
A17: ='02_Employee_Master'!A15 | B17: ='02_Employee_Master'!B15 | C17: ='02_Employee_Master'!D15 | D17: ='02_Employee_Master'!C15 | E17: M | F17: M | G17: E | H17: WO | I17: M | J17: E | K17: M
A18: ='02_Employee_Master'!A16 | B18: ='02_Employee_Master'!B16 | C18: ='02_Employee_Master'!D16 | D18: ='02_Employee_Master'!C16 | E18: M | F18: M | G18: M | H18: M | I18: M | J18: WO | K18: M
A19: ='02_Employee_Master'!A17 | B19: ='02_Employee_Master'!B17 | C19: ='02_Employee_Master'!D17 | D19: ='02_Employee_Master'!C17 | E19: WO | F19: M | G19: E | H19: M | I19: M | J19: N | K19: M
A20: ='02_Employee_Master'!A18 | B20: ='02_Employee_Master'!B18 | C20: ='02_Employee_Master'!D18 | D20: ='02_Employee_Master'!C18 | E20: M | F20: M | G20: WO | H20: M | I20: M | J20: M | K20: M | L20: Deepak Joshi
A21: ='02_Employee_Master'!A19 | B21: ='02_Employee_Master'!B19 | C21: ='02_Employee_Master'!D19 | D21: ='02_Employee_Master'!C19 | E21: M | F21: E | G21: M | H21: M | I21: WO | J21: M | K21: M
A22: ='02_Employee_Master'!A20 | B22: ='02_Employee_Master'!B20 | C22: ='02_Employee_Master'!D20 | D22: ='02_Employee_Master'!C20 | E22: M | F22: M | G22: M | H22: M | I22: M | J22: M | K22: WO
A23: ='02_Employee_Master'!A21 | B23: ='02_Employee_Master'!B21 | C23: ='02_Employee_Master'!D21 | D23: ='02_Employee_Master'!C21 | E23: M | F23: WO | G23: M | H23: E | I23: M | J23: M | K23: M
A24: ='02_Employee_Master'!A22 | B24: ='02_Employee_Master'!B22 | C24: ='02_Employee_Master'!D22 | D24: ='02_Employee_Master'!C22 | E24: M | F24: E | G24: M | H24: WO | I24: E | J24: M | K24: M
A25: ='02_Employee_Master'!A23 | B25: ='02_Employee_Master'!B23 | C25: ='02_Employee_Master'!D23 | D25: ='02_Employee_Master'!C23 | E25: M | F25: M | G25: M | H25: M | I25: M | J25: WO | K25: M
A26: ='02_Employee_Master'!A24 | B26: ='02_Employee_Master'!B24 | C26: ='02_Employee_Master'!D24 | D26: ='02_Employee_Master'!C24 | E26: WO | F26: M | G26: M | H26: M | I26: M | J26: M | K26: M | L26: Thomas Mathew
A27: ='02_Employee_Master'!A25 | B27: ='02_Employee_Master'!B25 | C27: ='02_Employee_Master'!D25 | D27: ='02_Employee_Master'!C25
A28: On duty (M+E+N) | E28: =COUNTIF(E8:E27,"M")+COUNTIF(E8:E27,"E")+COUNTIF(E8:E27,"N") | F28: =COUNTIF(F8:F27,"M")+COUNTIF(F8:F27,"E")+COUNTIF(F8:F27,"N") | G28: =COUNTIF(G8:G27,"M")+COUNTIF(G8:G27,"E")+COUNTIF(G8:G27,"N") | H28: =COUNTIF(H8:H27,"M")+COUNTIF(H8:H27,"E")+COUNTIF(H8:H27,"N") | I28: =COUNTIF(I8:I27,"M")+COUNTIF(I8:I27,"E")+COUNTIF(I8:I27,"N") | J28: =COUNTIF(J8:J27,"M")+COUNTIF(J8:J27,"E")+COUNTIF(J8:J27,"N") | K28: =COUNTIF(K8:K27,"M")+COUNTIF(K8:K27,"E")+COUNTIF(K8:K27,"N")

Sheet W5_Roster
A1: PATHCARE DIAGNOSTICS · Pathology Laboratory
A2: WEEK 5 ROSTER · Days 29–31
A3: Edit shifts here · Syncs to Full Month automatically · Period = Roster Month/Year
A4: GO → | B4: Full Month | C4: ▶ W1 | D4: ▶ W2 | E4: ▶ W3 | F4: ▶ W4 | G4: ● W5 | H4: You are on Week 5 | Drop-down: M E N WO PH LV TR
A5: Month | B5: ='03_Roster'!B5 | C5: Year | D5: ='03_Roster'!D5
A6: Emp ID | B6: Employee Name | C6: Department | D6: Designation | E6: 29 | F6: 30 | G6: 31 | H6: Backup | I6: Week notes
E7: =IF(E$6>DAY(DATE('03_Roster'!$D$5,'03_Roster'!$B$5+1,0)),"",TEXT(DATE('03_Roster'!$D$5,'03_Roster'!$B$5,E$6),"DDD")) | F7: =IF(F$6>DAY(DATE('03_Roster'!$D$5,'03_Roster'!$B$5+1,0)),"",TEXT(DATE('03_Roster'!$D$5,'03_Roster'!$B$5,F$6),"DDD")) | G7: =IF(G$6>DAY(DATE('03_Roster'!$D$5,'03_Roster'!$B$5+1,0)),"",TEXT(DATE('03_Roster'!$D$5,'03_Roster'!$B$5,G$6),"DDD"))
A8: ='02_Employee_Master'!A6 | B8: ='02_Employee_Master'!B6 | C8: ='02_Employee_Master'!D6 | D8: ='02_Employee_Master'!C6 | E8: M | F8: M | H8: Vikram Singh
A9: ='02_Employee_Master'!A7 | B9: ='02_Employee_Master'!B7 | C9: ='02_Employee_Master'!D7 | D9: ='02_Employee_Master'!C7 | E9: E | F9: WO
A10: ='02_Employee_Master'!A8 | B10: ='02_Employee_Master'!B8 | C10: ='02_Employee_Master'!D8 | D10: ='02_Employee_Master'!C8 | E10: N | F10: M
A11: ='02_Employee_Master'!A9 | B11: ='02_Employee_Master'!B9 | C11: ='02_Employee_Master'!D9 | D11: ='02_Employee_Master'!C9 | E11: M | F11: M
A12: ='02_Employee_Master'!A10 | B12: ='02_Employee_Master'!B10 | C12: ='02_Employee_Master'!D10 | D12: ='02_Employee_Master'!C10 | E12: WO | F12: M
A13: ='02_Employee_Master'!A11 | B13: ='02_Employee_Master'!B11 | C13: ='02_Employee_Master'!D11 | D13: ='02_Employee_Master'!C11 | E13: M | F13: E
A14: ='02_Employee_Master'!A12 | B14: ='02_Employee_Master'!B12 | C14: ='02_Employee_Master'!D12 | D14: ='02_Employee_Master'!C12 | E14: M | F14: E | H14: Karan Malhotra
A15: ='02_Employee_Master'!A13 | B15: ='02_Employee_Master'!B13 | C15: ='02_Employee_Master'!D13 | D15: ='02_Employee_Master'!C13 | E15: M | F15: M
A16: ='02_Employee_Master'!A14 | B16: ='02_Employee_Master'!B14 | C16: ='02_Employee_Master'!D14 | D16: ='02_Employee_Master'!C14 | E16: M | F16: WO
A17: ='02_Employee_Master'!A15 | B17: ='02_Employee_Master'!B15 | C17: ='02_Employee_Master'!D15 | D17: ='02_Employee_Master'!C15 | E17: M | F17: E
A18: ='02_Employee_Master'!A16 | B18: ='02_Employee_Master'!B16 | C18: ='02_Employee_Master'!D16 | D18: ='02_Employee_Master'!C16 | E18: M | F18: M
A19: ='02_Employee_Master'!A17 | B19: ='02_Employee_Master'!B17 | C19: ='02_Employee_Master'!D17 | D19: ='02_Employee_Master'!C17 | E19: WO | F19: M
A20: ='02_Employee_Master'!A18 | B20: ='02_Employee_Master'!B18 | C20: ='02_Employee_Master'!D18 | D20: ='02_Employee_Master'!C18 | E20: M | F20: M | H20: Deepak Joshi
A21: ='02_Employee_Master'!A19 | B21: ='02_Employee_Master'!B19 | C21: ='02_Employee_Master'!D19 | D21: ='02_Employee_Master'!C19 | E21: E | F21: M
A22: ='02_Employee_Master'!A20 | B22: ='02_Employee_Master'!B20 | C22: ='02_Employee_Master'!D20 | D22: ='02_Employee_Master'!C20 | E22: M | F22: M
A23: ='02_Employee_Master'!A21 | B23: ='02_Employee_Master'!B21 | C23: ='02_Employee_Master'!D21 | D23: ='02_Employee_Master'!C21 | E23: M | F23: WO
A24: ='02_Employee_Master'!A22 | B24: ='02_Employee_Master'!B22 | C24: ='02_Employee_Master'!D22 | D24: ='02_Employee_Master'!C22 | E24: E | F24: M
A25: ='02_Employee_Master'!A23 | B25: ='02_Employee_Master'!B23 | C25: ='02_Employee_Master'!D23 | D25: ='02_Employee_Master'!C23 | E25: M | F25: M
A26: ='02_Employee_Master'!A24 | B26: ='02_Employee_Master'!B24 | C26: ='02_Employee_Master'!D24 | D26: ='02_Employee_Master'!C24 | E26: WO | F26: M | H26: Thomas Mathew
A27: ='02_Employee_Master'!A25 | B27: ='02_Employee_Master'!B25 | C27: ='02_Employee_Master'!D25 | D27: ='02_Employee_Master'!C25
A28: On duty (M+E+N) | E28: =COUNTIF(E8:E27,"M")+COUNTIF(E8:E27,"E")+COUNTIF(E8:E27,"N") | F28: =COUNTIF(F8:F27,"M")+COUNTIF(F8:F27,"E")+COUNTIF(F8:F27,"N") | G28: =COUNTIF(G8:G27,"M")+COUNTIF(G8:G27,"E")+COUNTIF(G8:G27,"N")

Sheet 04_Attendance
A1: PATHCARE DIAGNOSTICS · Pathology Laboratory
A2: DAILY ATTENDANCE REGISTER
A3: Period follows Roster Month/Year · Clear marks when month changes · Color-coded statuses
A5: Period | B5: ='03_Roster'!B5 | C5: ='03_Roster'!D5 | D5: =DATE(C5,B5,1) | E5: Legend: P Present · A Absent · L Late · HD Half Day · WFO Work From Office · PL/UL/VL/SL Leave · H Holiday · WO Off · OT Overtime | Grey = invalid day for month
A6: Emp ID | B6: Employee Name | C6: Department | D6: Designation | E6: 1 | F6: 2 | G6: 3 | H6: 4 | I6: 5 | J6: 6 | K6: 7 | L6: 8 | M6: 9 | N6: 10 | O6: 11 | P6: 12 | Q6: 13 | R6: 14 | S6: 15 | T6: 16 | U6: 17 | V6: 18 | W6: 19 | X6: 20 | Y6: 21 | Z6: 22 | AA6: 23 | AB6: 24 | AC6: 25 | AD6: 26 | AE6: 27 | AF6: 28 | AG6: 29 | AH6: 30 | AI6: 31 | AJ6: Present | AK6: Absent | AL6: Late | AM6: Half Day | AN6: Leave | AO6: WO/H | AP6: OT Hrs | AQ6: Att %
E7: =IF(E$6>DAY(DATE('03_Roster'!$D$5,'03_Roster'!$B$5+1,0)),"",TEXT(DATE('03_Roster'!$D$5,'03_Roster'!$B$5,E$6),"DDD")) | F7: =IF(F$6>DAY(DATE('03_Roster'!$D$5,'03_Roster'!$B$5+1,0)),"",TEXT(DATE('03_Roster'!$D$5,'03_Roster'!$B$5,F$6),"DDD")) | G7: =IF(G$6>DAY(DATE('03_Roster'!$D$5,'03_Roster'!$B$5+1,0)),"",TEXT(DATE('03_Roster'!$D$5,'03_Roster'!$B$5,G$6),"DDD")) | H7: =IF(H$6>DAY(DATE('03_Roster'!$D$5,'03_Roster'!$B$5+1,0)),"",TEXT(DATE('03_Roster'!$D$5,'03_Roster'!$B$5,H$6),"DDD")) | I7: =IF(I$6>DAY(DATE('03_Roster'!$D$5,'03_Roster'!$B$5+1,0)),"",TEXT(DATE('03_Roster'!$D$5,'03_Roster'!$B$5,I$6),"DDD")) | J7: =IF(J$6>DAY(DATE('03_Roster'!$D$5,'03_Roster'!$B$5+1,0)),"",TEXT(DATE('03_Roster'!$D$5,'03_Roster'!$B$5,J$6),"DDD")) | K7: =IF(K$6>DAY(DATE('03_Roster'!$D$5,'03_Roster'!$B$5+1,0)),"",TEXT(DATE('03_Roster'!$D$5,'03_Roster'!$B$5,K$6),"DDD")) | L7: =IF(L$6>DAY(DATE('03_Roster'!$D$5,'03_Roster'!$B$5+1,0)),"",TEXT(DATE('03_Roster'!$D$5,'03_Roster'!$B$5,L$6),"DDD")) | ... AI7: =IF(AI$6>DAY(DATE('03_Roster'!$D$5,'03_Roster'!$B$5+1,0)),"",TEXT(DATE('03_Roster'!$D$5,'03_Roster'!$B$5,AI$6),"DDD"))
