Workbook

Sheet Start Here
A1: AskDB chat: manual test sheet
A3: Before you start
A4: 1. Dev environment only. Turn on chat_router_enabled and chat_structured_classifier_enabled, and confirm the follow-up guard setting is on.
A5: 2. Use a real model and key. Use automotive examples first; repeat key tests with insurance wording (premium, claims by status, agent, channel).
A6: 3. For each test note the route taken, whether SQL ran, and whether any number appeared that did not come from the query.
A7: 4. Record anything surprising, even if it looks harmless.
A9: How to record
A10: On 'Test Cases', set Result with the dropdown (Pass / Fail / Blocked / Not run). Fill Route taken, SQL ran?, and Notes. The 'Summary' tab updates automatically.
A12: Severity levels
A13: Blocker: a failure here means real data behaviour regressed, or a safety / access problem. Sections 1, 2, 4, 11, 13.
A14: High: memory, multi-turn, grounding, cost. Sections 3, 12, 14, 16 (severity assigned by me; adjust in column C if you disagree).
A15: Quality: tuning problems you can fix by adjusting rules or prompts. Sections 5-10, 15.
... A21: If you find failures, send the message, the route taken and what you expected, and we can decide whether it is a rule gap, a labelling issue, or a fix for Cursor.

Sheet Test Cases
A1: ID | B1: Section | C1: Severity | D1: Setup / prior steps | E1: Message to send / steps | F1: Expected | G1: Result | H1: Route taken | I1: SQL ran? | J1: Actual behaviour / notes
A2: 1 | B2: 1. Data questions | C2: Blocker | E2: Total revenue by city | F2: Table, chart, narration and SQL shown | G2: Not run
A3: 2 | B3: 1. Data questions | C3: Blocker | E3: Which make sold the most units? | F3: Single top result | G3: Not run
A4: 3 | B4: 1. Data questions | C4: Blocker | E4: Show me units by month for MG | F4: Filter on MG, monthly grain | G4: Not run
A5: 4 | B5: 1. Data questions | C5: Blocker | E5: Bottom 3 dealers by revenue | F5: Ordered ascending, 3 rows | G5: Not run
A6: 5 | B6: 1. Data questions | C6: Blocker | E6: Average selling price for EVs | F6: Correct EV filter | G6: Not run
A7: 6 | B7: 1. Data questions | C7: Blocker | E7: Revenue in Karnataka vs Maharashtra | F7: Side-by-side comparison | G7: Not run
A8: 7 | B8: 1. Data questions | C8: Blocker | E8: How many SUVs were sold in Pune? | F8: One number matching the table | G8: Not run
A9: 8 | B9: 1. Data questions | C9: Blocker | E9: Units by colour, top 5 | F9: 5 rows | G9: Not run
A10: 9 | B10: 1. Data questions | C10: Blocker | E10: Compare this year to last year revenue | F10: Correct date handling | G10: Not run
A11: 10 | B11: 1. Data questions | C11: Blocker | E11: revnue by regon | F11: Spell correction still works | G11: Not run
A12: 11 | B12: 2. Follow-ups (single hop) | C12: Blocker | D12: First: Revenue by region | E12: And for the East? | F12: Region swapped, metric kept, interpretation line shown | G12: Not run
A13: 12 | B13: 2. Follow-ups (single hop) | C13: Blocker | D13: First: Units by make | E13: Only EVs | F13: Filter added | G13: Not run
A14: 13 | B14: 2. Follow-ups (single hop) | C14: Blocker | D14: First: Top 5 dealers by revenue | E14: Now show 10 | F14: N changed to 10 | G14: Not run
A15: 14 | B15: 2. Follow-ups (single hop) | C15: Blocker | D15: First: Revenue by month | E15: Quarterly instead | F15: Grain changed | G15: Not run
A16: 15 | B16: 2. Follow-ups (single hop) | C16: Blocker | D16: First: Units by city | E16: Same but revenue | F16: Metric swapped, city kept | G16: Not run
A17: 16 | B17: 2. Follow-ups (single hop) | C17: Blocker | D17: First: Revenue by region | E17: Sort it ascending | F17: Order changed | G17: Not run
A18: 17 | B18: 2. Follow-ups (single hop) | C18: Blocker | D18: First: Units sold in Mumbai | E18: What about Pune? | F18: City swapped | G18: Not run
A19: 18 | B19: 2. Follow-ups (single hop) | C19: Blocker | D19: First: Revenue by make | E19: Drop MG | F19: Exclusion handled, or a clear clarification | G19: Not run
A20: 19 | B20: 3. Multi-turn chains | C20: High | D20: Send in order, same conversation | E20: Revenue by region → Just South → By month → Top 3 months | F20: Context accumulates correctly at each step | G20: Not run
A21: 20 | B21: 3. Multi-turn chains | C21: High | D21: Send in order, same conversation | E21: Units by make → Only SUVs → Which colour sells most among them? | F21: SUV filter carried through | G21: Not run
A22: 21 | B22: 3. Multi-turn chains | C22: High | D22: Send in order, same conversation | E22: Revenue by city → For MG only → Compare with Hyundai | F22: Both makes compared | G22: Not run
A23: 22 | B23: 3. Multi-turn chains | C23: High | D23: Data question, then 10 unrelated chat turns | E23: What about South? | F23: Clarifies or resolves safely; must not guess | G23: Not run
... A30: 29 | B30: 4. Fake follow-ups | C30: Blocker | D30: After 'Revenue by region' | E30: What about Delhii? | F30: Spell-corrected to Delhi, or a clarification; not an error | G30: Not run
A31: 30 | B31: 5. Greetings and casual | C31: Quality | E31: hey there | F31: Friendly reply, no SQL, no schema loaded | G31: Not run
A32: 31 | B32: 5. Greetings and casual | C32: Quality | E32: Good evening! | F32: Friendly reply, no SQL | G32: Not run
A33: 32 | B33: 5. Greetings and casual | C33: Quality | E33: thx a lot | F33: Acknowledgement | G33: Not run
A34: 33 | B34: 5. Greetings and casual | C34: Quality | D34: Right after a data answer | E34: Thanks | F34: Acknowledgement, no new query | G34: Not run
A35: 34 | B35: 5. Greetings and casual | C35: Quality | E35: You're awesome | F35: Natural reply | G35: Not run
A36: 35 | B36: 5. Greetings and casual | C36: Quality | E36: tell me something funny | F36: Short joke | G36: Not run
A37: 36 | B37: 5. Greetings and casual | C37: Quality | E37: who are you? | F37: Brief identity, no claims about data | G37: Not run
A38: 37 | B38: 5. Greetings and casual | C38: Quality | E38: what can you do? | F38: Says it helps with data questions; may give examples | G38: Not run
A39: 38 | B39: 5. Greetings and casual | C39: Quality | E39: bye | F39: Short goodbye | G39: Not run
A40: 39 | B40: 5. Greetings and casual | C40: Quality | E40: 😀 | F40: Sensible reply, no error | G40: Not run
A41: 40 | B41: 5. Greetings and casual | C41: Quality | D41: Send 5 times | E41: hi hi hi hi hi | F41: Varied replies, no SQL, no schema loaded | G41: Not run
A42: 41 | B42: 6. General knowledge | C42: Quality | E42: What is a data lake? | F42: Normal explanation | G42: Not run
A43: 42 | B43: 6. General knowledge | C43: Quality | E43: Explain EBITDA | F43: Explanation, no claims about your data | G43: Not run
A44: 43 | B44: 6. General knowledge | C44: Quality | E44: What's a good profit margin for a car dealership? | F44: General answer; must NOT say anything about your dealership | G44: Not run
A45: 44 | B45: 6. General knowledge | C45: Quality | E45: Is 12% revenue growth good? | F45: General framing only; no claim about your business | G45: Not run
A46: 45 | B46: 6. General knowledge | C46: Quality | E46: What is the difference between SQL and NoSQL? | F46: Explanation | G46: Not run
...

Sheet Summary
A1: Test progress summary
A3: Section | B3: Severity | C3: Total | D3: Pass | E3: Fail | F3: Blocked | G3: Not run | H3: Pass rate (of run)
A4: 1. Data questions | B4: =INDEX('Test Cases'!$C$2:$C$132,MATCH(A4,'Test Cases'!$B$2:$B$132,0)) -> Blocker | C4: =COUNTIF('Test Cases'!$B$2:$B$132,$A4) -> 10 | D4: =COUNTIFS('Test Cases'!$B$2:$B$132,$A4,'Test Cases'!$G$2:$G$132,"Pass") -> 0 | E4: =COUNTIFS('Test Cases'!$B$2:$B$132,$A4,'Test Cases'!$G$2:$G$132,"Fail") -> 0 | F4: =COUNTIFS('Test Cases'!$B$2:$B$132,$A4,'Test Cases'!$G$2:$G$132,"Blocked") -> 0 | G4: =COUNTIFS('Test Cases'!$B$2:$B$132,$A4,'Test Cases'!$G$2:$G$132,"Not run") -> 10 | H4: =IFERROR(D4/(D4+E4),"-") -> -
A5: 2. Follow-ups (single hop) | B5: =INDEX('Test Cases'!$C$2:$C$132,MATCH(A5,'Test Cases'!$B$2:$B$132,0)) -> Blocker | C5: =COUNTIF('Test Cases'!$B$2:$B$132,$A5) -> 8 | D5: =COUNTIFS('Test Cases'!$B$2:$B$132,$A5,'Test Cases'!$G$2:$G$132,"Pass") -> 0 | E5: =COUNTIFS('Test Cases'!$B$2:$B$132,$A5,'Test Cases'!$G$2:$G$132,"Fail") -> 0 | F5: =COUNTIFS('Test Cases'!$B$2:$B$132,$A5,'Test Cases'!$G$2:$G$132,"Blocked") -> 0 | G5: =COUNTIFS('Test Cases'!$B$2:$B$132,$A5,'Test Cases'!$G$2:$G$132,"Not run") -> 8 | H5: =IFERROR(D5/(D5+E5),"-") -> -
A6: 3. Multi-turn chains | B6: =INDEX('Test Cases'!$C$2:$C$132,MATCH(A6,'Test Cases'!$B$2:$B$132,0)) -> High | C6: =COUNTIF('Test Cases'!$B$2:$B$132,$A6) -> 4 | D6: =COUNTIFS('Test Cases'!$B$2:$B$132,$A6,'Test Cases'!$G$2:$G$132,"Pass") -> 0 | E6: =COUNTIFS('Test Cases'!$B$2:$B$132,$A6,'Test Cases'!$G$2:$G$132,"Fail") -> 0 | F6: =COUNTIFS('Test Cases'!$B$2:$B$132,$A6,'Test Cases'!$G$2:$G$132,"Blocked") -> 0 | G6: =COUNTIFS('Test Cases'!$B$2:$B$132,$A6,'Test Cases'!$G$2:$G$132,"Not run") -> 4 | H6: =IFERROR(D6/(D6+E6),"-") -> -
A7: 4. Fake follow-ups | B7: =INDEX('Test Cases'!$C$2:$C$132,MATCH(A7,'Test Cases'!$B$2:$B$132,0)) -> Blocker | C7: =COUNTIF('Test Cases'!$B$2:$B$132,$A7) -> 7 | D7: =COUNTIFS('Test Cases'!$B$2:$B$132,$A7,'Test Cases'!$G$2:$G$132,"Pass") -> 0 | E7: =COUNTIFS('Test Cases'!$B$2:$B$132,$A7,'Test Cases'!$G$2:$G$132,"Fail") -> 0 | F7: =COUNTIFS('Test Cases'!$B$2:$B$132,$A7,'Test Cases'!$G$2:$G$132,"Blocked") -> 0 | G7: =COUNTIFS('Test Cases'!$B$2:$B$132,$A7,'Test Cases'!$G$2:$G$132,"Not run") -> 7 | H7: =IFERROR(D7/(D7+E7),"-") -> -
A8: 5. Greetings and casual | B8: =INDEX('Test Cases'!$C$2:$C$132,MATCH(A8,'Test Cases'!$B$2:$B$132,0)) -> Quality | C8: =COUNTIF('Test Cases'!$B$2:$B$132,$A8) -> 11 | D8: =COUNTIFS('Test Cases'!$B$2:$B$132,$A8,'Test Cases'!$G$2:$G$132,"Pass") -> 0 | E8: =COUNTIFS('Test Cases'!$B$2:$B$132,$A8,'Test Cases'!$G$2:$G$132,"Fail") -> 0 | F8: =COUNTIFS('Test Cases'!$B$2:$B$132,$A8,'Test Cases'!$G$2:$G$132,"Blocked") -> 0 | G8: =COUNTIFS('Test Cases'!$B$2:$B$132,$A8,'Test Cases'!$G$2:$G$132,"Not run") -> 11 | H8: =IFERROR(D8/(D8+E8),"-") -> -
A9: 6. General knowledge | B9: =INDEX('Test Cases'!$C$2:$C$132,MATCH(A9,'Test Cases'!$B$2:$B$132,0)) -> Quality | C9: =COUNTIF('Test Cases'!$B$2:$B$132,$A9) -> 8 | D9: =COUNTIFS('Test Cases'!$B$2:$B$132,$A9,'Test Cases'!$G$2:$G$132,"Pass") -> 0 | E9: =COUNTIFS('Test Cases'!$B$2:$B$132,$A9,'Test Cases'!$G$2:$G$132,"Fail") -> 0 | F9: =COUNTIFS('Test Cases'!$B$2:$B$132,$A9,'Test Cases'!$G$2:$G$132,"Blocked") -> 0 | G9: =COUNTIFS('Test Cases'!$B$2:$B$132,$A9,'Test Cases'!$G$2:$G$132,"Not run") -> 8 | H9: =IFERROR(D9/(D9+E9),"-") -> -
A10: 7. App help (semantic metadata only) | B10: =INDEX('Test Cases'!$C$2:$C$132,MATCH(A10,'Test Cases'!$B$2:$B$132,0)) -> Quality | C10: =COUNTIF('Test Cases'!$B$2:$B$132,$A10) -> 9 | D10: =COUNTIFS('Test Cases'!$B$2:$B$132,$A10,'Test Cases'!$G$2:$G$132,"Pass") -> 0 | E10: =COUNTIFS('Test Cases'!$B$2:$B$132,$A10,'Test Cases'!$G$2:$G$132,"Fail") -> 0 | F10: =COUNTIFS('Test Cases'!$B$2:$B$132,$A10,'Test Cases'!$G$2:$G$132,"Blocked") -> 0 | G10: =COUNTIFS('Test Cases'!$B$2:$B$132,$A10,'Test Cases'!$G$2:$G$132,"Not run") -> 9 | H10: =IFERROR(D10/(D10+E10),"-") -> -
A11: 8. Ambiguous and clarification | B11: =INDEX('Test Cases'!$C$2:$C$132,MATCH(A11,'Test Cases'!$B$2:$B$132,0)) -> Quality | C11: =COUNTIF('Test Cases'!$B$2:$B$132,$A11) -> 12 | D11: =COUNTIFS('Test Cases'!$B$2:$B$132,$A11,'Test Cases'!$G$2:$G$132,"Pass") -> 0 | E11: =COUNTIFS('Test Cases'!$B$2:$B$132,$A11,'Test Cases'!$G$2:$G$132,"Fail") -> 0 | F11: =COUNTIFS('Test Cases'!$B$2:$B$132,$A11,'Test Cases'!$G$2:$G$132,"Blocked") -> 0 | G11: =COUNTIFS('Test Cases'!$B$2:$B$132,$A11,'Test Cases'!$G$2:$G$132,"Not run") -> 12 | H11: =IFERROR(D11/(D11+E11),"-") -> -
A12: 9. Compound and why questions | B12: =INDEX('Test Cases'!$C$2:$C$132,MATCH(A12,'Test Cases'!$B$2:$B$132,0)) -> Quality | C12: =COUNTIF('Test Cases'!$B$2:$B$132,$A12) -> 6 | D12: =COUNTIFS('Test Cases'!$B$2:$B$132,$A12,'Test Cases'!$G$2:$G$132,"Pass") -> 0 | E12: =COUNTIFS('Test Cases'!$B$2:$B$132,$A12,'Test Cases'!$G$2:$G$132,"Fail") -> 0 | F12: =COUNTIFS('Test Cases'!$B$2:$B$132,$A12,'Test Cases'!$G$2:$G$132,"Blocked") -> 0 | G12: =COUNTIFS('Test Cases'!$B$2:$B$132,$A12,'Test Cases'!$G$2:$G$132,"Not run") -> 6 | H12: =IFERROR(D12/(D12+E12),"-") -> -
A13: 10. Out of scope and live data | B13: =INDEX('Test Cases'!$C$2:$C$132,MATCH(A13,'Test Cases'!$B$2:$B$132,0)) -> Quality | C13: =COUNTIF('Test Cases'!$B$2:$B$132,$A13) -> 5 | D13: =COUNTIFS('Test Cases'!$B$2:$B$132,$A13,'Test Cases'!$G$2:$G$132,"Pass") -> 0 | E13: =COUNTIFS('Test Cases'!$B$2:$B$132,$A13,'Test Cases'!$G$2:$G$132,"Fail") -> 0 | F13: =COUNTIFS('Test Cases'!$B$2:$B$132,$A13,'Test Cases'!$G$2:$G$132,"Blocked") -> 0 | G13: =COUNTIFS('Test Cases'!$B$2:$B$132,$A13,'Test Cases'!$G$2:$G$132,"Not run") -> 5 | H13: =IFERROR(D13/(D13+E13),"-") -> -
A14: 11. Unsupported, unsafe, injection | B14: =INDEX('Test Cases'!$C$2:$C$132,MATCH(A14,'Test Cases'!$B$2:$B$132,0)) -> Blocker | C14: =COUNTIF('Test Cases'!$B$2:$B$132,$A14) -> 14 | D14: =COUNTIFS('Test Cases'!$B$2:$B$132,$A14,'Test Cases'!$G$2:$G$132,"Pass") -> 0 | E14: =COUNTIFS('Test Cases'!$B$2:$B$132,$A14,'Test Cases'!$G$2:$G$132,"Fail") -> 0 | F14: =COUNTIFS('Test Cases'!$B$2:$B$132,$A14,'Test Cases'!$G$2:$G$132,"Blocked") -> 0 | G14: =COUNTIFS('Test Cases'!$B$2:$B$132,$A14,'Test Cases'!$G$2:$G$132,"Not run") -> 14 | H14: =IFERROR(D14/(D14+E14),"-") -> -
A15: 12. Memory, expiry, refresh | B15: =INDEX('Test Cases'!$C$2:$C$132,MATCH(A15,'Test Cases'!$B$2:$B$132,0)) -> High | C15: =COUNTIF('Test Cases'!$B$2:$B$132,$A15) -> 8 | D15: =COUNTIFS('Test Cases'!$B$2:$B$132,$A15,'Test Cases'!$G$2:$G$132,"Pass") -> 0 | E15: =COUNTIFS('Test Cases'!$B$2:$B$132,$A15,'Test Cases'!$G$2:$G$132,"Fail") -> 0 | F15: =COUNTIFS('Test Cases'!$B$2:$B$132,$A15,'Test Cases'!$G$2:$G$132,"Blocked") -> 0 | G15: =COUNTIFS('Test Cases'!$B$2:$B$132,$A15,'Test Cases'!$G$2:$G$132,"Not run") -> 8 | H15: =IFERROR(D15/(D15+E15),"-") -> -
... A19: 16. Cost, quota, observability | B19: =INDEX('Test Cases'!$C$2:$C$132,MATCH(A19,'Test Cases'!$B$2:$B$132,0)) -> High | C19: =COUNTIF('Test Cases'!$B$2:$B$132,$A19) -> 6 | D19: =COUNTIFS('Test Cases'!$B$2:$B$132,$A19,'Test Cases'!$G$2:$G$132,"Pass") -> 0 | E19: =COUNTIFS('Test Cases'!$B$2:$B$132,$A19,'Test Cases'!$G$2:$G$132,"Fail") -> 0 | F19: =COUNTIFS('Test Cases'!$B$2:$B$132,$A19,'Test Cases'!$G$2:$G$132,"Blocked") -> 0 | G19: =COUNTIFS('Test Cases'!$B$2:$B$132,$A19,'Test Cases'!$G$2:$G$132,"Not run") -> 6 | H19: =IFERROR(D19/(D19+E19),"-") -> -
A20: Total | C20: =SUM(C4:C19) -> 131 | D20: =SUM(D4:D19) -> 0 | E20: =SUM(E4:E19) -> 0 | F20: =SUM(F4:F19) -> 0 | G20: =SUM(G4:G19) -> 131 | H20: =IFERROR(D20/(D20+E20),"-") -> -
A22: By severity
A23: Severity | B23: Total | C23: Pass | D23: Fail | E23: Blocked | F23: Not run
A24: Blocker | B24: =COUNTIF('Test Cases'!$C$2:$C$132,$A24) -> 50 | C24: =COUNTIFS('Test Cases'!$C$2:$C$132,$A24,'Test Cases'!$G$2:$G$132,"Pass") -> 0 | D24: =COUNTIFS('Test Cases'!$C$2:$C$132,$A24,'Test Cases'!$G$2:$G$132,"Fail") -> 0 | E24: =COUNTIFS('Test Cases'!$C$2:$C$132,$A24,'Test Cases'!$G$2:$G$132,"Blocked") -> 0 | F24: =COUNTIFS('Test Cases'!$C$2:$C$132,$A24,'Test Cases'!$G$2:$G$132,"Not run") -> 50
A25: High | B25: =COUNTIF('Test Cases'!$C$2:$C$132,$A25) -> 23 | C25: =COUNTIFS('Test Cases'!$C$2:$C$132,$A25,'Test Cases'!$G$2:$G$132,"Pass") -> 0 | D25: =COUNTIFS('Test Cases'!$C$2:$C$132,$A25,'Test Cases'!$G$2:$G$132,"Fail") -> 0 | E25: =COUNTIFS('Test Cases'!$C$2:$C$132,$A25,'Test Cases'!$G$2:$G$132,"Blocked") -> 0 | F25: =COUNTIFS('Test Cases'!$C$2:$C$132,$A25,'Test Cases'!$G$2:$G$132,"Not run") -> 23
A26: Quality | B26: =COUNTIF('Test Cases'!$C$2:$C$132,$A26) -> 58 | C26: =COUNTIFS('Test Cases'!$C$2:$C$132,$A26,'Test Cases'!$G$2:$G$132,"Pass") -> 0 | D26: =COUNTIFS('Test Cases'!$C$2:$C$132,$A26,'Test Cases'!$G$2:$G$132,"Fail") -> 0 | E26: =COUNTIFS('Test Cases'!$C$2:$C$132,$A26,'Test Cases'!$G$2:$G$132,"Blocked") -> 0 | F26: =COUNTIFS('Test Cases'!$C$2:$C$132,$A26,'Test Cases'!$G$2:$G$132,"Not run") -> 58
A29: Status | B29: =IF(D24+E24>0,"NO-GO: "&D24&" blocker failed, "&E24&" blocked",IF(G20>0,"In progress: "&G20&" tests not run",IF(E20>0,"All run: review "&E20&" non-blocker failures","All run, all passed"))) -> In progress: 131 tests not run
